,ts_recv,ts_event,rtype,publisher_id,instrument_id,action,side,depth,price,size,flags,ts_in_delta,sequence,bid_px_00,bid_sz_0,bid_ct_0,ask_px_0,ask_sz_0,ask_ct_0,bid_px_01,bid_sz_1,bid_ct_1,ask_px_1,ask_sz_1,ask_ct_1,bid_px_02,bid_sz_2,bid_ct_2,ask_px_2,ask_sz_2,ask_ct_2,bid_px_03,bid_sz_3,bid_ct_3,ask_px_3,ask_sz_3,ask_ct_3,bid_px_04,bid_sz_4,bid_ct_4,ask_px_4,ask_sz_4,ask_ct_4,bid_px_05,bid_sz_5,bid_ct_5,ask_px_5,ask_sz_5,ask_ct_5,bid_px_06,bid_sz_6,bid_ct_6,ask_px_6,ask_sz_6,ask_ct_6,bid_px_07,bid_sz_7,bid_ct_7,ask_px_7,ask_sz_7,ask_ct_7,bid_px_08,bid_sz_8,bid_ct_8,ask_px_8,ask_sz_8,ask_ct_8,bid_px_09,bid_sz_9,bid_ct_9,ask_px_9,ask_sz_9,ask_ct_9,symbol,order_id
1662,2025-07-17T16:02:20.651459317Z,2025-07-17T16:02:20.651293729Z,10,2,1108,C,A,0,17.250000000,100,0,165588,271676055,13.04,2,1,13.83,100,1,13.03,100,1,13.92,2,1,13.02,100,1,14.28,100,1,12.73,100,1,14.43,200,2,12.71,100,1,14.51,100,1,12.50,700,1,14.53,700,1,12.46,200,2,14.56,800,2,12.43,700,1,14.57,100,1,12.42,700,1,14.60,700,1,12.37,700,1,14.64,100,1,ARL,324942361
1663,2025-07-17T16:02:20.651459317Z,2025-07-17T16:02:20.651293729Z,10,2,1108,A,A,0,17.570000000,100,130,165588,271676055,13.04,2,1,13.83,100,1,13.03,100,1,13.92,2,1,13.02,100,1,14.28,100,1,12.73,100,1,14.43,200,2,12.71,100,1,14.51,100,1,12.50,700,1,14.53,700,1,12.46,200,2,14.56,800,2,12.43,700,1,14.57,100,1,12.42,700,1,14.60,700,1,12.37,700,1,14.64,100,1,ARL,325714589
1664,2025-07-17T16:02:20.651558948Z,2025-07-17T16:02:20.651393708Z,10,2,1108,A,A,0,14.450000000,100,130,165240,271676057,13.04,2,1,13.83,100,1,13.03,100,1,13.92,2,1,13.02,100,1,14.28,100,1,12.73,100,1,14.43,200,2,12.71,100,1,14.45,100,1,12.50,700,1,14.51,100,1,12.46,200,2,14.53,700,1,12.43,700,1,14.56,800,2,12.42,700,1,14.57,100,1,12.37,700,1,14.60,700,1,ARL,325714601
1665,2025-07-17T16:02:20.651787813Z,2025-07-17T16:02:20.651618897Z,10,2,1108,C,A,0,14.430000000,100,0,168916,271676089,13.04,2,1,13.83,100,1,13.03,100,1,13.92,2,1,13.02,100,1,14.28,100,1,12.73,100,1,14.43,100,1,12.71,100,1,14.45,100,1,12.50,700,1,14.51,100,1,12.46,200,2,14.53,700,1,12.43,700,1,14.56,800,2,12.42,700,1,14.57,100,1,12.37,700,1,14.60,700,1,ARL,325382437
1666,2025-07-17T16:02:20.651787813Z,2025-07-17T16:02:20.651618897Z,10,2,1108,A,A,0,14.730000000,100,128,168916,271676089,13.04,2,1,13.83,100,1,13.03,100,1,13.92,2,1,13.02,100,1,14.28,100,1,12.73,100,1,14.43,100,1,12.71,100,1,14.45,100,1,12.50,700,1,14.51,100,1,12.46,200,2,14.53,700,1,12.43,700,1,14.56,800,2,12.42,700,1,14.57,100,1,12.37,700,1,14.60,700,1,ARL,325714613
1667,2025-07-17T16:02:20.652021618Z,2025-07-17T16:02:20.651854531Z,10,2,1108,C,A,0,14.570000000,100,0,167087,271676104,13.04,2,1,13.83,100,1,13.03,100,1,13.92,2,1,13.02,100,1,14.28,100,1,12.73,100,1,14.43,100,1,12.71,100,1,14.45,100,1,12.50,700,1,14.51,100,1,12.46,200,2,14.53,700,1,12.43,700,1,14.56,800,2,12.42,700,1,14.60,700,1,12.37,700,1,14.64,100,1,ARL,324619409
1668,2025-07-17T16:02:20.652021618Z,2025-07-17T16:02:20.651854531Z,10,2,1108,A,A,0,14.800000000,100,130,167087,271676104,13.04,2,1,13.83,100,1,13.03,100,1,13.92,2,1,13.02,100,1,14.28,100,1,12.73,100,1,14.43,100,1,12.71,100,1,14.45,100,1,12.50,700,1,14.51,100,1,12.46,200,2,14.53,700,1,12.43,700,1,14.56,800,2,12.42,700,1,14.60,700,1,12.37,700,1,14.64,100,1,ARL,325714629
1669,2025-07-17T16:02:20.652097288Z,2025-07-17T16:02:20.651932129Z,10,2,1108,C,A,0,14.430000000,100,130,165159,271676110,13.04,2,1,13.83,100,1,13.03,100,1,13.92,2,1,13.02,100,1,14.28,100,1,12.73,100,1,14.45,100,1,12.71,100,1,14.51,100,1,12.50,700,1,14.53,700,1,12.46,200,2,14.56,800,2,12.43,700,1,14.60,700,1,12.42,700,1,14.64,100,1,12.37,700,1,14.68,700,1,ARL,324186781
1670,2025-07-17T16:02:20.652160470Z,2025-07-17T16:02:20.651994883Z,10,2,1108,C,A,0,15.600000000,100,0,165587,271676111,13.04,2,1,13.83,100,1,13.03,100,1,13.92,2,1,13.02,100,1,14.28,100,1,12.73,100,1,14.45,100,1,12.71,100,1,14.51,100,1,12.50,700,1,14.53,700,1,12.46,200,2,14.56,800,2,12.43,700,1,14.60,700,1,12.42,700,1,14.64,100,1,12.37,700,1,14.68,700,1,ARL,325176677
1671,2025-07-17T16:02:20.652160470Z,2025-07-17T16:02:20.651994883Z,10,2,1108,A,A,0,15.910000000,100,130,165587,271676111,13.04,2,1,13.83,100,1,13.03,100,1,13.92,2,1,13.02,100,1,14.28,100,1,12.73,100,1,14.45,100,1,12.71,100,1,14.51,100,1,12.50,700,1,14.53,700,1,12.46,200,2,14.56,800,2,12.43,700,1,14.60,700,1,12.42,700,1,14.64,100,1,12.37,700,1,14.68,700,1,ARL,325714633
1672,2025-07-17T16:02:20.652259931Z,2025-07-17T16:02:20.652094426Z,10,2,1108,A,A,0,14.630000000,100,130,165505,271676118,13.04,2,1,13.83,100,1,13.03,100,1,13.92,2,1,13.02,100,1,14.28,100,1,12.73,100,1,14.45,100,1,12.71,100,1,14.51,100,1,12.50,700,1,14.53,700,1,12.46,200,2,14.56,800,2,12.43,700,1,14.60,700,1,12.42,700,1,14.63,100,1,12.37,700,1,14.64,100,1,ARL,325714653
1673,2025-07-17T16:02:20.653626391Z,2025-07-17T16:02:20.653460814Z,10,2,1108,A,B,0,13.270000000,10,130,165577,271676147,13.27,10,1,13.83,100,1,13.04,2,1,13.92,2,1,13.03,100,1,14.28,100,1,13.02,100,1,14.45,100,1,12.73,100,1,14.51,100,1,12.71,100,1,14.53,700,1,12.50,700,1,14.56,800,2,12.46,200,2,14.60,700,1,12.43,700,1,14.63,100,1,12.42,700,1,14.64,100,1,ARL,325714717
1674,2025-07-17T16:02:20.653627232Z,2025-07-17T16:02:20.653461966Z,10,2,1108,A,A,0,13.830000000,15,130,165266,271676148,13.27,10,1,13.83,115,2,13.04,2,1,13.92,2,1,13.03,100,1,14.28,100,1,13.02,100,1,14.45,100,1,12.73,100,1,14.51,100,1,12.71,100,1,14.53,700,1,12.50,700,1,14.56,800,2,12.46,200,2,14.60,700,1,12.43,700,1,14.63,100,1,12.42,700,1,14.64,100,1,ARL,325714721
1675,2025-07-17T16:02:20.653886896Z,2025-07-17T16:02:20.653721185Z,10,2,1108,C,B,0,13.020000000,100,0,165711,271676153,13.27,10,1,13.83,115,2,13.04,2,1,13.92,2,1,13.03,100,1,14.28,100,1,12.73,100,1,14.45,100,1,12.71,100,1,14.51,100,1,12.50,700,1,14.53,700,1,12.46,200,2,14.56,800,2,12.43,700,1,14.60,700,1,12.42,700,1,14.63,100,1,12.37,700,1,14.64,100,1,ARL,320485385
1676,2025-07-17T16:02:20.653886896Z,2025-07-17T16:02:20.653721185Z,10,2,1108,A,B,0,13.260000000,100,130,165711,271676153,13.27,10,1,13.83,115,2,13.26,100,1,13.92,2,1,13.04,2,1,14.28,100,1,13.03,100,1,14.45,100,1,12.73,100,1,14.51,100,1,12.71,100,1,14.53,700,1,12.50,700,1,14.56,800,2,12.46,200,2,14.60,700,1,12.43,700,1,14.63,100,1,12.42,700,1,14.64,100,1,ARL,325714729
1677,2025-07-17T16:02:20.655277066Z,2025-07-17T16:02:20.655111649Z,10,2,1108,C,B,0,13.040000000,2,0,165417,271676165,13.27,10,1,13.83,115,2,13.26,100,1,13.92,2,1,13.03,100,1,14.28,100,1,12.73,100,1,14.45,100,1,12.71,100,1,14.51,100,1,12.50,700,1,14.53,700,1,12.46,200,2,14.56,800,2,12.43,700,1,14.60,700,1,12.42,700,1,14.63,100,1,12.37,700,1,14.64,100,1,ARL,293594281
1678,2025-07-17T16:02:20.655277066Z,2025-07-17T16:02:20.655111649Z,10,2,1108,A,B,0,12.910000000,2,130,165417,271676165,13.27,10,1,13.83,115,2,13.26,100,1,13.92,2,1,13.03,100,1,14.28,100,1,12.91,2,1,14.45,100,1,12.73,100,1,14.51,100,1,12.71,100,1,14.53,700,1,12.50,700,1,14.56,800,2,12.46,200,2,14.60,700,1,12.43,700,1,14.63,100,1,12.42,700,1,14.64,100,1,ARL,325714741
1679,2025-07-17T16:02:20.663374576Z,2025-07-17T16:02:20.663209235Z,10,2,1108,C,A,0,13.830000000,100,130,165341,271676274,13.27,10,1,13.83,15,1,13.26,100,1,13.92,2,1,13.03,100,1,14.28,100,1,12.91,2,1,14.45,100,1,12.73,100,1,14.51,100,1,12.71,100,1,14.53,700,1,12.50,700,1,14.56,800,2,12.46,200,2,14.60,700,1,12.43,700,1,14.63,100,1,12.42,700,1,14.64,100,1,ARL,325176373
1680,2025-07-17T16:02:20.663406861Z,2025-07-17T16:02:20.663241882Z,10,2,1108,C,A,0,14.530000000,700,130,164979,271676275,13.27,10,1,13.83,15,1,13.26,100,1,13.92,2,1,13.03,100,1,14.28,100,1,12.91,2,1,14.45,100,1,12.73,100,1,14.51,100,1,12.71,100,1,14.56,800,2,12.50,700,1,14.60,700,1,12.46,200,2,14.63,100,1,12.43,700,1,14.64,100,1,12.42,700,1,14.68,700,1,ARL,325714545
1681,2025-07-17T16:02:20.663426974Z,2025-07-17T16:02:20.663261632Z,10,2,1108,A,A,0,14.110000000,100,130,165342,271676276,13.27,10,1,13.83,15,1,13.26,100,1,13.92,2,1,13.03,100,1,14.11,100,1,12.91,2,1,14.28,100,1,12.73,100,1,14.45,100,1,12.71,100,1,14.51,100,1,12.50,700,1,14.56,800,2,12.46,200,2,14.60,700,1,12.43,700,1,14.63,100,1,12.42,700,1,14.64,100,1,ARL,325714905
1682,2025-07-17T16:02:20.663559466Z,2025-07-17T16:02:20.663394059Z,10,2,1108,A,A,0,15.940000000,100,130,165407,271676277,13.27,10,1,13.83,15,1,13.26,100,1,13.92,2,1,13.03,100,1,14.11,100,1,12.91,2,1,14.28,100,1,12.73,100,1,14.45,100,1,12.71,100,1,14.51,100,1,12.50,700,1,14.56,800,2,12.46,200,2,14.60,700,1,12.43,700,1,14.63,100,1,12.42,700,1,14.64,100,1,ARL,325714909
1683,2025-07-17T16:02:20.663572634Z,2025-07-17T16:02:20.663407337Z,10,2,1108,C,A,0,15.590000000,100,130,165297,271676278,13.27,10,1,13.83,15,1,13.26,100,1,13.92,2,1,13.03,100,1,14.11,100,1,12.91,2,1,14.28,100,1,12.73,100,1,14.45,100,1,12.71,100,1,14.51,100,1,12.50,700,1,14.56,800,2,12.46,200,2,14.60,700,1,12.43,700,1,14.63,100,1,12.42,700,1,14.64,100,1,ARL,323730697
1684,2025-07-17T16:02:20.664956400Z,2025-07-17T16:02:20.664790768Z,10,2,1108,C,A,0,17.570000000,100,0,165632,271676310,13.27,10,1,13.83,15,1,13.26,100,1,13.92,2,1,13.03,100,1,14.11,100,1,12.91,2,1,14.28,100,1,12.73,100,1,14.45,100,1,12.71,100,1,14.51,100,1,12.50,700,1,14.56,800,2,12.46,200,2,14.60,700,1,12.43,700,1,14.63,100,1,12.42,700,1,14.64,100,1,ARL,325714589
1685,2025-07-17T16:02:20.664956400Z,2025-07-17T16:02:20.664790768Z,10,2,1108,A,A,0,17.760000000,100,130,165632,271676310,13.27,10,1,13.83,15,1,13.26,100,1,13.92,2,1,13.03,100,1,14.11,100,1,12.91,2,1,14.28,100,1,12.73,100,1,14.45,100,1,12.71,100,1,14.51,100,1,12.50,700,1,14.56,800,2,12.46,200,2,14.60,700,1,12.43,700,1,14.63,100,1,12.42,700,1,14.64,100,1,ARL,325714949
1686,2025-07-17T16:02:20.665129279Z,2025-07-17T16:02:20.664963386Z,10,2,1108,C,A,0,14.800000000,100,0,165893,271676320,13.27,10,1,13.83,15,1,13.26,100,1,13.92,2,1,13.03,100,1,14.11,100,1,12.91,2,1,14.28,100,1,12.73,100,1,14.45,100,1,12.71,100,1,14.51,100,1,12.50,700,1,14.56,800,2,12.46,200,2,14.60,700,1,12.43,700,1,14.63,100,1,12.42,700,1,14.64,100,1,ARL,325714629
1687,2025-07-17T16:02:20.665129279Z,2025-07-17T16:02:20.664963386Z,10,2,1108,A,A,0,14.960000000,100,130,165893,271676320,13.27,10,1,13.83,15,1,13.26,100,1,13.92,2,1,13.03,100,1,14.11,100,1,12.91,2,1,14.28,100,1,12.73,100,1,14.45,100,1,12.71,100,1,14.51,100,1,12.50,700,1,14.56,800,2,12.46,200,2,14.60,700,1,12.43,700,1,14.63,100,1,12.42,700,1,14.64,100,1,ARL,325714953
1688,2025-07-17T16:02:20.665200392Z,2025-07-17T16:02:20.665034825Z,10,2,1108,C,A,0,15.910000000,100,0,165567,271676330,13.27,10,1,13.83,15,1,13.26,100,1,13.92,2,1,13.03,100,1,14.11,100,1,12.91,2,1,14.28,100,1,12.73,100,1,14.45,100,1,12.71,100,1,14.51,100,1,12.50,700,1,14.56,800,2,12.46,200,2,14.60,700,1,12.43,700,1,14.63,100,1,12.42,700,1,14.64,100,1,ARL,325714633
1689,2025-07-17T16:02:20.665200392Z,2025-07-17T16:02:20.665034825Z,10,2,1108,A,A,0,16.080000000,100,130,165567,271676330,13.27,10,1,13.83,15,1,13.26,100,1,13.92,2,1,13.03,100,1,14.11,100,1,12.91,2,1,14.28,100,1,12.73,100,1,14.45,100,1,12.71,100,1,14.51,100,1,12.50,700,1,14.56,800,2,12.46,200,2,14.60,700,1,12.43,700,1,14.63,100,1,12.42,700,1,14.64,100,1,ARL,325714957
1690,2025-07-17T16:02:20.665457595Z,2025-07-17T16:02:20.665292049Z,10,2,1108,C,A,0,14.940000000,100,0,165546,271676355,13.27,10,1,13.83,15,1,13.26,100,1,13.92,2,1,13.03,100,1,14.11,100,1,12.91,2,1,14.28,100,1,12.73,100,1,14.45,100,1,12.71,100,1,14.51,100,1,12.50,700,1,14.56,800,2,12.46,200,2,14.60,700,1,12.43,700,1,14.63,100,1,12.42,700,1,14.64,100,1,ARL,324942277
1691,2025-07-17T16:02:20.665457595Z,2025-07-17T16:02:20.665292049Z,10,2,1108,A,A,0,15.380000000,100,130,165546,271676355,13.27,10,1,13.83,15,1,13.26,100,1,13.92,2,1,13.03,100,1,14.11,100,1,12.91,2,1,14.28,100,1,12.73,100,1,14.45,100,1,12.71,100,1,14.51,100,1,12.50,700,1,14.56,800,2,12.46,200,2,14.60,700,1,12.43,700,1,14.63,100,1,12.42,700,1,14.64,100,1,ARL,325714965
1692,2025-07-17T16:02:20.669701452Z,2025-07-17T16:02:20.669536385Z,10,2,1108,C,A,0,14.110000000,100,130,165067,271676398,13.27,10,1,13.83,15,1,13.26,100,1,13.92,2,1,13.03,100,1,14.28,100,1,12.91,2,1,14.45,100,1,12.73,100,1,14.51,100,1,12.71,100,1,14.56,800,2,12.50,700,1,14.60,700,1,12.46,200,2,14.63,100,1,12.43,700,1,14.64,100,1,12.42,700,1,14.68,700,1,ARL,325714905
1693,2025-07-17T16:02:20.669748954Z,2025-07-17T16:02:20.669583810Z,10,2,1108,A,A,0,14.260000000,100,130,165144,271676399,13.27,10,1,13.83,15,1,13.26,100,1,13.92,2,1,13.03,100,1,14.26,100,1,12.91,2,1,14.28,100,1,12.73,100,1,14.45,100,1,12.71,100,1,14.51,100,1,12.50,700,1,14.56,800,2,12.46,200,2,14.60,700,1,12.43,700,1,14.63,100,1,12.42,700,1,14.64,100,1,ARL,325715045
1694,2025-07-17T16:02:20.669752979Z,2025-07-17T16:02:20.669587514Z,10,2,1108,C,A,0,14.510000000,100,0,165465,271676400,13.27,10,1,13.83,15,1,13.26,100,1,13.92,2,1,13.03,100,1,14.26,100,1,12.91,2,1,14.28,100,1,12.73,100,1,14.45,100,1,12.71,100,1,14.56,800,2,12.50,700,1,14.60,700,1,12.46,200,2,14.63,100,1,12.43,700,1,14.64,100,1,12.42,700,1,14.68,700,1,ARL,325177757
1695,2025-07-17T16:02:20.669752979Z,2025-07-17T16:02:20.669587514Z,10,2,1108,A,A,0,14.960000000,100,130,165465,271676400,13.27,10,1,13.83,15,1,13.26,100,1,13.92,2,1,13.03,100,1,14.26,100,1,12.91,2,1,14.28,100,1,12.73,100,1,14.45,100,1,12.71,100,1,14.56,800,2,12.50,700,1,14.60,700,1,12.46,200,2,14.63,100,1,12.43,700,1,14.64,100,1,12.42,700,1,14.68,700,1,ARL,325715053
1696,2025-07-17T16:02:20.685252049Z,2025-07-17T16:02:20.685086585Z,10,2,1108,C,A,0,14.640000000,100,0,165464,271676621,13.27,10,1,13.83,15,1,13.26,100,1,13.92,2,1,13.03,100,1,14.26,100,1,12.91,2,1,14.28,100,1,12.73,100,1,14.45,100,1,12.71,100,1,14.56,800,2,12.50,700,1,14.60,700,1,12.46,200,2,14.63,100,1,12.43,700,1,14.68,700,1,12.42,700,1,14.73,200,2,ARL,325714169
1697,2025-07-17T16:02:20.685252049Z,2025-07-17T16:02:20.685086585Z,10,2,1108,A,A,0,15.060000000,100,130,165464,271676621,13.27,10,1,13.83,15,1,13.26,100,1,13.92,2,1,13.03,100,1,14.26,100,1,12.91,2,1,14.28,100,1,12.73,100,1,14.45,100,1,12.71,100,1,14.56,800,2,12.50,700,1,14.60,700,1,12.46,200,2,14.63,100,1,12.43,700,1,14.68,700,1,12.42,700,1,14.73,200,2,ARL,325715113
1698,2025-07-17T16:02:20.832112637Z,2025-07-17T16:02:20.831947250Z,10,2,1108,A,A,0,14.680000000,700,130,165387,271678584,13.27,10,1,13.83,15,1,13.26,100,1,13.92,2,1,13.03,100,1,14.26,100,1,12.91,2,1,14.28,100,1,12.73,100,1,14.45,100,1,12.71,100,1,14.56,800,2,12.50,700,1,14.60,700,1,12.46,200,2,14.63,100,1,12.43,700,1,14.68,1400,2,12.42,700,1,14.73,200,2,ARL,325716945
1699,2025-07-17T16:02:20.936787418Z,2025-07-17T16:02:20.936622241Z,10,2,1108,C,B,0,13.260000000,100,130,165177,271679553,13.27,10,1,13.83,15,1,13.03,100,1,13.92,2,1,12.91,2,1,14.26,100,1,12.73,100,1,14.28,100,1,12.71,100,1,14.45,100,1,12.50,700,1,14.56,800,2,12.46,200,2,14.60,700,1,12.43,700,1,14.63,100,1,12.42,700,1,14.68,1400,2,12.37,700,1,14.73,200,2,ARL,325714729
1700,2025-07-17T16:02:20.936837611Z,2025-07-17T16:02:20.936672130Z,10,2,1108,A,A,0,13.910000000,5,130,165481,271679555,13.27,10,1,13.83,15,1,13.03,100,1,13.91,5,1,12.91,2,1,13.92,2,1,12.73,100,1,14.26,100,1,12.71,100,1,14.28,100,1,12.50,700,1,14.45,100,1,12.46,200,2,14.56,800,2,12.43,700,1,14.60,700,1,12.42,700,1,14.63,100,1,12.37,700,1,14.68,1400,2,ARL,325718477
1701,2025-07-17T16:02:20.936914901Z,2025-07-17T16:02:20.936748894Z,10,2,1108,T,N,0,13.280000000,11,130,166007,271679557,13.27,10,1,13.83,15,1,13.03,100,1,13.91,5,1,12.91,2,1,13.92,2,1,12.73,100,1,14.26,100,1,12.71,100,1,14.28,100,1,12.50,700,1,14.45,100,1,12.46,200,2,14.56,800,2,12.43,700,1,14.60,700,1,12.42,700,1,14.63,100,1,12.37,700,1,14.68,1400,2,ARL,0
1702,2025-07-17T16:02:20.936999211Z,2025-07-17T16:02:20.936833988Z,10,2,1108,A,A,0,13.840000000,100,130,165223,271679558,13.27,10,1,13.83,15,1,13.03,100,1,13.84,100,1,12.91,2,1,13.91,5,1,12.73,100,1,13.92,2,1,12.71,100,1,14.26,100,1,12.50,700,1,14.28,100,1,12.46,200,2,14.45,100,1,12.43,700,1,14.56,800,2,12.42,700,1,14.60,700,1,12.37,700,1,14.63,100,1,ARL,325718485
1703,2025-07-17T16:02:20.937307935Z,2025-07-17T16:02:20.937142186Z,10,2,1108,T,N,0,13.280000000,11,130,165749,271679562,13.27,10,1,13.83,15,1,13.03,100,1,13.84,100,1,12.91,2,1,13.91,5,1,12.73,100,1,13.92,2,1,12.71,100,1,14.26,100,1,12.50,700,1,14.28,100,1,12.46,200,2,14.45,100,1,12.43,700,1,14.56,800,2,12.42,700,1,14.60,700,1,12.37,700,1,14.63,100,1,ARL,0
1704,2025-07-17T16:02:20.937744264Z,2025-07-17T16:02:20.937578907Z,10,2,1108,C,A,0,15.060000000,100,0,165357,271679565,13.27,10,1,13.83,15,1,13.03,100,1,13.84,100,1,12.91,2,1,13.91,5,1,12.73,100,1,13.92,2,1,12.71,100,1,14.26,100,1,12.50,700,1,14.28,100,1,12.46,200,2,14.45,100,1,12.43,700,1,14.56,800,2,12.42,700,1,14.60,700,1,12.37,700,1,14.63,100,1,ARL,325715113
1705,2025-07-17T16:02:20.937744264Z,2025-07-17T16:02:20.937578907Z,10,2,1108,A,A,0,14.910000000,100,130,165357,271679565,13.27,10,1,13.83,15,1,13.03,100,1,13.84,100,1,12.91,2,1,13.91,5,1,12.73,100,1,13.92,2,1,12.71,100,1,14.26,100,1,12.50,700,1,14.28,100,1,12.46,200,2,14.45,100,1,12.43,700,1,14.56,800,2,12.42,700,1,14.60,700,1,12.37,700,1,14.63,100,1,ARL,325718509
1706,2025-07-17T16:02:20.937901293Z,2025-07-17T16:02:20.937736247Z,10,2,1108,C,A,0,13.910000000,5,130,165046,271679567,13.27,10,1,13.83,15,1,13.03,100,1,13.84,100,1,12.91,2,1,13.92,2,1,12.73,100,1,14.26,100,1,12.71,100,1,14.28,100,1,12.50,700,1,14.45,100,1,12.46,200,2,14.56,800,2,12.43,700,1,14.60,700,1,12.42,700,1,14.63,100,1,12.37,700,1,14.68,1400,2,ARL,325718477
1707,2025-07-17T16:02:20.938093286Z,2025-07-17T16:02:20.937927380Z,10,2,1108,C,A,0,14.960000000,100,0,165906,271679569,13.27,10,1,13.83,15,1,13.03,100,1,13.84,100,1,12.91,2,1,13.92,2,1,12.73,100,1,14.26,100,1,12.71,100,1,14.28,100,1,12.50,700,1,14.45,100,1,12.46,200,2,14.56,800,2,12.43,700,1,14.60,700,1,12.42,700,1,14.63,100,1,12.37,700,1,14.68,1400,2,ARL,325715053
1708,2025-07-17T16:02:20.938093286Z,2025-07-17T16:02:20.937927380Z,10,2,1108,A,A,0,14.810000000,100,130,165906,271679569,13.27,10,1,13.83,15,1,13.03,100,1,13.84,100,1,12.91,2,1,13.92,2,1,12.73,100,1,14.26,100,1,12.71,100,1,14.28,100,1,12.50,700,1,14.45,100,1,12.46,200,2,14.56,800,2,12.43,700,1,14.60,700,1,12.42,700,1,14.63,100,1,12.37,700,1,14.68,1400,2,ARL,325718517
1709,2025-07-17T16:02:20.938297839Z,2025-07-17T16:02:20.938132716Z,10,2,1108,C,A,0,16.080000000,100,0,165123,271679571,13.27,10,1,13.83,15,1,13.03,100,1,13.84,100,1,12.91,2,1,13.92,2,1,12.73,100,1,14.26,100,1,12.71,100,1,14.28,100,1,12.50,700,1,14.45,100,1,12.46,200,2,14.56,800,2,12.43,700,1,14.60,700,1,12.42,700,1,14.63,100,1,12.37,700,1,14.68,1400,2,ARL,325714957
1710,2025-07-17T16:02:20.938297839Z,2025-07-17T16:02:20.938132716Z,10,2,1108,A,A,0,15.920000000,100,130,165123,271679571,13.27,10,1,13.83,15,1,13.03,100,1,13.84,100,1,12.91,2,1,13.92,2,1,12.73,100,1,14.26,100,1,12.71,100,1,14.28,100,1,12.50,700,1,14.45,100,1,12.46,200,2,14.56,800,2,12.43,700,1,14.60,700,1,12.42,700,1,14.63,100,1,12.37,700,1,14.68,1400,2,ARL,325718525
1711,2025-07-17T16:02:20.938616654Z,2025-07-17T16:02:20.938451331Z,10,2,1108,C,A,0,14.960000000,100,0,165323,271679575,13.27,10,1,13.83,15,1,13.03,100,1,13.84,100,1,12.91,2,1,13.92,2,1,12.73,100,1,14.26,100,1,12.71,100,1,14.28,100,1,12.50,700,1,14.45,100,1,12.46,200,2,14.56,800,2,12.43,700,1,14.60,700,1,12.42,700,1,14.63,100,1,12.37,700,1,14.68,1400,2,ARL,325714953
1712,2025-07-17T16:02:20.938616654Z,2025-07-17T16:02:20.938451331Z,10,2,1108,A,A,0,14.810000000,100,130,165323,271679575,13.27,10,1,13.83,15,1,13.03,100,1,13.84,100,1,12.91,2,1,13.92,2,1,12.73,100,1,14.26,100,1,12.71,100,1,14.28,100,1,12.50,700,1,14.45,100,1,12.46,200,2,14.56,800,2,12.43,700,1,14.60,700,1,12.42,700,1,14.63,100,1,12.37,700,1,14.68,1400,2,ARL,325718549
1713,2025-07-17T16:02:20.938889819Z,2025-07-17T16:02:20.938724516Z,10,2,1108,C,A,0,17.760000000,100,0,165303,271679576,13.27,10,1,13.83,15,1,13.03,100,1,13.84,100,1,12.91,2,1,13.92,2,1,12.73,100,1,14.26,100,1,12.71,100,1,14.28,100,1,12.50,700,1,14.45,100,1,12.46,200,2,14.56,800,2,12.43,700,1,14.60,700,1,12.42,700,1,14.63,100,1,12.37,700,1,14.68,1400,2,ARL,325714949
1714,2025-07-17T16:02:20.938889819Z,2025-07-17T16:02:20.938724516Z,10,2,1108,A,A,0,17.580000000,100,130,165303,271679576,13.27,10,1,13.83,15,1,13.03,100,1,13.84,100,1,12.91,2,1,13.92,2,1,12.73,100,1,14.26,100,1,12.71,100,1,14.28,100,1,12.50,700,1,14.45,100,1,12.46,200,2,14.56,800,2,12.43,700,1,14.60,700,1,12.42,700,1,14.63,100,1,12.37,700,1,14.68,1400,2,ARL,325718557
1715,2025-07-17T16:02:20.939554686Z,2025-07-17T16:02:20.939389367Z,10,2,1108,A,B,0,13.020000000,100,130,165319,271679578,13.27,10,1,13.83,15,1,13.03,100,1,13.84,100,1,13.02,100,1,13.92,2,1,12.91,2,1,14.26,100,1,12.73,100,1,14.28,100,1,12.71,100,1,14.45,100,1,12.50,700,1,14.56,800,2,12.46,200,2,14.60,700,1,12.43,700,1,14.63,100,1,12.42,700,1,14.68,1400,2,ARL,325718561
1716,2025-07-17T16:02:20.946406202Z,2025-07-17T16:02:20.946240970Z,10,2,1108,C,A,0,14.260000000,100,130,165232,271679616,13.27,10,1,13.83,15,1,13.03,100,1,13.84,100,1,13.02,100,1,13.92,2,1,12.91,2,1,14.28,100,1,12.73,100,1,14.45,100,1,12.71,100,1,14.56,800,2,12.50,700,1,14.60,700,1,12.46,200,2,14.63,100,1,12.43,700,1,14.68,1400,2,12.42,700,1,14.73,200,2,ARL,325715045
1717,2025-07-17T16:02:20.946456786Z,2025-07-17T16:02:20.946291345Z,10,2,1108,A,A,0,14.120000000,100,130,165441,271679617,13.27,10,1,13.83,15,1,13.03,100,1,13.84,100,1,13.02,100,1,13.92,2,1,12.91,2,1,14.12,100,1,12.73,100,1,14.28,100,1,12.71,100,1,14.45,100,1,12.50,700,1,14.56,800,2,12.46,200,2,14.60,700,1,12.43,700,1,14.63,100,1,12.42,700,1,14.68,1400,2,ARL,325718637
1718,2025-07-17T16:02:20.957051613Z,2025-07-17T16:02:20.956886401Z,10,2,1108,C,B,0,13.020000000,100,0,165212,271679685,13.27,10,1,13.83,15,1,13.03,100,1,13.84,100,1,12.91,2,1,13.92,2,1,12.73,100,1,14.12,100,1,12.71,100,1,14.28,100,1,12.50,700,1,14.45,100,1,12.46,200,2,14.56,800,2,12.43,700,1,14.60,700,1,12.42,700,1,14.63,100,1,12.37,700,1,14.68,1400,2,ARL,325718561
1719,2025-07-17T16:02:20.957051613Z,2025-07-17T16:02:20.956886401Z,10,2,1108,A,B,0,13.260000000,100,130,165212,271679685,13.27,10,1,13.83,15,1,13.26,100,1,13.84,100,1,13.03,100,1,13.92,2,1,12.91,2,1,14.12,100,1,12.73,100,1,14.28,100,1,12.71,100,1,14.45,100,1,12.50,700,1,14.56,800,2,12.46,200,2,14.60,700,1,12.43,700,1,14.63,100,1,12.42,700,1,14.68,1400,2,ARL,325718821
1720,2025-07-17T16:02:20.957089143Z,2025-07-17T16:02:20.956923753Z,10,2,1108,A,B,0,13.120000000,100,130,165390,271679686,13.27,10,1,13.83,15,1,13.26,100,1,13.84,100,1,13.12,100,1,13.92,2,1,13.03,100,1,14.12,100,1,12.91,2,1,14.28,100,1,12.73,100,1,14.45,100,1,12.71,100,1,14.56,800,2,12.50,700,1,14.60,700,1,12.46,200,2,14.63,100,1,12.43,700,1,14.68,1400,2,ARL,325718833
1721,2025-07-17T16:02:20.957090484Z,2025-07-17T16:02:20.956925447Z,10,2,1108,A,B,0,13.120000000,100,130,165037,271679687,13.27,10,1,13.83,15,1,13.26,100,1,13.84,100,1,13.12,200,2,13.92,2,1,13.03,100,1,14.12,100,1,12.91,2,1,14.28,100,1,12.73,100,1,14.45,100,1,12.71,100,1,14.56,800,2,12.50,700,1,14.60,700,1,12.46,200,2,14.63,100,1,12.43,700,1,14.68,1400,2,ARL,325718837
1722,2025-07-17T16:02:20.988655870Z,2025-07-17T16:02:20.988490644Z,10,2,1108,A,A,0,13.980000000,100,130,165226,271679923,13.27,10,1,13.83,15,1,13.26,100,1,13.84,100,1,13.12,200,2,13.92,2,1,13.03,100,1,13.98,100,1,12.91,2,1,14.12,100,1,12.73,100,1,14.28,100,1,12.71,100,1,14.45,100,1,12.50,700,1,14.56,800,2,12.46,200,2,14.60,700,1,12.43,700,1,14.63,100,1,ARL,325719353
1723,2025-07-17T16:02:20.988656944Z,2025-07-17T16:02:20.988491826Z,10,2,1108,A,A,0,13.980000000,100,130,165118,271679924,13.27,10,1,13.83,15,1,13.26,100,1,13.84,100,1,13.12,200,2,13.92,2,1,13.03,100,1,13.98,200,2,12.91,2,1,14.12,100,1,12.73,100,1,14.28,100,1,12.71,100,1,14.45,100,1,12.50,700,1,14.56,800,2,12.46,200,2,14.60,700,1,12.43,700,1,14.63,100,1,ARL,325719357
1724,2025-07-17T16:02:30.805193695Z,2025-07-17T16:02:30.805028316Z,10,2,1108,C,B,0,13.270000000,10,130,165379,271818376,13.26,100,1,13.83,15,1,13.12,200,2,13.84,100,1,13.03,100,1,13.92,2,1,12.91,2,1,13.98,200,2,12.73,100,1,14.12,100,1,12.71,100,1,14.28,100,1,12.50,700,1,14.45,100,1,12.46,200,2,14.56,800,2,12.43,700,1,14.60,700,1,12.42,700,1,14.63,100,1,ARL,325714717
1725,2025-07-17T16:02:34.987171397Z,2025-07-17T16:02:34.987005787Z,10,2,1108,C,B,0,12.910000000,2,0,165610,271871706,13.26,100,1,13.83,15,1,13.12,200,2,13.84,100,1,13.03,100,1,13.92,2,1,12.73,100,1,13.98,200,2,12.71,100,1,14.12,100,1,12.50,700,1,14.28,100,1,12.46,200,2,14.45,100,1,12.43,700,1,14.56,800,2,12.42,700,1,14.60,700,1,12.37,700,1,14.63,100,1,ARL,325714741
1726,2025-07-17T16:02:34.987171397Z,2025-07-17T16:02:34.987005787Z,10,2,1108,A,B,0,13.000000000,2,130,165610,271871706,13.26,100,1,13.83,15,1,13.12,200,2,13.84,100,1,13.03,100,1,13.92,2,1,13.00,2,1,13.98,200,2,12.73,100,1,14.12,100,1,12.71,100,1,14.28,100,1,12.50,700,1,14.45,100,1,12.46,200,2,14.56,800,2,12.43,700,1,14.60,700,1,12.42,700,1,14.63,100,1,ARL,325967705
1727,2025-07-17T16:02:39.809464961Z,2025-07-17T16:02:39.809299504Z,10,2,1108,A,A,0,13.790000000,15,130,165457,271952021,13.26,100,1,13.79,15,1,13.12,200,2,13.83,15,1,13.03,100,1,13.84,100,1,13.00,2,1,13.92,2,1,12.73,100,1,13.98,200,2,12.71,100,1,14.12,100,1,12.50,700,1,14.28,100,1,12.46,200,2,14.45,100,1,12.43,700,1,14.56,800,2,12.42,700,1,14.60,700,1,ARL,326077141
1728,2025-07-17T16:02:40.007472020Z,2025-07-17T16:02:40.007306432Z,10,2,1108,C,A,0,13.840000000,100,0,165588,271957331,13.26,100,1,13.79,15,1,13.12,200,2,13.83,15,1,13.03,100,1,13.92,2,1,13.00,2,1,13.98,200,2,12.73,100,1,14.12,100,1,12.71,100,1,14.28,100,1,12.50,700,1,14.45,100,1,12.46,200,2,14.56,800,2,12.43,700,1,14.60,700,1,12.42,700,1,14.63,100,1,ARL,325718485
1729,2025-07-17T16:02:40.007472020Z,2025-07-17T16:02:40.007306432Z,10,2,1108,A,A,0,13.800000000,100,130,165588,271957331,13.26,100,1,13.79,15,1,13.12,200,2,13.80,100,1,13.03,100,1,13.83,15,1,13.00,2,1,13.92,2,1,12.73,100,1,13.98,200,2,12.71,100,1,14.12,100,1,12.50,700,1,14.28,100,1,12.46,200,2,14.45,100,1,12.43,700,1,14.56,800,2,12.42,700,1,14.60,700,1,ARL,326082329
1730,2025-07-17T16:02:40.008213654Z,2025-07-17T16:02:40.008048023Z,10,2,1108,C,A,0,14.910000000,100,0,165631,271957349,13.26,100,1,13.79,15,1,13.12,200,2,13.80,100,1,13.03,100,1,13.83,15,1,13.00,2,1,13.92,2,1,12.73,100,1,13.98,200,2,12.71,100,1,14.12,100,1,12.50,700,1,14.28,100,1,12.46,200,2,14.45,100,1,12.43,700,1,14.56,800,2,12.42,700,1,14.60,700,1,ARL,325718509
1731,2025-07-17T16:02:40.008213654Z,2025-07-17T16:02:40.008048023Z,10,2,1108,A,A,0,14.870000000,100,130,165631,271957349,13.26,100,1,13.79,15,1,13.12,200,2,13.80,100,1,13.03,100,1,13.83,15,1,13.00,2,1,13.92,2,1,12.73,100,1,13.98,200,2,12.71,100,1,14.12,100,1,12.50,700,1,14.28,100,1,12.46,200,2,14.45,100,1,12.43,700,1,14.56,800,2,12.42,700,1,14.60,700,1,ARL,326082353
1732,2025-07-17T16:02:40.795014471Z,2025-07-17T16:02:40.794847674Z,10,2,1108,C,A,0,13.790000000,15,130,166797,271972417,13.26,100,1,13.80,100,1,13.12,200,2,13.83,15,1,13.03,100,1,13.92,2,1,13.00,2,1,13.98,200,2,12.73,100,1,14.12,100,1,12.71,100,1,14.28,100,1,12.50,700,1,14.45,100,1,12.46,200,2,14.56,800,2,12.43,700,1,14.60,700,1,12.42,700,1,14.63,100,1,ARL,326077141
1733,2025-07-17T16:02:40.806305895Z,2025-07-17T16:02:40.806140621Z,10,2,1108,C,A,0,13.830000000,15,130,165274,271973288,13.26,100,1,13.80,100,1,13.12,200,2,13.92,2,1,13.03,100,1,13.98,200,2,13.00,2,1,14.12,100,1,12.73,100,1,14.28,100,1,12.71,100,1,14.45,100,1,12.50,700,1,14.56,800,2,12.46,200,2,14.60,700,1,12.43,700,1,14.63,100,1,12.42,700,1,14.68,1400,2,ARL,325714721
1734,2025-07-17T16:02:43.834428162Z,2025-07-17T16:02:43.834262065Z,10,2,1108,T,N,0,13.280000000,100,130,166097,272014629,13.26,100,1,13.80,100,1,13.12,200,2,13.92,2,1,13.03,100,1,13.98,200,2,13.00,2,1,14.12,100,1,12.73,100,1,14.28,100,1,12.71,100,1,14.45,100,1,12.50,700,1,14.56,800,2,12.46,200,2,14.60,700,1,12.43,700,1,14.63,100,1,12.42,700,1,14.68,1400,2,ARL,0
1735,2025-07-17T16:02:43.841852430Z,2025-07-17T16:02:43.841686908Z,10,2,1108,C,B,0,13.260000000,100,130,165522,272014658,13.12,200,2,13.80,100,1,13.03,100,1,13.92,2,1,13.00,2,1,13.98,200,2,12.73,100,1,14.12,100,1,12.71,100,1,14.28,100,1,12.50,700,1,14.45,100,1,12.46,200,2,14.56,800,2,12.43,700,1,14.60,700,1,12.42,700,1,14.63,100,1,12.37,700,1,14.68,1400,2,ARL,325718821
1736,2025-07-17T16:02:43.841912053Z,2025-07-17T16:02:43.841746626Z,10,2,1108,A,A,0,13.900000000,4,130,165427,272014659,13.12,200,2,13.80,100,1,13.03,100,1,13.90,4,1,13.00,2,1,13.92,2,1,12.73,100,1,13.98,200,2,12.71,100,1,14.12,100,1,12.50,700,1,14.28,100,1,12.46,200,2,14.45,100,1,12.43,700,1,14.56,800,2,12.42,700,1,14.60,700,1,12.37,700,1,14.63,100,1,ARL,326158809
1737,2025-07-17T16:02:43.842295427Z,2025-07-17T16:02:43.842130114Z,10,2,1108,C,A,0,13.800000000,100,130,165313,272014661,13.12,200,2,13.90,4,1,13.03,100,1,13.92,2,1,13.00,2,1,13.98,200,2,12.73,100,1,14.12,100,1,12.71,100,1,14.28,100,1,12.50,700,1,14.45,100,1,12.46,200,2,14.56,800,2,12.43,700,1,14.60,700,1,12.42,700,1,14.63,100,1,12.37,700,1,14.68,1400,2,ARL,326082329
1738,2025-07-17T16:02:43.843036936Z,2025-07-17T16:02:43.842871428Z,10,2,1108,C,A,0,14.870000000,100,0,165508,272014673,13.12,200,2,13.90,4,1,13.03,100,1,13.92,2,1,13.00,2,1,13.98,200,2,12.73,100,1,14.12,100,1,12.71,100,1,14.28,100,1,12.50,700,1,14.45,100,1,12.46,200,2,14.56,800,2,12.43,700,1,14.60,700,1,12.42,700,1,14.63,100,1,12.37,700,1,14.68,1400,2,ARL,326082353
1739,2025-07-17T16:02:43.843036936Z,2025-07-17T16:02:43.842871428Z,10,2,1108,A,A,0,14.920000000,100,130,165508,272014673,13.12,200,2,13.90,4,1,13.03,100,1,13.92,2,1,13.00,2,1,13.98,200,2,12.73,100,1,14.12,100,1,12.71,100,1,14.28,100,1,12.50,700,1,14.45,100,1,12.46,200,2,14.56,800,2,12.43,700,1,14.60,700,1,12.42,700,1,14.63,100,1,12.37,700,1,14.68,1400,2,ARL,326158869
1740,2025-07-17T16:02:43.843106749Z,2025-07-17T16:02:43.842941514Z,10,2,1108,A,B,0,13.110000000,100,130,165235,272014674,13.12,200,2,13.90,4,1,13.11,100,1,13.92,2,1,13.03,100,1,13.98,200,2,13.00,2,1,14.12,100,1,12.73,100,1,14.28,100,1,12.71,100,1,14.45,100,1,12.50,700,1,14.56,800,2,12.46,200,2,14.60,700,1,12.43,700,1,14.63,100,1,12.42,700,1,14.68,1400,2,ARL,326158877
1741,2025-07-17T16:02:43.843109026Z,2025-07-17T16:02:43.842943173Z,10,2,1108,C,A,0,14.810000000,100,0,165853,272014675,13.12,200,2,13.90,4,1,13.11,100,1,13.92,2,1,13.03,100,1,13.98,200,2,13.00,2,1,14.12,100,1,12.73,100,1,14.28,100,1,12.71,100,1,14.45,100,1,12.50,700,1,14.56,800,2,12.46,200,2,14.60,700,1,12.43,700,1,14.63,100,1,12.42,700,1,14.68,1400,2,ARL,325718549
1742,2025-07-17T16:02:43.843109026Z,2025-07-17T16:02:43.842943173Z,10,2,1108,A,A,0,14.960000000,100,130,165853,272014675,13.12,200,2,13.90,4,1,13.11,100,1,13.92,2,1,13.03,100,1,13.98,200,2,13.00,2,1,14.12,100,1,12.73,100,1,14.28,100,1,12.71,100,1,14.45,100,1,12.50,700,1,14.56,800,2,12.46,200,2,14.60,700,1,12.43,700,1,14.63,100,1,12.42,700,1,14.68,1400,2,ARL,326158881
1743,2025-07-17T16:02:43.843204692Z,2025-07-17T16:02:43.843039530Z,10,2,1108,C,A,0,13.900000000,4,130,165162,272014681,13.12,200,2,13.92,2,1,13.11,100,1,13.98,200,2,13.03,100,1,14.12,100,1,13.00,2,1,14.28,100,1,12.73,100,1,14.45,100,1,12.71,100,1,14.56,800,2,12.50,700,1,14.60,700,1,12.46,200,2,14.63,100,1,12.43,700,1,14.68,1400,2,12.42,700,1,14.73,200,2,ARL,326158809
1744,2025-07-17T16:02:43.843956820Z,2025-07-17T16:02:43.843791297Z,10,2,1108,C,A,0,17.580000000,100,0,165523,272014689,13.12,200,2,13.92,2,1,13.11,100,1,13.98,200,2,13.03,100,1,14.12,100,1,13.00,2,1,14.28,100,1,12.73,100,1,14.45,100,1,12.71,100,1,14.56,800,2,12.50,700,1,14.60,700,1,12.46,200,2,14.63,100,1,12.43,700,1,14.68,1400,2,12.42,700,1,14.73,200,2,ARL,325718557
1745,2025-07-17T16:02:43.843956820Z,2025-07-17T16:02:43.843791297Z,10,2,1108,A,A,0,17.760000000,100,130,165523,272014689,13.12,200,2,13.92,2,1,13.11,100,1,13.98,200,2,13.03,100,1,14.12,100,1,13.00,2,1,14.28,100,1,12.73,100,1,14.45,100,1,12.71,100,1,14.56,800,2,12.50,700,1,14.60,700,1,12.46,200,2,14.63,100,1,12.43,700,1,14.68,1400,2,12.42,700,1,14.73,200,2,ARL,326158953
1746,2025-07-17T16:02:43.844653014Z,2025-07-17T16:02:43.844487204Z,10,2,1108,C,A,0,15.920000000,100,0,165810,272014697,13.12,200,2,13.92,2,1,13.11,100,1,13.98,200,2,13.03,100,1,14.12,100,1,13.00,2,1,14.28,100,1,12.73,100,1,14.45,100,1,12.71,100,1,14.56,800,2,12.50,700,1,14.60,700,1,12.46,200,2,14.63,100,1,12.43,700,1,14.68,1400,2,12.42,700,1,14.73,200,2,ARL,325718525
1747,2025-07-17T16:02:43.844653014Z,2025-07-17T16:02:43.844487204Z,10,2,1108,A,A,0,16.080000000,100,130,165810,272014697,13.12,200,2,13.92,2,1,13.11,100,1,13.98,200,2,13.03,100,1,14.12,100,1,13.00,2,1,14.28,100,1,12.73,100,1,14.45,100,1,12.71,100,1,14.56,800,2,12.50,700,1,14.60,700,1,12.46,200,2,14.63,100,1,12.43,700,1,14.68,1400,2,12.42,700,1,14.73,200,2,ARL,326158989
1748,2025-07-17T16:02:43.844801951Z,2025-07-17T16:02:43.844636465Z,10,2,1108,C,A,0,14.810000000,100,0,165486,272014698,13.12,200,2,13.92,2,1,13.11,100,1,13.98,200,2,13.03,100,1,14.12,100,1,13.00,2,1,14.28,100,1,12.73,100,1,14.45,100,1,12.71,100,1,14.56,800,2,12.50,700,1,14.60,700,1,12.46,200,2,14.63,100,1,12.43,700,1,14.68,1400,2,12.42,700,1,14.73,200,2,ARL,325718517
1749,2025-07-17T16:02:43.844801951Z,2025-07-17T16:02:43.844636465Z,10,2,1108,A,A,0,14.960000000,100,130,165486,272014698,13.12,200,2,13.92,2,1,13.11,100,1,13.98,200,2,13.03,100,1,14.12,100,1,13.00,2,1,14.28,100,1,12.73,100,1,14.45,100,1,12.71,100,1,14.56,800,2,12.50,700,1,14.60,700,1,12.46,200,2,14.63,100,1,12.43,700,1,14.68,1400,2,12.42,700,1,14.73,200,2,ARL,326158997
1750,2025-07-17T16:02:43.847026795Z,2025-07-17T16:02:43.846861336Z,10,2,1108,C,A,0,13.920000000,2,0,165459,272014713,13.12,200,2,13.98,200,2,13.11,100,1,14.12,100,1,13.03,100,1,14.28,100,1,13.00,2,1,14.45,100,1,12.73,100,1,14.56,800,2,12.71,100,1,14.60,700,1,12.50,700,1,14.63,100,1,12.46,200,2,14.68,1400,2,12.43,700,1,14.73,200,2,12.42,700,1,14.92,100,1,ARL,325297093
1751,2025-07-17T16:02:43.847026795Z,2025-07-17T16:02:43.846861336Z,10,2,1108,A,A,0,14.030000000,2,130,165459,272014713,13.12,200,2,13.98,200,2,13.11,100,1,14.03,2,1,13.03,100,1,14.12,100,1,13.00,2,1,14.28,100,1,12.73,100,1,14.45,100,1,12.71,100,1,14.56,800,2,12.50,700,1,14.60,700,1,12.46,200,2,14.63,100,1,12.43,700,1,14.68,1400,2,12.42,700,1,14.73,200,2,ARL,326159041
1752,2025-07-17T16:02:43.847832258Z,2025-07-17T16:02:43.847666979Z,10,2,1108,C,A,0,14.730000000,100,0,165279,272014721,13.12,200,2,13.98,200,2,13.11,100,1,14.03,2,1,13.03,100,1,14.12,100,1,13.00,2,1,14.28,100,1,12.73,100,1,14.45,100,1,12.71,100,1,14.56,800,2,12.50,700,1,14.60,700,1,12.46,200,2,14.63,100,1,12.43,700,1,14.68,1400,2,12.42,700,1,14.73,100,1,ARL,325714613
1753,2025-07-17T16:02:43.847832258Z,2025-07-17T16:02:43.847666979Z,10,2,1108,A,A,0,14.870000000,100,130,165279,272014721,13.12,200,2,13.98,200,2,13.11,100,1,14.03,2,1,13.03,100,1,14.12,100,1,13.00,2,1,14.28,100,1,12.73,100,1,14.45,100,1,12.71,100,1,14.56,800,2,12.50,700,1,14.60,700,1,12.46,200,2,14.63,100,1,12.43,700,1,14.68,1400,2,12.42,700,1,14.73,100,1,ARL,326159049
1754,2025-07-17T16:02:43.848147198Z,2025-07-17T16:02:43.847981726Z,10,2,1108,C,A,0,14.730000000,100,0,165472,272014724,13.12,200,2,13.98,200,2,13.11,100,1,14.03,2,1,13.03,100,1,14.12,100,1,13.00,2,1,14.28,100,1,12.73,100,1,14.45,100,1,12.71,100,1,14.56,800,2,12.50,700,1,14.60,700,1,12.46,200,2,14.63,100,1,12.43,700,1,14.68,1400,2,12.42,700,1,14.87,100,1,ARL,325714577
1755,2025-07-17T16:02:43.848147198Z,2025-07-17T16:02:43.847981726Z,10,2,1108,A,A,0,14.870000000,100,130,165472,272014724,13.12,200,2,13.98,200,2,13.11,100,1,14.03,2,1,13.03,100,1,14.12,100,1,13.00,2,1,14.28,100,1,12.73,100,1,14.45,100,1,12.71,100,1,14.56,800,2,12.50,700,1,14.60,700,1,12.46,200,2,14.63,100,1,12.43,700,1,14.68,1400,2,12.42,700,1,14.87,200,2,ARL,326159061
1756,2025-07-17T16:02:43.860199647Z,2025-07-17T16:02:43.860034354Z,10,2,1108,C,A,0,14.120000000,100,130,165293,272014788,13.12,200,2,13.98,200,2,13.11,100,1,14.03,2,1,13.03,100,1,14.28,100,1,13.00,2,1,14.45,100,1,12.73,100,1,14.56,800,2,12.71,100,1,14.60,700,1,12.50,700,1,14.63,100,1,12.46,200,2,14.68,1400,2,12.43,700,1,14.87,200,2,12.42,700,1,14.92,100,1,ARL,325718637
1757,2025-07-17T16:02:43.860252446Z,2025-07-17T16:02:43.860087215Z,10,2,1108,A,A,0,14.260000000,100,130,165231,272014789,13.12,200,2,13.98,200,2,13.11,100,1,14.03,2,1,13.03,100,1,14.26,100,1,13.00,2,1,14.28,100,1,12.73,100,1,14.45,100,1,12.71,100,1,14.56,800,2,12.50,700,1,14.60,700,1,12.46,200,2,14.63,100,1,12.43,700,1,14.68,1400,2,12.42,700,1,14.87,200,2,ARL,326159201
1758,2025-07-17T16:02:43.893176312Z,2025-07-17T16:02:43.893011012Z,10,2,1108,C,A,0,14.920000000,100,0,165300,272014986,13.12,200,2,13.98,200,2,13.11,100,1,14.03,2,1,13.03,100,1,14.26,100,1,13.00,2,1,14.28,100,1,12.73,100,1,14.45,100,1,12.71,100,1,14.56,800,2,12.50,700,1,14.60,700,1,12.46,200,2,14.63,100,1,12.43,700,1,14.68,1400,2,12.42,700,1,14.87,200,2,ARL,326158869
1759,2025-07-17T16:02:43.893176312Z,2025-07-17T16:02:43.893011012Z,10,2,1108,A,A,0,15.060000000,100,130,165300,272014986,13.12,200,2,13.98,200,2,13.11,100,1,14.03,2,1,13.03,100,1,14.26,100,1,13.00,2,1,14.28,100,1,12.73,100,1,14.45,100,1,12.71,100,1,14.56,800,2,12.50,700,1,14.60,700,1,12.46,200,2,14.63,100,1,12.43,700,1,14.68,1400,2,12.42,700,1,14.87,200,2,ARL,326159425
1760,2025-07-17T16:02:43.946967137Z,2025-07-17T16:02:43.946801538Z,10,2,1108,C,A,0,14.630000000,100,0,165599,272015584,13.12,200,2,13.98,200,2,13.11,100,1,14.03,2,1,13.03,100,1,14.26,100,1,13.00,2,1,14.28,100,1,12.73,100,1,14.45,100,1,12.71,100,1,14.56,800,2,12.50,700,1,14.60,700,1,12.46,200,2,14.68,1400,2,12.43,700,1,14.87,200,2,12.42,700,1,14.96,200,2,ARL,325714653
1761,2025-07-17T16:02:43.946967137Z,2025-07-17T16:02:43.946801538Z,10,2,1108,A,A,0,14.770000000,100,130,165599,272015584,13.12,200,2,13.98,200,2,13.11,100,1,14.03,2,1,13.03,100,1,14.26,100,1,13.00,2,1,14.28,100,1,12.73,100,1,14.45,100,1,12.71,100,1,14.56,800,2,12.50,700,1,14.60,700,1,12.46,200,2,14.68,1400,2,12.43,700,1,14.77,100,1,12.42,700,1,14.87,200,2,ARL,326160141
1762,2025-07-17T16:02:44.664219784Z,2025-07-17T16:02:44.664054457Z,10,2,1108,A,A,0,13.990000000,100,130,165327,272021808,13.12,200,2,13.98,200,2,13.11,100,1,13.99,100,1,13.03,100,1,14.03,2,1,13.00,2,1,14.26,100,1,12.73,100,1,14.28,100,1,12.71,100,1,14.45,100,1,12.50,700,1,14.56,800,2,12.46,200,2,14.60,700,1,12.43,700,1,14.68,1400,2,12.42,700,1,14.77,100,1,ARL,326167529
1763,2025-07-17T16:03:02.985987598Z,2025-07-17T16:03:02.985818199Z,10,2,1108,C,A,0,14.870000000,100,0,169399,272331833,13.12,200,2,13.98,200,2,13.11,100,1,13.99,100,1,13.03,100,1,14.03,2,1,13.00,2,1,14.26,100,1,12.73,100,1,14.28,100,1,12.71,100,1,14.45,100,1,12.50,700,1,14.56,800,2,12.46,200,2,14.60,700,1,12.43,700,1,14.68,1400,2,12.42,700,1,14.77,100,1,ARL,326159049
1764,2025-07-17T16:03:02.985987598Z,2025-07-17T16:03:02.985818199Z,10,2,1108,A,A,0,14.700000000,100,128,169399,272331833,13.12,200,2,13.98,200,2,13.11,100,1,13.99,100,1,13.03,100,1,14.03,2,1,13.00,2,1,14.26,100,1,12.73,100,1,14.28,100,1,12.71,100,1,14.45,100,1,12.50,700,1,14.56,800,2,12.46,200,2,14.60,700,1,12.43,700,1,14.68,1400,2,12.42,700,1,14.70,100,1,ARL,326551237
1765,2025-07-17T16:03:02.987969729Z,2025-07-17T16:03:02.987797728Z,10,2,1108,C,A,0,14.870000000,100,0,172001,272332718,13.12,200,2,13.98,200,2,13.11,100,1,13.99,100,1,13.03,100,1,14.03,2,1,13.00,2,1,14.26,100,1,12.73,100,1,14.28,100,1,12.71,100,1,14.45,100,1,12.50,700,1,14.56,800,2,12.46,200,2,14.60,700,1,12.43,700,1,14.68,1400,2,12.42,700,1,14.70,100,1,ARL,326159061
1766,2025-07-17T16:03:02.987969729Z,2025-07-17T16:03:02.987797728Z,10,2,1108,A,A,0,14.700000000,100,128,172001,272332718,13.12,200,2,13.98,200,2,13.11,100,1,13.99,100,1,13.03,100,1,14.03,2,1,13.00,2,1,14.26,100,1,12.73,100,1,14.28,100,1,12.71,100,1,14.45,100,1,12.50,700,1,14.56,800,2,12.46,200,2,14.60,700,1,12.43,700,1,14.68,1400,2,12.42,700,1,14.70,200,2,ARL,326551829
1767,2025-07-17T16:03:10.807446975Z,2025-07-17T16:03:10.807281669Z,10,2,1108,A,A,0,13.720000000,15,130,165306,272474575,13.12,200,2,13.72,15,1,13.11,100,1,13.98,200,2,13.03,100,1,13.99,100,1,13.00,2,1,14.03,2,1,12.73,100,1,14.26,100,1,12.71,100,1,14.28,100,1,12.50,700,1,14.45,100,1,12.46,200,2,14.56,800,2,12.43,700,1,14.60,700,1,12.42,700,1,14.68,1400,2,ARL,326729677
1768,2025-07-17T16:03:10.807714421Z,2025-07-17T16:03:10.807548848Z,10,2,1108,C,A,0,13.990000000,100,0,165573,272474576,13.12,200,2,13.72,15,1,13.11,100,1,13.98,200,2,13.03,100,1,14.03,2,1,13.00,2,1,14.26,100,1,12.73,100,1,14.28,100,1,12.71,100,1,14.45,100,1,12.50,700,1,14.56,800,2,12.46,200,2,14.60,700,1,12.43,700,1,14.68,1400,2,12.42,700,1,14.70,200,2,ARL,326167529
1769,2025-07-17T16:03:10.807714421Z,2025-07-17T16:03:10.807548848Z,10,2,1108,A,A,0,13.730000000,100,130,165573,272474576,13.12,200,2,13.72,15,1,13.11,100,1,13.73,100,1,13.03,100,1,13.98,200,2,13.00,2,1,14.03,2,1,12.73,100,1,14.26,100,1,12.71,100,1,14.28,100,1,12.50,700,1,14.45,100,1,12.46,200,2,14.56,800,2,12.43,700,1,14.60,700,1,12.42,700,1,14.68,1400,2,ARL,326729685
1770,2025-07-17T16:03:10.808457278Z,2025-07-17T16:03:10.808290914Z,10,2,1108,C,A,0,15.060000000,100,0,166364,272474580,13.12,200,2,13.72,15,1,13.11,100,1,13.73,100,1,13.03,100,1,13.98,200,2,13.00,2,1,14.03,2,1,12.73,100,1,14.26,100,1,12.71,100,1,14.28,100,1,12.50,700,1,14.45,100,1,12.46,200,2,14.56,800,2,12.43,700,1,14.60,700,1,12.42,700,1,14.68,1400,2,ARL,326159425
1771,2025-07-17T16:03:10.808457278Z,2025-07-17T16:03:10.808290914Z,10,2,1108,A,A,0,14.790000000,100,128,166364,272474580,13.12,200,2,13.72,15,1,13.11,100,1,13.73,100,1,13.03,100,1,13.98,200,2,13.00,2,1,14.03,2,1,12.73,100,1,14.26,100,1,12.71,100,1,14.28,100,1,12.50,700,1,14.45,100,1,12.46,200,2,14.56,800,2,12.43,700,1,14.60,700,1,12.42,700,1,14.68,1400,2,ARL,326729705
1772,2025-07-17T16:03:10.809707274Z,2025-07-17T16:03:10.809541651Z,10,2,1108,C,A,0,14.960000000,100,0,165623,272474585,13.12,200,2,13.72,15,1,13.11,100,1,13.73,100,1,13.03,100,1,13.98,200,2,13.00,2,1,14.03,2,1,12.73,100,1,14.26,100,1,12.71,100,1,14.28,100,1,12.50,700,1,14.45,100,1,12.46,200,2,14.56,800,2,12.43,700,1,14.60,700,1,12.42,700,1,14.68,1400,2,ARL,326158881
1773,2025-07-17T16:03:10.809707274Z,2025-07-17T16:03:10.809541651Z,10,2,1108,A,A,0,14.700000000,100,130,165623,272474585,13.12,200,2,13.72,15,1,13.11,100,1,13.73,100,1,13.03,100,1,13.98,200,2,13.00,2,1,14.03,2,1,12.73,100,1,14.26,100,1,12.71,100,1,14.28,100,1,12.50,700,1,14.45,100,1,12.46,200,2,14.56,800,2,12.43,700,1,14.60,700,1,12.42,700,1,14.68,1400,2,ARL,326729721
1774,2025-07-17T16:03:10.809936821Z,2025-07-17T16:03:10.809771527Z,10,2,1108,C,A,0,14.770000000,100,130,165294,272474594,13.12,200,2,13.72,15,1,13.11,100,1,13.73,100,1,13.03,100,1,13.98,200,2,13.00,2,1,14.03,2,1,12.73,100,1,14.26,100,1,12.71,100,1,14.28,100,1,12.50,700,1,14.45,100,1,12.46,200,2,14.56,800,2,12.43,700,1,14.60,700,1,12.42,700,1,14.68,1400,2,ARL,326160141
1775,2025-07-17T16:03:10.809963577Z,2025-07-17T16:03:10.809798084Z,10,2,1108,C,A,0,17.760000000,100,0,165493,272474595,13.12,200,2,13.72,15,1,13.11,100,1,13.73,100,1,13.03,100,1,13.98,200,2,13.00,2,1,14.03,2,1,12.73,100,1,14.26,100,1,12.71,100,1,14.28,100,1,12.50,700,1,14.45,100,1,12.46,200,2,14.56,800,2,12.43,700,1,14.60,700,1,12.42,700,1,14.68,1400,2,ARL,326158953
1776,2025-07-17T16:03:10.809963577Z,2025-07-17T16:03:10.809798084Z,10,2,1108,A,A,0,17.440000000,100,130,165493,272474595,13.12,200,2,13.72,15,1,13.11,100,1,13.73,100,1,13.03,100,1,13.98,200,2,13.00,2,1,14.03,2,1,12.73,100,1,14.26,100,1,12.71,100,1,14.28,100,1,12.50,700,1,14.45,100,1,12.46,200,2,14.56,800,2,12.43,700,1,14.60,700,1,12.42,700,1,14.68,1400,2,ARL,326729725
1777,2025-07-17T16:03:10.810059442Z,2025-07-17T16:03:10.809894317Z,10,2,1108,A,A,0,14.520000000,100,130,165125,272474597,13.12,200,2,13.72,15,1,13.11,100,1,13.73,100,1,13.03,100,1,13.98,200,2,13.00,2,1,14.03,2,1,12.73,100,1,14.26,100,1,12.71,100,1,14.28,100,1,12.50,700,1,14.45,100,1,12.46,200,2,14.52,100,1,12.43,700,1,14.56,800,2,12.42,700,1,14.60,700,1,ARL,326729729
1778,2025-07-17T16:03:10.810478524Z,2025-07-17T16:03:10.810312923Z,10,2,1108,C,A,0,16.080000000,100,0,165601,272474600,13.12,200,2,13.72,15,1,13.11,100,1,13.73,100,1,13.03,100,1,13.98,200,2,13.00,2,1,14.03,2,1,12.73,100,1,14.26,100,1,12.71,100,1,14.28,100,1,12.50,700,1,14.45,100,1,12.46,200,2,14.52,100,1,12.43,700,1,14.56,800,2,12.42,700,1,14.60,700,1,ARL,326158989
1779,2025-07-17T16:03:10.810478524Z,2025-07-17T16:03:10.810312923Z,10,2,1108,A,A,0,15.790000000,100,130,165601,272474600,13.12,200,2,13.72,15,1,13.11,100,1,13.73,100,1,13.03,100,1,13.98,200,2,13.00,2,1,14.03,2,1,12.73,100,1,14.26,100,1,12.71,100,1,14.28,100,1,12.50,700,1,14.45,100,1,12.46,200,2,14.52,100,1,12.43,700,1,14.56,800,2,12.42,700,1,14.60,700,1,ARL,326729733
1780,2025-07-17T16:03:10.814646270Z,2025-07-17T16:03:10.814480532Z,10,2,1108,C,A,0,14.960000000,100,0,165738,272474635,13.12,200,2,13.72,15,1,13.11,100,1,13.73,100,1,13.03,100,1,13.98,200,2,13.00,2,1,14.03,2,1,12.73,100,1,14.26,100,1,12.71,100,1,14.28,100,1,12.50,700,1,14.45,100,1,12.46,200,2,14.52,100,1,12.43,700,1,14.56,800,2,12.42,700,1,14.60,700,1,ARL,326158997
1781,2025-07-17T16:03:10.814646270Z,2025-07-17T16:03:10.814480532Z,10,2,1108,A,A,0,14.700000000,100,130,165738,272474635,13.12,200,2,13.72,15,1,13.11,100,1,13.73,100,1,13.03,100,1,13.98,200,2,13.00,2,1,14.03,2,1,12.73,100,1,14.26,100,1,12.71,100,1,14.28,100,1,12.50,700,1,14.45,100,1,12.46,200,2,14.52,100,1,12.43,700,1,14.56,800,2,12.42,700,1,14.60,700,1,ARL,326729821
1782,2025-07-17T16:03:10.817866066Z,2025-07-17T16:03:10.817700664Z,10,2,1108,C,A,0,14.260000000,100,130,165402,272474675,13.12,200,2,13.72,15,1,13.11,100,1,13.73,100,1,13.03,100,1,13.98,200,2,13.00,2,1,14.03,2,1,12.73,100,1,14.28,100,1,12.71,100,1,14.45,100,1,12.50,700,1,14.52,100,1,12.46,200,2,14.56,800,2,12.43,700,1,14.60,700,1,12.42,700,1,14.68,1400,2,ARL,326159201
1783,2025-07-17T16:03:10.817919970Z,2025-07-17T16:03:10.817754737Z,10,2,1108,A,A,0,14.000000000,100,130,165233,272474676,13.12,200,2,13.72,15,1,13.11,100,1,13.73,100,1,13.03,100,1,13.98,200,2,13.00,2,1,14.00,100,1,12.73,100,1,14.03,2,1,12.71,100,1,14.28,100,1,12.50,700,1,14.45,100,1,12.46,200,2,14.52,100,1,12.43,700,1,14.56,800,2,12.42,700,1,14.60,700,1,ARL,326729929
1784,2025-07-17T16:03:10.843337845Z,2025-07-17T16:03:10.843172549Z,10,2,1108,A,A,0,15.660000000,100,130,165296,272474826,13.12,200,2,13.72,15,1,13.11,100,1,13.73,100,1,13.03,100,1,13.98,200,2,13.00,2,1,14.00,100,1,12.73,100,1,14.03,2,1,12.71,100,1,14.28,100,1,12.50,700,1,14.45,100,1,12.46,200,2,14.52,100,1,12.43,700,1,14.56,800,2,12.42,700,1,14.60,700,1,ARL,326730513
1785,2025-07-17T16:03:10.843350160Z,2025-07-17T16:03:10.843184785Z,10,2,1108,C,A,0,15.940000000,100,130,165375,272474827,13.12,200,2,13.72,15,1,13.11,100,1,13.73,100,1,13.03,100,1,13.98,200,2,13.00,2,1,14.00,100,1,12.73,100,1,14.03,2,1,12.71,100,1,14.28,100,1,12.50,700,1,14.45,100,1,12.46,200,2,14.52,100,1,12.43,700,1,14.56,800,2,12.42,700,1,14.60,700,1,ARL,325714909
1786,2025-07-17T16:03:10.843615537Z,2025-07-17T16:03:10.843448998Z,10,2,1108,C,A,0,13.980000000,100,0,166539,272474828,13.12,200,2,13.72,15,1,13.11,100,1,13.73,100,1,13.03,100,1,13.98,100,1,13.00,2,1,14.00,100,1,12.73,100,1,14.03,2,1,12.71,100,1,14.28,100,1,12.50,700,1,14.45,100,1,12.46,200,2,14.52,100,1,12.43,700,1,14.56,800,2,12.42,700,1,14.60,700,1,ARL,325719357
1787,2025-07-17T16:03:10.843615537Z,2025-07-17T16:03:10.843449402Z,10,2,1108,C,A,0,13.980000000,100,130,166135,272474829,13.12,200,2,13.72,15,1,13.11,100,1,13.73,100,1,13.03,100,1,14.00,100,1,13.00,2,1,14.03,2,1,12.73,100,1,14.28,100,1,12.71,100,1,14.45,100,1,12.50,700,1,14.52,100,1,12.46,200,2,14.56,800,2,12.43,700,1,14.60,700,1,12.42,700,1,14.68,1400,2,ARL,325719353
1788,2025-07-17T16:03:10.843628246Z,2025-07-17T16:03:10.843462898Z,10,2,1108,A,A,0,13.870000000,100,130,165348,272474830,13.12,200,2,13.72,15,1,13.11,100,1,13.73,100,1,13.03,100,1,13.87,100,1,13.00,2,1,14.00,100,1,12.73,100,1,14.03,2,1,12.71,100,1,14.28,100,1,12.50,700,1,14.45,100,1,12.46,200,2,14.52,100,1,12.43,700,1,14.56,800,2,12.42,700,1,14.60,700,1,ARL,326730517
1789,2025-07-17T16:03:10.843629633Z,2025-07-17T16:03:10.843464369Z,10,2,1108,A,A,0,13.870000000,100,130,165264,272474831,13.12,200,2,13.72,15,1,13.11,100,1,13.73,100,1,13.03,100,1,13.87,200,2,13.00,2,1,14.00,100,1,12.73,100,1,14.03,2,1,12.71,100,1,14.28,100,1,12.50,700,1,14.45,100,1,12.46,200,2,14.52,100,1,12.43,700,1,14.56,800,2,12.42,700,1,14.60,700,1,ARL,326730521
1790,2025-07-17T16:03:16.348189077Z,2025-07-17T16:03:16.348023740Z,10,2,1108,A,A,0,13.690000000,15,130,165337,272557172,13.12,200,2,13.69,15,1,13.11,100,1,13.72,15,1,13.03,100,1,13.73,100,1,13.00,2,1,13.87,200,2,12.73,100,1,14.00,100,1,12.71,100,1,14.03,2,1,12.50,700,1,14.28,100,1,12.46,200,2,14.45,100,1,12.43,700,1,14.52,100,1,12.42,700,1,14.56,800,2,ARL,326835877
1791,2025-07-17T16:03:16.348468824Z,2025-07-17T16:03:16.348302787Z,10,2,1108,C,A,0,14.700000000,100,0,166037,272557230,13.12,200,2,13.69,15,1,13.11,100,1,13.72,15,1,13.03,100,1,13.73,100,1,13.00,2,1,13.87,200,2,12.73,100,1,14.00,100,1,12.71,100,1,14.03,2,1,12.50,700,1,14.28,100,1,12.46,200,2,14.45,100,1,12.43,700,1,14.52,100,1,12.42,700,1,14.56,800,2,ARL,326551829
1792,2025-07-17T16:03:16.348468824Z,2025-07-17T16:03:16.348302787Z,10,2,1108,A,A,0,14.580000000,100,130,166037,272557230,13.12,200,2,13.69,15,1,13.11,100,1,13.72,15,1,13.03,100,1,13.73,100,1,13.00,2,1,13.87,200,2,12.73,100,1,14.00,100,1,12.71,100,1,14.03,2,1,12.50,700,1,14.28,100,1,12.46,200,2,14.45,100,1,12.43,700,1,14.52,100,1,12.42,700,1,14.56,800,2,ARL,326835885
1793,2025-07-17T16:03:16.349679949Z,2025-07-17T16:03:16.349513354Z,10,2,1108,C,A,0,14.700000000,100,0,166595,272557430,13.12,200,2,13.69,15,1,13.11,100,1,13.72,15,1,13.03,100,1,13.73,100,1,13.00,2,1,13.87,200,2,12.73,100,1,14.00,100,1,12.71,100,1,14.03,2,1,12.50,700,1,14.28,100,1,12.46,200,2,14.45,100,1,12.43,700,1,14.52,100,1,12.42,700,1,14.56,800,2,ARL,326551237
1794,2025-07-17T16:03:16.349679949Z,2025-07-17T16:03:16.349513354Z,10,2,1108,A,A,0,14.580000000,100,130,166595,272557430,13.12,200,2,13.69,15,1,13.11,100,1,13.72,15,1,13.03,100,1,13.73,100,1,13.00,2,1,13.87,200,2,12.73,100,1,14.00,100,1,12.71,100,1,14.03,2,1,12.50,700,1,14.28,100,1,12.46,200,2,14.45,100,1,12.43,700,1,14.52,100,1,12.42,700,1,14.56,800,2,ARL,326836085
1795,2025-07-17T16:03:16.352011831Z,2025-07-17T16:03:16.351845457Z,10,2,1108,C,A,0,13.730000000,100,0,166374,272557789,13.12,200,2,13.69,15,1,13.11,100,1,13.72,15,1,13.03,100,1,13.87,200,2,13.00,2,1,14.00,100,1,12.73,100,1,14.03,2,1,12.71,100,1,14.28,100,1,12.50,700,1,14.45,100,1,12.46,200,2,14.52,100,1,12.43,700,1,14.56,800,2,12.42,700,1,14.58,200,2,ARL,326729685
1796,2025-07-17T16:03:16.352011831Z,2025-07-17T16:03:16.351845457Z,10,2,1108,A,A,0,13.700000000,100,130,166374,272557789,13.12,200,2,13.69,15,1,13.11,100,1,13.70,100,1,13.03,100,1,13.72,15,1,13.00,2,1,13.87,200,2,12.73,100,1,14.00,100,1,12.71,100,1,14.03,2,1,12.50,700,1,14.28,100,1,12.46,200,2,14.45,100,1,12.43,700,1,14.52,100,1,12.42,700,1,14.56,800,2,ARL,326836533
1797,2025-07-17T16:03:16.365985162Z,2025-07-17T16:03:16.365819243Z,10,2,1108,C,A,0,15.380000000,100,0,165919,272559024,13.12,200,2,13.69,15,1,13.11,100,1,13.70,100,1,13.03,100,1,13.72,15,1,13.00,2,1,13.87,200,2,12.73,100,1,14.00,100,1,12.71,100,1,14.03,2,1,12.50,700,1,14.28,100,1,12.46,200,2,14.45,100,1,12.43,700,1,14.52,100,1,12.42,700,1,14.56,800,2,ARL,325714965
1798,2025-07-17T16:03:16.365985162Z,2025-07-17T16:03:16.365819243Z,10,2,1108,A,A,0,15.070000000,100,130,165919,272559024,13.12,200,2,13.69,15,1,13.11,100,1,13.70,100,1,13.03,100,1,13.72,15,1,13.00,2,1,13.87,200,2,12.73,100,1,14.00,100,1,12.71,100,1,14.03,2,1,12.50,700,1,14.28,100,1,12.46,200,2,14.45,100,1,12.43,700,1,14.52,100,1,12.42,700,1,14.56,800,2,ARL,326837501
1799,2025-07-17T16:03:18.804325078Z,2025-07-17T16:03:18.804159952Z,10,2,1108,C,A,0,13.690000000,15,130,165126,272609485,13.12,200,2,13.70,100,1,13.11,100,1,13.72,15,1,13.03,100,1,13.87,200,2,13.00,2,1,14.00,100,1,12.73,100,1,14.03,2,1,12.71,100,1,14.28,100,1,12.50,700,1,14.45,100,1,12.46,200,2,14.52,100,1,12.43,700,1,14.56,800,2,12.42,700,1,14.58,200,2,ARL,326835877
1800,2025-07-17T16:03:18.804367560Z,2025-07-17T16:03:18.804202246Z,10,2,1108,C,A,0,13.700000000,100,130,165314,272609486,13.12,200,2,13.72,15,1,13.11,100,1,13.87,200,2,13.03,100,1,14.00,100,1,13.00,2,1,14.03,2,1,12.73,100,1,14.28,100,1,12.71,100,1,14.45,100,1,12.50,700,1,14.52,100,1,12.46,200,2,14.56,800,2,12.43,700,1,14.58,200,2,12.42,700,1,14.60,700,1,ARL,326836533
1801,2025-07-17T16:03:18.805099118Z,2025-07-17T16:03:18.804933488Z,10,2,1108,C,A,0,14.790000000,100,0,165630,272609510,13.12,200,2,13.72,15,1,13.11,100,1,13.87,200,2,13.03,100,1,14.00,100,1,13.00,2,1,14.03,2,1,12.73,100,1,14.28,100,1,12.71,100,1,14.45,100,1,12.50,700,1,14.52,100,1,12.46,200,2,14.56,800,2,12.43,700,1,14.58,200,2,12.42,700,1,14.60,700,1,ARL,326729705
1802,2025-07-17T16:03:18.805099118Z,2025-07-17T16:03:18.804933488Z,10,2,1108,A,A,0,14.950000000,100,130,165630,272609510,13.12,200,2,13.72,15,1,13.11,100,1,13.87,200,2,13.03,100,1,14.00,100,1,13.00,2,1,14.03,2,1,12.73,100,1,14.28,100,1,12.71,100,1,14.45,100,1,12.50,700,1,14.52,100,1,12.46,200,2,14.56,800,2,12.43,700,1,14.58,200,2,12.42,700,1,14.60,700,1,ARL,326892717
1803,2025-07-17T16:03:18.805291629Z,2025-07-17T16:03:18.805126035Z,10,2,1108,C,A,0,14.700000000,100,0,165594,272609526,13.12,200,2,13.72,15,1,13.11,100,1,13.87,200,2,13.03,100,1,14.00,100,1,13.00,2,1,14.03,2,1,12.73,100,1,14.28,100,1,12.71,100,1,14.45,100,1,12.50,700,1,14.52,100,1,12.46,200,2,14.56,800,2,12.43,700,1,14.58,200,2,12.42,700,1,14.60,700,1,ARL,326729721
1804,2025-07-17T16:03:18.805291629Z,2025-07-17T16:03:18.805126035Z,10,2,1108,A,A,0,14.850000000,100,130,165594,272609526,13.12,200,2,13.72,15,1,13.11,100,1,13.87,200,2,13.03,100,1,14.00,100,1,13.00,2,1,14.03,2,1,12.73,100,1,14.28,100,1,12.71,100,1,14.45,100,1,12.50,700,1,14.52,100,1,12.46,200,2,14.56,800,2,12.43,700,1,14.58,200,2,12.42,700,1,14.60,700,1,ARL,326892721
1805,2025-07-17T16:03:18.805449089Z,2025-07-17T16:03:18.805283236Z,10,2,1108,C,A,0,13.720000000,15,130,165853,272609541,13.12,200,2,13.87,200,2,13.11,100,1,14.00,100,1,13.03,100,1,14.03,2,1,13.00,2,1,14.28,100,1,12.73,100,1,14.45,100,1,12.71,100,1,14.52,100,1,12.50,700,1,14.56,800,2,12.46,200,2,14.58,200,2,12.43,700,1,14.60,700,1,12.42,700,1,14.68,1400,2,ARL,326729677
1806,2025-07-17T16:03:18.806535903Z,2025-07-17T16:03:18.806370373Z,10,2,1108,C,A,0,14.580000000,100,0,165530,272609577,13.12,200,2,13.87,200,2,13.11,100,1,14.00,100,1,13.03,100,1,14.03,2,1,13.00,2,1,14.28,100,1,12.73,100,1,14.45,100,1,12.71,100,1,14.52,100,1,12.50,700,1,14.56,800,2,12.46,200,2,14.58,100,1,12.43,700,1,14.60,700,1,12.42,700,1,14.68,1400,2,ARL,326835885
1807,2025-07-17T16:03:18.806535903Z,2025-07-17T16:03:18.806370373Z,10,2,1108,A,A,0,14.760000000,100,130,165530,272609577,13.12,200,2,13.87,200,2,13.11,100,1,14.00,100,1,13.03,100,1,14.03,2,1,13.00,2,1,14.28,100,1,12.73,100,1,14.45,100,1,12.71,100,1,14.52,100,1,12.50,700,1,14.56,800,2,12.46,200,2,14.58,100,1,12.43,700,1,14.60,700,1,12.42,700,1,14.68,1400,2,ARL,326892817
1808,2025-07-17T16:03:18.806802589Z,2025-07-17T16:03:18.806637004Z,10,2,1108,C,A,0,14.580000000,100,0,165585,272609583,13.12,200,2,13.87,200,2,13.11,100,1,14.00,100,1,13.03,100,1,14.03,2,1,13.00,2,1,14.28,100,1,12.73,100,1,14.45,100,1,12.71,100,1,14.52,100,1,12.50,700,1,14.56,800,2,12.46,200,2,14.60,700,1,12.43,700,1,14.68,1400,2,12.42,700,1,14.70,100,1,ARL,326836085
1809,2025-07-17T16:03:18.806802589Z,2025-07-17T16:03:18.806637004Z,10,2,1108,A,A,0,14.760000000,100,130,165585,272609583,13.12,200,2,13.87,200,2,13.11,100,1,14.00,100,1,13.03,100,1,14.03,2,1,13.00,2,1,14.28,100,1,12.73,100,1,14.45,100,1,12.71,100,1,14.52,100,1,12.50,700,1,14.56,800,2,12.46,200,2,14.60,700,1,12.43,700,1,14.68,1400,2,12.42,700,1,14.70,100,1,ARL,326892825
1810,2025-07-17T16:03:18.809706334Z,2025-07-17T16:03:18.809540733Z,10,2,1108,C,A,0,14.520000000,100,0,165601,272609656,13.12,200,2,13.87,200,2,13.11,100,1,14.00,100,1,13.03,100,1,14.03,2,1,13.00,2,1,14.28,100,1,12.73,100,1,14.45,100,1,12.71,100,1,14.56,800,2,12.50,700,1,14.60,700,1,12.46,200,2,14.68,1400,2,12.43,700,1,14.70,100,1,12.42,700,1,14.76,200,2,ARL,326729729
1811,2025-07-17T16:03:18.809706334Z,2025-07-17T16:03:18.809540733Z,10,2,1108,A,A,0,14.660000000,100,130,165601,272609656,13.12,200,2,13.87,200,2,13.11,100,1,14.00,100,1,13.03,100,1,14.03,2,1,13.00,2,1,14.28,100,1,12.73,100,1,14.45,100,1,12.71,100,1,14.56,800,2,12.50,700,1,14.60,700,1,12.46,200,2,14.66,100,1,12.43,700,1,14.68,1400,2,12.42,700,1,14.70,100,1,ARL,326892885
1812,2025-07-17T16:03:18.809848665Z,2025-07-17T16:03:18.809683187Z,10,2,1108,C,A,0,15.790000000,100,0,165478,272609658,13.12,200,2,13.87,200,2,13.11,100,1,14.00,100,1,13.03,100,1,14.03,2,1,13.00,2,1,14.28,100,1,12.73,100,1,14.45,100,1,12.71,100,1,14.56,800,2,12.50,700,1,14.60,700,1,12.46,200,2,14.66,100,1,12.43,700,1,14.68,1400,2,12.42,700,1,14.70,100,1,ARL,326729733
1813,2025-07-17T16:03:18.809848665Z,2025-07-17T16:03:18.809683187Z,10,2,1108,A,A,0,15.960000000,100,130,165478,272609658,13.12,200,2,13.87,200,2,13.11,100,1,14.00,100,1,13.03,100,1,14.03,2,1,13.00,2,1,14.28,100,1,12.73,100,1,14.45,100,1,12.71,100,1,14.56,800,2,12.50,700,1,14.60,700,1,12.46,200,2,14.66,100,1,12.43,700,1,14.68,1400,2,12.42,700,1,14.70,100,1,ARL,326892889
1814,2025-07-17T16:03:18.812107206Z,2025-07-17T16:03:18.811941680Z,10,2,1108,C,A,0,17.440000000,100,0,165526,272609679,13.12,200,2,13.87,200,2,13.11,100,1,14.00,100,1,13.03,100,1,14.03,2,1,13.00,2,1,14.28,100,1,12.73,100,1,14.45,100,1,12.71,100,1,14.56,800,2,12.50,700,1,14.60,700,1,12.46,200,2,14.66,100,1,12.43,700,1,14.68,1400,2,12.42,700,1,14.70,100,1,ARL,326729725
1815,2025-07-17T16:03:18.812107206Z,2025-07-17T16:03:18.811941680Z,10,2,1108,A,A,0,17.620000000,100,130,165526,272609679,13.12,200,2,13.87,200,2,13.11,100,1,14.00,100,1,13.03,100,1,14.03,2,1,13.00,2,1,14.28,100,1,12.73,100,1,14.45,100,1,12.71,100,1,14.56,800,2,12.50,700,1,14.60,700,1,12.46,200,2,14.66,100,1,12.43,700,1,14.68,1400,2,12.42,700,1,14.70,100,1,ARL,326892921
1816,2025-07-17T16:03:18.818245629Z,2025-07-17T16:03:18.818080239Z,10,2,1108,C,A,0,14.000000000,100,130,165390,272609768,13.12,200,2,13.87,200,2,13.11,100,1,14.03,2,1,13.03,100,1,14.28,100,1,13.00,2,1,14.45,100,1,12.73,100,1,14.56,800,2,12.71,100,1,14.60,700,1,12.50,700,1,14.66,100,1,12.46,200,2,14.68,1400,2,12.43,700,1,14.70,100,1,12.42,700,1,14.76,200,2,ARL,326729929
1817,2025-07-17T16:03:18.818301143Z,2025-07-17T16:03:18.818135688Z,10,2,1108,A,A,0,14.150000000,100,130,165455,272609769,13.12,200,2,13.87,200,2,13.11,100,1,14.03,2,1,13.03,100,1,14.15,100,1,13.00,2,1,14.28,100,1,12.73,100,1,14.45,100,1,12.71,100,1,14.56,800,2,12.50,700,1,14.60,700,1,12.46,200,2,14.66,100,1,12.43,700,1,14.68,1400,2,12.42,700,1,14.70,100,1,ARL,326893213
1818,2025-07-17T16:03:18.868420503Z,2025-07-17T16:03:18.868254768Z,10,2,1108,C,A,0,14.700000000,100,0,165735,272610397,13.12,200,2,13.87,200,2,13.11,100,1,14.03,2,1,13.03,100,1,14.15,100,1,13.00,2,1,14.28,100,1,12.73,100,1,14.45,100,1,12.71,100,1,14.56,800,2,12.50,700,1,14.60,700,1,12.46,200,2,14.66,100,1,12.43,700,1,14.68,1400,2,12.42,700,1,14.76,200,2,ARL,326729821
1819,2025-07-17T16:03:18.868420503Z,2025-07-17T16:03:18.868254768Z,10,2,1108,A,A,0,14.850000000,100,130,165735,272610397,13.12,200,2,13.87,200,2,13.11,100,1,14.03,2,1,13.03,100,1,14.15,100,1,13.00,2,1,14.28,100,1,12.73,100,1,14.45,100,1,12.71,100,1,14.56,800,2,12.50,700,1,14.60,700,1,12.46,200,2,14.66,100,1,12.43,700,1,14.68,1400,2,12.42,700,1,14.76,200,2,ARL,326893961
1820,2025-07-17T16:03:19.191219507Z,2025-07-17T16:03:19.191054306Z,10,2,1108,A,A,0,13.880000000,100,130,165201,272614303,13.12,200,2,13.87,200,2,13.11,100,1,13.88,100,1,13.03,100,1,14.03,2,1,13.00,2,1,14.15,100,1,12.73,100,1,14.28,100,1,12.71,100,1,14.45,100,1,12.50,700,1,14.56,800,2,12.46,200,2,14.60,700,1,12.43,700,1,14.66,100,1,12.42,700,1,14.68,1400,2,ARL,326899125
1821,2025-07-17T16:03:27.433957932Z,2025-07-17T16:03:27.433791643Z,10,2,1108,T,N,0,13.280000000,40,130,166289,272788756,13.12,200,2,13.87,200,2,13.11,100,1,13.88,100,1,13.03,100,1,14.03,2,1,13.00,2,1,14.15,100,1,12.73,100,1,14.28,100,1,12.71,100,1,14.45,100,1,12.50,700,1,14.56,800,2,12.46,200,2,14.60,700,1,12.43,700,1,14.66,100,1,12.42,700,1,14.68,1400,2,ARL,0
1822,2025-07-17T16:03:27.436323951Z,2025-07-17T16:03:27.436158395Z,10,2,1108,A,A,0,14.250000000,53,130,165556,272788767,13.12,200,2,13.87,200,2,13.11,100,1,13.88,100,1,13.03,100,1,14.03,2,1,13.00,2,1,14.15,100,1,12.73,100,1,14.25,53,1,12.71,100,1,14.28,100,1,12.50,700,1,14.45,100,1,12.46,200,2,14.56,800,2,12.43,700,1,14.60,700,1,12.42,700,1,14.66,100,1,ARL,327112281
1823,2025-07-17T16:03:27.436880768Z,2025-07-17T16:03:27.436715001Z,10,2,1108,C,B,0,12.230000000,100,0,165767,272788774,13.12,200,2,13.87,200,2,13.11,100,1,13.88,100,1,13.03,100,1,14.03,2,1,13.00,2,1,14.15,100,1,12.73,100,1,14.25,53,1,12.71,100,1,14.28,100,1,12.50,700,1,14.45,100,1,12.46,200,2,14.56,800,2,12.43,700,1,14.60,700,1,12.42,700,1,14.66,100,1,ARL,291964745
1824,2025-07-17T16:03:27.436880768Z,2025-07-17T16:03:27.436715001Z,10,2,1108,A,B,0,12.100000000,100,130,165767,272788774,13.12,200,2,13.87,200,2,13.11,100,1,13.88,100,1,13.03,100,1,14.03,2,1,13.00,2,1,14.15,100,1,12.73,100,1,14.25,53,1,12.71,100,1,14.28,100,1,12.50,700,1,14.45,100,1,12.46,200,2,14.56,800,2,12.43,700,1,14.60,700,1,12.42,700,1,14.66,100,1,ARL,327112289
1825,2025-07-17T16:03:27.438566971Z,2025-07-17T16:03:27.438400828Z,10,2,1108,C,B,0,12.340000000,100,0,166143,272788792,13.12,200,2,13.87,200,2,13.11,100,1,13.88,100,1,13.03,100,1,14.03,2,1,13.00,2,1,14.15,100,1,12.73,100,1,14.25,53,1,12.71,100,1,14.28,100,1,12.50,700,1,14.45,100,1,12.46,200,2,14.56,800,2,12.43,700,1,14.60,700,1,12.42,700,1,14.66,100,1,ARL,285586113
1826,2025-07-17T16:03:27.438566971Z,2025-07-17T16:03:27.438400828Z,10,2,1108,A,B,0,12.200000000,100,130,166143,272788792,13.12,200,2,13.87,200,2,13.11,100,1,13.88,100,1,13.03,100,1,14.03,2,1,13.00,2,1,14.15,100,1,12.73,100,1,14.25,53,1,12.71,100,1,14.28,100,1,12.50,700,1,14.45,100,1,12.46,200,2,14.56,800,2,12.43,700,1,14.60,700,1,12.42,700,1,14.66,100,1,ARL,327112385
1827,2025-07-17T16:03:27.438603564Z,2025-07-17T16:03:27.438437969Z,10,2,1108,C,B,0,12.340000000,100,0,165595,272788793,13.12,200,2,13.87,200,2,13.11,100,1,13.88,100,1,13.03,100,1,14.03,2,1,13.00,2,1,14.15,100,1,12.73,100,1,14.25,53,1,12.71,100,1,14.28,100,1,12.50,700,1,14.45,100,1,12.46,200,2,14.56,800,2,12.43,700,1,14.60,700,1,12.42,700,1,14.66,100,1,ARL,285586189
1828,2025-07-17T16:03:27.438603564Z,2025-07-17T16:03:27.438437969Z,10,2,1108,A,B,0,12.200000000,100,130,165595,272788793,13.12,200,2,13.87,200,2,13.11,100,1,13.88,100,1,13.03,100,1,14.03,2,1,13.00,2,1,14.15,100,1,12.73,100,1,14.25,53,1,12.71,100,1,14.28,100,1,12.50,700,1,14.45,100,1,12.46,200,2,14.56,800,2,12.43,700,1,14.60,700,1,12.42,700,1,14.66,100,1,ARL,327112393
1829,2025-07-17T16:03:27.454010355Z,2025-07-17T16:03:27.453845141Z,10,2,1108,C,B,0,13.030000000,100,130,165214,272788897,13.12,200,2,13.87,200,2,13.11,100,1,13.88,100,1,13.00,2,1,14.03,2,1,12.73,100,1,14.15,100,1,12.71,100,1,14.25,53,1,12.50,700,1,14.28,100,1,12.46,200,2,14.45,100,1,12.43,700,1,14.56,800,2,12.42,700,1,14.60,700,1,12.37,700,1,14.66,100,1,ARL,285586293
1830,2025-07-17T16:03:27.454059719Z,2025-07-17T16:03:27.453894425Z,10,2,1108,A,B,0,12.950000000,100,130,165294,272788898,13.12,200,2,13.87,200,2,13.11,100,1,13.88,100,1,13.00,2,1,14.03,2,1,12.95,100,1,14.15,100,1,12.73,100,1,14.25,53,1,12.71,100,1,14.28,100,1,12.50,700,1,14.45,100,1,12.46,200,2,14.56,800,2,12.43,700,1,14.60,700,1,12.42,700,1,14.66,100,1,ARL,327112565
1831,2025-07-17T16:03:27.454892321Z,2025-07-17T16:03:27.454726901Z,10,2,1108,C,B,0,12.950000000,100,130,165420,272788942,13.12,200,2,13.87,200,2,13.11,100,1,13.88,100,1,13.00,2,1,14.03,2,1,12.73,100,1,14.15,100,1,12.71,100,1,14.25,53,1,12.50,700,1,14.28,100,1,12.46,200,2,14.45,100,1,12.43,700,1,14.56,800,2,12.42,700,1,14.60,700,1,12.37,700,1,14.66,100,1,ARL,327112565
1832,2025-07-17T16:03:27.454939600Z,2025-07-17T16:03:27.454773691Z,10,2,1108,A,B,0,12.860000000,100,130,165909,272788943,13.12,200,2,13.87,200,2,13.11,100,1,13.88,100,1,13.00,2,1,14.03,2,1,12.86,100,1,14.15,100,1,12.73,100,1,14.25,53,1,12.71,100,1,14.28,100,1,12.50,700,1,14.45,100,1,12.46,200,2,14.56,800,2,12.43,700,1,14.60,700,1,12.42,700,1,14.66,100,1,ARL,327112577
1833,2025-07-17T16:03:27.517751270Z,2025-07-17T16:03:27.517585374Z,10,2,1108,C,B,0,12.460000000,100,130,165896,272790695,13.12,200,2,13.87,200,2,13.11,100,1,13.88,100,1,13.00,2,1,14.03,2,1,12.86,100,1,14.15,100,1,12.73,100,1,14.25,53,1,12.71,100,1,14.28,100,1,12.50,700,1,14.45,100,1,12.46,100,1,14.56,800,2,12.43,700,1,14.60,700,1,12.42,700,1,14.66,100,1,ARL,285587281
1834,2025-07-17T16:03:27.517864675Z,2025-07-17T16:03:27.517699408Z,10,2,1108,A,B,0,12.330000000,100,130,165267,272790696,13.12,200,2,13.87,200,2,13.11,100,1,13.88,100,1,13.00,2,1,14.03,2,1,12.86,100,1,14.15,100,1,12.73,100,1,14.25,53,1,12.71,100,1,14.28,100,1,12.50,700,1,14.45,100,1,12.46,100,1,14.56,800,2,12.43,700,1,14.60,700,1,12.42,700,1,14.66,100,1,ARL,327114465
1835,2025-07-17T16:03:27.536343943Z,2025-07-17T16:03:27.536178718Z,10,2,1108,C,A,0,14.250000000,53,130,165225,272791410,13.12,200,2,13.87,200,2,13.11,100,1,13.88,100,1,13.00,2,1,14.03,2,1,12.86,100,1,14.15,100,1,12.73,100,1,14.28,100,1,12.71,100,1,14.45,100,1,12.50,700,1,14.56,800,2,12.46,100,1,14.60,700,1,12.43,700,1,14.66,100,1,12.42,700,1,14.68,1400,2,ARL,327112281
1836,2025-07-17T16:03:56.548348047Z,2025-07-17T16:03:56.548182793Z,10,2,1108,A,A,0,13.800000000,15,130,165254,273208310,13.12,200,2,13.80,15,1,13.11,100,1,13.87,200,2,13.00,2,1,13.88,100,1,12.86,100,1,14.03,2,1,12.73,100,1,14.15,100,1,12.71,100,1,14.28,100,1,12.50,700,1,14.45,100,1,12.46,100,1,14.56,800,2,12.43,700,1,14.60,700,1,12.42,700,1,14.66,100,1,ARL,327675057
1837,2025-07-17T16:03:56.548611716Z,2025-07-17T16:03:56.548446336Z,10,2,1108,C,A,0,13.880000000,100,0,165380,273208316,13.12,200,2,13.80,15,1,13.11,100,1,13.87,200,2,13.00,2,1,14.03,2,1,12.86,100,1,14.15,100,1,12.73,100,1,14.28,100,1,12.71,100,1,14.45,100,1,12.50,700,1,14.56,800,2,12.46,100,1,14.60,700,1,12.43,700,1,14.66,100,1,12.42,700,1,14.68,1400,2,ARL,326899125
1838,2025-07-17T16:03:56.548611716Z,2025-07-17T16:03:56.548446336Z,10,2,1108,A,A,0,13.810000000,100,130,165380,273208316,13.12,200,2,13.80,15,1,13.11,100,1,13.81,100,1,13.00,2,1,13.87,200,2,12.86,100,1,14.03,2,1,12.73,100,1,14.15,100,1,12.71,100,1,14.28,100,1,12.50,700,1,14.45,100,1,12.46,100,1,14.56,800,2,12.43,700,1,14.60,700,1,12.42,700,1,14.66,100,1,ARL,327675065
1839,2025-07-17T16:03:56.549354405Z,2025-07-17T16:03:56.549188993Z,10,2,1108,C,A,0,14.950000000,100,0,165412,273208325,13.12,200,2,13.80,15,1,13.11,100,1,13.81,100,1,13.00,2,1,13.87,200,2,12.86,100,1,14.03,2,1,12.73,100,1,14.15,100,1,12.71,100,1,14.28,100,1,12.50,700,1,14.45,100,1,12.46,100,1,14.56,800,2,12.43,700,1,14.60,700,1,12.42,700,1,14.66,100,1,ARL,326892717
1840,2025-07-17T16:03:56.549354405Z,2025-07-17T16:03:56.549188993Z,10,2,1108,A,A,0,14.880000000,100,130,165412,273208325,13.12,200,2,13.80,15,1,13.11,100,1,13.81,100,1,13.00,2,1,13.87,200,2,12.86,100,1,14.03,2,1,12.73,100,1,14.15,100,1,12.71,100,1,14.28,100,1,12.50,700,1,14.45,100,1,12.46,100,1,14.56,800,2,12.43,700,1,14.60,700,1,12.42,700,1,14.66,100,1,ARL,327675093
1841,2025-07-17T16:04:06.233858611Z,2025-07-17T16:04:06.233692491Z,10,2,1108,C,A,0,14.760000000,100,0,166120,273345719,13.12,200,2,13.80,15,1,13.11,100,1,13.81,100,1,13.00,2,1,13.87,200,2,12.86,100,1,14.03,2,1,12.73,100,1,14.15,100,1,12.71,100,1,14.28,100,1,12.50,700,1,14.45,100,1,12.46,100,1,14.56,800,2,12.43,700,1,14.60,700,1,12.42,700,1,14.66,100,1,ARL,326892825
1842,2025-07-17T16:04:06.233858611Z,2025-07-17T16:04:06.233692491Z,10,2,1108,A,A,0,14.640000000,100,130,166120,273345719,13.12,200,2,13.80,15,1,13.11,100,1,13.81,100,1,13.00,2,1,13.87,200,2,12.86,100,1,14.03,2,1,12.73,100,1,14.15,100,1,12.71,100,1,14.28,100,1,12.50,700,1,14.45,100,1,12.46,100,1,14.56,800,2,12.43,700,1,14.60,700,1,12.42,700,1,14.64,100,1,ARL,327856297
1843,2025-07-17T16:04:06.234600198Z,2025-07-17T16:04:06.234433294Z,10,2,1108,C,A,0,14.760000000,100,0,166904,273345721,13.12,200,2,13.80,15,1,13.11,100,1,13.81,100,1,13.00,2,1,13.87,200,2,12.86,100,1,14.03,2,1,12.73,100,1,14.15,100,1,12.71,100,1,14.28,100,1,12.50,700,1,14.45,100,1,12.46,100,1,14.56,800,2,12.43,700,1,14.60,700,1,12.42,700,1,14.64,100,1,ARL,326892817
1844,2025-07-17T16:04:06.234600198Z,2025-07-17T16:04:06.234433294Z,10,2,1108,A,A,0,14.640000000,100,130,166904,273345721,13.12,200,2,13.80,15,1,13.11,100,1,13.81,100,1,13.00,2,1,13.87,200,2,12.86,100,1,14.03,2,1,12.73,100,1,14.15,100,1,12.71,100,1,14.28,100,1,12.50,700,1,14.45,100,1,12.46,100,1,14.56,800,2,12.43,700,1,14.60,700,1,12.42,700,1,14.64,200,2,ARL,327856309
1845,2025-07-17T16:04:06.510914101Z,2025-07-17T16:04:06.510748731Z,10,2,1108,A,A,0,13.720000000,15,130,165370,273352664,13.12,200,2,13.72,15,1,13.11,100,1,13.80,15,1,13.00,2,1,13.81,100,1,12.86,100,1,13.87,200,2,12.73,100,1,14.03,2,1,12.71,100,1,14.15,100,1,12.50,700,1,14.28,100,1,12.46,100,1,14.45,100,1,12.43,700,1,14.56,800,2,12.42,700,1,14.60,700,1,ARL,327863853
1846,2025-07-17T16:04:06.512413102Z,2025-07-17T16:04:06.512244746Z,10,2,1108,C,A,0,13.810000000,100,0,168356,273352888,13.12,200,2,13.72,15,1,13.11,100,1,13.80,15,1,13.00,2,1,13.87,200,2,12.86,100,1,14.03,2,1,12.73,100,1,14.15,100,1,12.71,100,1,14.28,100,1,12.50,700,1,14.45,100,1,12.46,100,1,14.56,800,2,12.43,700,1,14.60,700,1,12.42,700,1,14.64,200,2,ARL,327675065
1847,2025-07-17T16:04:06.512413102Z,2025-07-17T16:04:06.512244746Z,10,2,1108,A,A,0,13.730000000,100,128,168356,273352888,13.12,200,2,13.72,15,1,13.11,100,1,13.73,100,1,13.00,2,1,13.80,15,1,12.86,100,1,13.87,200,2,12.73,100,1,14.03,2,1,12.71,100,1,14.15,100,1,12.50,700,1,14.28,100,1,12.46,100,1,14.45,100,1,12.43,700,1,14.56,800,2,12.42,700,1,14.60,700,1,ARL,327864137
1848,2025-07-17T16:04:06.513675299Z,2025-07-17T16:04:06.513497276Z,10,2,1108,C,A,0,14.880000000,100,0,178023,273353923,13.12,200,2,13.72,15,1,13.11,100,1,13.73,100,1,13.00,2,1,13.80,15,1,12.86,100,1,13.87,200,2,12.73,100,1,14.03,2,1,12.71,100,1,14.15,100,1,12.50,700,1,14.28,100,1,12.46,100,1,14.45,100,1,12.43,700,1,14.56,800,2,12.42,700,1,14.60,700,1,ARL,327675093
1849,2025-07-17T16:04:06.513675299Z,2025-07-17T16:04:06.513497276Z,10,2,1108,A,A,0,14.790000000,100,128,178023,273353923,13.12,200,2,13.72,15,1,13.11,100,1,13.73,100,1,13.00,2,1,13.80,15,1,12.86,100,1,13.87,200,2,12.73,100,1,14.03,2,1,12.71,100,1,14.15,100,1,12.50,700,1,14.28,100,1,12.46,100,1,14.45,100,1,12.43,700,1,14.56,800,2,12.42,700,1,14.60,700,1,ARL,327864893
1850,2025-07-17T16:04:06.522853161Z,2025-07-17T16:04:06.522687474Z,10,2,1108,C,A,0,14.850000000,100,0,165687,273357758,13.12,200,2,13.72,15,1,13.11,100,1,13.73,100,1,13.00,2,1,13.80,15,1,12.86,100,1,13.87,200,2,12.73,100,1,14.03,2,1,12.71,100,1,14.15,100,1,12.50,700,1,14.28,100,1,12.46,100,1,14.45,100,1,12.43,700,1,14.56,800,2,12.42,700,1,14.60,700,1,ARL,326892721
1851,2025-07-17T16:04:06.522853161Z,2025-07-17T16:04:06.522687474Z,10,2,1108,A,A,0,14.700000000,100,130,165687,273357758,13.12,200,2,13.72,15,1,13.11,100,1,13.73,100,1,13.00,2,1,13.80,15,1,12.86,100,1,13.87,200,2,12.73,100,1,14.03,2,1,12.71,100,1,14.15,100,1,12.50,700,1,14.28,100,1,12.46,100,1,14.45,100,1,12.43,700,1,14.56,800,2,12.42,700,1,14.60,700,1,ARL,327868421
1852,2025-07-17T16:04:06.525550815Z,2025-07-17T16:04:06.525385108Z,10,2,1108,C,A,0,14.150000000,100,130,165707,273358260,13.12,200,2,13.72,15,1,13.11,100,1,13.73,100,1,13.00,2,1,13.80,15,1,12.86,100,1,13.87,200,2,12.73,100,1,14.03,2,1,12.71,100,1,14.28,100,1,12.50,700,1,14.45,100,1,12.46,100,1,14.56,800,2,12.43,700,1,14.60,700,1,12.42,700,1,14.64,200,2,ARL,326893213
1853,2025-07-17T16:04:06.525608746Z,2025-07-17T16:04:06.525442486Z,10,2,1108,A,A,0,14.000000000,100,128,166260,273358273,13.12,200,2,13.72,15,1,13.11,100,1,13.73,100,1,13.00,2,1,13.80,15,1,12.86,100,1,13.87,200,2,12.73,100,1,14.00,100,1,12.71,100,1,14.03,2,1,12.50,700,1,14.28,100,1,12.46,100,1,14.45,100,1,12.43,700,1,14.56,800,2,12.42,700,1,14.60,700,1,ARL,327869193
1854,2025-07-17T16:04:06.528210755Z,2025-07-17T16:04:06.528043934Z,10,2,1108,C,A,0,14.660000000,100,130,166821,273358598,13.12,200,2,13.72,15,1,13.11,100,1,13.73,100,1,13.00,2,1,13.80,15,1,12.86,100,1,13.87,200,2,12.73,100,1,14.00,100,1,12.71,100,1,14.03,2,1,12.50,700,1,14.28,100,1,12.46,100,1,14.45,100,1,12.43,700,1,14.56,800,2,12.42,700,1,14.60,700,1,ARL,326892885
1855,2025-07-17T16:04:06.528329048Z,2025-07-17T16:04:06.528161631Z,10,2,1108,A,A,0,14.520000000,100,128,167417,273358642,13.12,200,2,13.72,15,1,13.11,100,1,13.73,100,1,13.00,2,1,13.80,15,1,12.86,100,1,13.87,200,2,12.73,100,1,14.00,100,1,12.71,100,1,14.03,2,1,12.50,700,1,14.28,100,1,12.46,100,1,14.45,100,1,12.43,700,1,14.52,100,1,12.42,700,1,14.56,800,2,ARL,327869529
1856,2025-07-17T16:04:06.543480312Z,2025-07-17T16:04:06.543314706Z,10,2,1108,C,A,0,17.620000000,100,0,165606,273359491,13.12,200,2,13.72,15,1,13.11,100,1,13.73,100,1,13.00,2,1,13.80,15,1,12.86,100,1,13.87,200,2,12.73,100,1,14.00,100,1,12.71,100,1,14.03,2,1,12.50,700,1,14.28,100,1,12.46,100,1,14.45,100,1,12.43,700,1,14.52,100,1,12.42,700,1,14.56,800,2,ARL,326892921
1857,2025-07-17T16:04:06.543480312Z,2025-07-17T16:04:06.543314706Z,10,2,1108,A,A,0,17.440000000,100,130,165606,273359491,13.12,200,2,13.72,15,1,13.11,100,1,13.73,100,1,13.00,2,1,13.80,15,1,12.86,100,1,13.87,200,2,12.73,100,1,14.00,100,1,12.71,100,1,14.03,2,1,12.50,700,1,14.28,100,1,12.46,100,1,14.45,100,1,12.43,700,1,14.52,100,1,12.42,700,1,14.56,800,2,ARL,327870217
1858,2025-07-17T16:04:06.548945239Z,2025-07-17T16:04:06.548778200Z,10,2,1108,C,A,0,15.960000000,100,0,167039,273359672,13.12,200,2,13.72,15,1,13.11,100,1,13.73,100,1,13.00,2,1,13.80,15,1,12.86,100,1,13.87,200,2,12.73,100,1,14.00,100,1,12.71,100,1,14.03,2,1,12.50,700,1,14.28,100,1,12.46,100,1,14.45,100,1,12.43,700,1,14.52,100,1,12.42,700,1,14.56,800,2,ARL,326892889
1859,2025-07-17T16:04:06.548945239Z,2025-07-17T16:04:06.548778200Z,10,2,1108,A,A,0,15.790000000,100,130,167039,273359672,13.12,200,2,13.72,15,1,13.11,100,1,13.73,100,1,13.00,2,1,13.80,15,1,12.86,100,1,13.87,200,2,12.73,100,1,14.00,100,1,12.71,100,1,14.03,2,1,12.50,700,1,14.28,100,1,12.46,100,1,14.45,100,1,12.43,700,1,14.52,100,1,12.42,700,1,14.56,800,2,ARL,327870361
1860,2025-07-17T16:04:06.648109829Z,2025-07-17T16:04:06.647944313Z,10,2,1108,C,A,0,14.850000000,100,0,165516,273361957,13.12,200,2,13.72,15,1,13.11,100,1,13.73,100,1,13.00,2,1,13.80,15,1,12.86,100,1,13.87,200,2,12.73,100,1,14.00,100,1,12.71,100,1,14.03,2,1,12.50,700,1,14.28,100,1,12.46,100,1,14.45,100,1,12.43,700,1,14.52,100,1,12.42,700,1,14.56,800,2,ARL,326893961
1861,2025-07-17T16:04:06.648109829Z,2025-07-17T16:04:06.647944313Z,10,2,1108,A,A,0,14.700000000,100,130,165516,273361957,13.12,200,2,13.72,15,1,13.11,100,1,13.73,100,1,13.00,2,1,13.80,15,1,12.86,100,1,13.87,200,2,12.73,100,1,14.00,100,1,12.71,100,1,14.03,2,1,12.50,700,1,14.28,100,1,12.46,100,1,14.45,100,1,12.43,700,1,14.52,100,1,12.42,700,1,14.56,800,2,ARL,327873009
1862,2025-07-17T16:04:06.805500523Z,2025-07-17T16:04:06.805335354Z,10,2,1108,C,A,0,13.720000000,15,130,165169,273364089,13.12,200,2,13.73,100,1,13.11,100,1,13.80,15,1,13.00,2,1,13.87,200,2,12.86,100,1,14.00,100,1,12.73,100,1,14.03,2,1,12.71,100,1,14.28,100,1,12.50,700,1,14.45,100,1,12.46,100,1,14.52,100,1,12.43,700,1,14.56,800,2,12.42,700,1,14.60,700,1,ARL,327863853
1863,2025-07-17T16:04:06.806217584Z,2025-07-17T16:04:06.806052396Z,10,2,1108,C,A,0,13.800000000,15,130,165188,273364090,13.12,200,2,13.73,100,1,13.11,100,1,13.87,200,2,13.00,2,1,14.00,100,1,12.86,100,1,14.03,2,1,12.73,100,1,14.28,100,1,12.71,100,1,14.45,100,1,12.50,700,1,14.52,100,1,12.46,100,1,14.56,800,2,12.43,700,1,14.60,700,1,12.42,700,1,14.64,200,2,ARL,327675057
1864,2025-07-17T16:04:21.277142662Z,2025-07-17T16:04:21.276976977Z,10,2,1108,A,A,0,13.770000000,100,130,165685,273687857,13.12,200,2,13.73,100,1,13.11,100,1,13.77,100,1,13.00,2,1,13.87,200,2,12.86,100,1,14.00,100,1,12.73,100,1,14.03,2,1,12.71,100,1,14.28,100,1,12.50,700,1,14.45,100,1,12.46,100,1,14.52,100,1,12.43,700,1,14.56,800,2,12.42,700,1,14.60,700,1,ARL,328239293
1865,2025-07-17T16:04:27.791055146Z,2025-07-17T16:04:27.790889618Z,10,2,1108,C,A,0,14.030000000,2,0,165528,273775264,13.12,200,2,13.73,100,1,13.11,100,1,13.77,100,1,13.00,2,1,13.87,200,2,12.86,100,1,14.00,100,1,12.73,100,1,14.28,100,1,12.71,100,1,14.45,100,1,12.50,700,1,14.52,100,1,12.46,100,1,14.56,800,2,12.43,700,1,14.60,700,1,12.42,700,1,14.64,200,2,ARL,326159041
1866,2025-07-17T16:04:27.791055146Z,2025-07-17T16:04:27.790889618Z,10,2,1108,A,A,0,13.940000000,2,130,165528,273775264,13.12,200,2,13.73,100,1,13.11,100,1,13.77,100,1,13.00,2,1,13.87,200,2,12.86,100,1,13.94,2,1,12.73,100,1,14.00,100,1,12.71,100,1,14.28,100,1,12.50,700,1,14.45,100,1,12.46,100,1,14.52,100,1,12.43,700,1,14.56,800,2,12.42,700,1,14.60,700,1,ARL,328351217
1867,2025-07-17T16:04:31.232053154Z,2025-07-17T16:04:31.231887784Z,10,2,1108,A,A,0,13.680000000,15,130,165370,273846737,13.12,200,2,13.68,15,1,13.11,100,1,13.73,100,1,13.00,2,1,13.77,100,1,12.86,100,1,13.87,200,2,12.73,100,1,13.94,2,1,12.71,100,1,14.00,100,1,12.50,700,1,14.28,100,1,12.46,100,1,14.45,100,1,12.43,700,1,14.52,100,1,12.42,700,1,14.56,800,2,ARL,328437797
1868,2025-07-17T16:04:31.232606440Z,2025-07-17T16:04:31.232440773Z,10,2,1108,A,A,0,13.720000000,100,130,165667,273846745,13.12,200,2,13.68,15,1,13.11,100,1,13.72,100,1,13.00,2,1,13.73,100,1,12.86,100,1,13.77,100,1,12.73,100,1,13.87,200,2,12.71,100,1,13.94,2,1,12.50,700,1,14.00,100,1,12.46,100,1,14.28,100,1,12.43,700,1,14.45,100,1,12.42,700,1,14.52,100,1,ARL,328437805
1869,2025-07-17T16:04:31.246681162Z,2025-07-17T16:04:31.246515467Z,10,2,1108,C,A,0,13.770000000,100,130,165695,273847000,13.12,200,2,13.68,15,1,13.11,100,1,13.72,100,1,13.00,2,1,13.73,100,1,12.86,100,1,13.87,200,2,12.73,100,1,13.94,2,1,12.71,100,1,14.00,100,1,12.50,700,1,14.28,100,1,12.46,100,1,14.45,100,1,12.43,700,1,14.52,100,1,12.42,700,1,14.56,800,2,ARL,328239293
1870,2025-07-17T16:04:32.836802111Z,2025-07-17T16:04:32.836635838Z,10,2,1108,C,A,0,13.730000000,100,0,166273,273882084,13.12,200,2,13.68,15,1,13.11,100,1,13.72,100,1,13.00,2,1,13.87,200,2,12.86,100,1,13.94,2,1,12.73,100,1,14.00,100,1,12.71,100,1,14.28,100,1,12.50,700,1,14.45,100,1,12.46,100,1,14.52,100,1,12.43,700,1,14.56,800,2,12.42,700,1,14.60,700,1,ARL,327864137
1871,2025-07-17T16:04:32.836802111Z,2025-07-17T16:04:32.836635838Z,10,2,1108,A,A,0,13.690000000,100,130,166273,273882084,13.12,200,2,13.68,15,1,13.11,100,1,13.69,100,1,13.00,2,1,13.72,100,1,12.86,100,1,13.87,200,2,12.73,100,1,13.94,2,1,12.71,100,1,14.00,100,1,12.50,700,1,14.28,100,1,12.46,100,1,14.45,100,1,12.43,700,1,14.52,100,1,12.42,700,1,14.56,800,2,ARL,328489153
1872,2025-07-17T16:04:32.837165431Z,2025-07-17T16:04:32.837000154Z,10,2,1108,C,B,0,13.120000000,100,130,165277,273882201,13.12,100,1,13.68,15,1,13.11,100,1,13.69,100,1,13.00,2,1,13.72,100,1,12.86,100,1,13.87,200,2,12.73,100,1,13.94,2,1,12.71,100,1,14.00,100,1,12.50,700,1,14.28,100,1,12.46,100,1,14.45,100,1,12.43,700,1,14.52,100,1,12.42,700,1,14.56,800,2,ARL,325718833
1873,2025-07-17T16:04:32.837169083Z,2025-07-17T16:04:32.837002825Z,10,2,1108,C,B,0,13.120000000,100,128,166258,273882202,13.11,100,1,13.68,15,1,13.00,2,1,13.69,100,1,12.86,100,1,13.72,100,1,12.73,100,1,13.87,200,2,12.71,100,1,13.94,2,1,12.50,700,1,14.00,100,1,12.46,100,1,14.28,100,1,12.43,700,1,14.45,100,1,12.42,700,1,14.52,100,1,12.37,700,1,14.56,800,2,ARL,325718837
1874,2025-07-17T16:04:32.837179568Z,2025-07-17T16:04:32.837013456Z,10,2,1108,A,B,0,12.980000000,100,130,166112,273882207,13.11,100,1,13.68,15,1,13.00,2,1,13.69,100,1,12.98,100,1,13.72,100,1,12.86,100,1,13.87,200,2,12.73,100,1,13.94,2,1,12.71,100,1,14.00,100,1,12.50,700,1,14.28,100,1,12.46,100,1,14.45,100,1,12.43,700,1,14.52,100,1,12.42,700,1,14.56,800,2,ARL,328489377
1875,2025-07-17T16:04:32.837181582Z,2025-07-17T16:04:32.837016087Z,10,2,1108,A,B,0,12.980000000,100,130,165495,273882208,13.11,100,1,13.68,15,1,13.00,2,1,13.69,100,1,12.98,200,2,13.72,100,1,12.86,100,1,13.87,200,2,12.73,100,1,13.94,2,1,12.71,100,1,14.00,100,1,12.50,700,1,14.28,100,1,12.46,100,1,14.45,100,1,12.43,700,1,14.52,100,1,12.42,700,1,14.56,800,2,ARL,328489385
1876,2025-07-17T16:04:32.837536434Z,2025-07-17T16:04:32.837369811Z,10,2,1108,C,A,0,14.790000000,100,0,166623,273882286,13.11,100,1,13.68,15,1,13.00,2,1,13.69,100,1,12.98,200,2,13.72,100,1,12.86,100,1,13.87,200,2,12.73,100,1,13.94,2,1,12.71,100,1,14.00,100,1,12.50,700,1,14.28,100,1,12.46,100,1,14.45,100,1,12.43,700,1,14.52,100,1,12.42,700,1,14.56,800,2,ARL,327864893
1877,2025-07-17T16:04:32.837536434Z,2025-07-17T16:04:32.837369811Z,10,2,1108,A,A,0,14.750000000,100,128,166623,273882286,13.11,100,1,13.68,15,1,13.00,2,1,13.69,100,1,12.98,200,2,13.72,100,1,12.86,100,1,13.87,200,2,12.73,100,1,13.94,2,1,12.71,100,1,14.00,100,1,12.50,700,1,14.28,100,1,12.46,100,1,14.45,100,1,12.43,700,1,14.52,100,1,12.42,700,1,14.56,800,2,ARL,328489481
1878,2025-07-17T16:04:36.810717146Z,2025-07-17T16:04:36.810551890Z,10,2,1108,A,A,0,13.650000000,15,130,165256,273963456,13.11,100,1,13.65,15,1,13.00,2,1,13.68,15,1,12.98,200,2,13.69,100,1,12.86,100,1,13.72,100,1,12.73,100,1,13.87,200,2,12.71,100,1,13.94,2,1,12.50,700,1,14.00,100,1,12.46,100,1,14.28,100,1,12.43,700,1,14.45,100,1,12.42,700,1,14.52,100,1,ARL,328603377
1879,2025-07-17T16:04:37.026937493Z,2025-07-17T16:04:37.026771973Z,10,2,1108,A,A,0,13.690000000,100,130,165520,273965417,13.11,100,1,13.65,15,1,13.00,2,1,13.68,15,1,12.98,200,2,13.69,200,2,12.86,100,1,13.72,100,1,12.73,100,1,13.87,200,2,12.71,100,1,13.94,2,1,12.50,700,1,14.00,100,1,12.46,100,1,14.28,100,1,12.43,700,1,14.45,100,1,12.42,700,1,14.52,100,1,ARL,328606289
1880,2025-07-17T16:04:37.033554557Z,2025-07-17T16:04:37.033389265Z,10,2,1108,C,A,0,13.720000000,100,130,165292,273965562,13.11,100,1,13.65,15,1,13.00,2,1,13.68,15,1,12.98,200,2,13.69,200,2,12.86,100,1,13.87,200,2,12.73,100,1,13.94,2,1,12.71,100,1,14.00,100,1,12.50,700,1,14.28,100,1,12.46,100,1,14.45,100,1,12.43,700,1,14.52,100,1,12.42,700,1,14.56,800,2,ARL,328437805
1881,2025-07-17T16:04:37.542961161Z,2025-07-17T16:04:37.542795711Z,10,2,1108,C,A,0,13.690000000,100,0,165450,273971021,13.11,100,1,13.65,15,1,13.00,2,1,13.68,15,1,12.98,200,2,13.69,100,1,12.86,100,1,13.87,200,2,12.73,100,1,13.94,2,1,12.71,100,1,14.00,100,1,12.50,700,1,14.28,100,1,12.46,100,1,14.45,100,1,12.43,700,1,14.52,100,1,12.42,700,1,14.56,800,2,ARL,328489153
1882,2025-07-17T16:04:37.542961161Z,2025-07-17T16:04:37.542795711Z,10,2,1108,A,A,0,13.660000000,100,130,165450,273971021,13.11,100,1,13.65,15,1,13.00,2,1,13.66,100,1,12.98,200,2,13.68,15,1,12.86,100,1,13.69,100,1,12.73,100,1,13.87,200,2,12.71,100,1,13.94,2,1,12.50,700,1,14.00,100,1,12.46,100,1,14.28,100,1,12.43,700,1,14.45,100,1,12.42,700,1,14.52,100,1,ARL,328614509
1883,2025-07-17T16:04:37.543230680Z,2025-07-17T16:04:37.543063240Z,10,2,1108,C,A,0,13.870000000,100,0,167440,273971035,13.11,100,1,13.65,15,1,13.00,2,1,13.66,100,1,12.98,200,2,13.68,15,1,12.86,100,1,13.69,100,1,12.73,100,1,13.87,100,1,12.71,100,1,13.94,2,1,12.50,700,1,14.00,100,1,12.46,100,1,14.28,100,1,12.43,700,1,14.45,100,1,12.42,700,1,14.52,100,1,ARL,326730517
1884,2025-07-17T16:04:37.543230680Z,2025-07-17T16:04:37.543064690Z,10,2,1108,C,A,0,13.870000000,100,130,165990,273971037,13.11,100,1,13.65,15,1,13.00,2,1,13.66,100,1,12.98,200,2,13.68,15,1,12.86,100,1,13.69,100,1,12.73,100,1,13.94,2,1,12.71,100,1,14.00,100,1,12.50,700,1,14.28,100,1,12.46,100,1,14.45,100,1,12.43,700,1,14.52,100,1,12.42,700,1,14.56,800,2,ARL,326730521
1885,2025-07-17T16:04:37.543242390Z,2025-07-17T16:04:37.543077174Z,10,2,1108,A,A,0,13.800000000,100,130,165216,273971040,13.11,100,1,13.65,15,1,13.00,2,1,13.66,100,1,12.98,200,2,13.68,15,1,12.86,100,1,13.69,100,1,12.73,100,1,13.80,100,1,12.71,100,1,13.94,2,1,12.50,700,1,14.00,100,1,12.46,100,1,14.28,100,1,12.43,700,1,14.45,100,1,12.42,700,1,14.52,100,1,ARL,328614525
1886,2025-07-17T16:04:37.543244193Z,2025-07-17T16:04:37.543078532Z,10,2,1108,A,A,0,13.800000000,100,130,165661,273971041,13.11,100,1,13.65,15,1,13.00,2,1,13.66,100,1,12.98,200,2,13.68,15,1,12.86,100,1,13.69,100,1,12.73,100,1,13.80,200,2,12.71,100,1,13.94,2,1,12.50,700,1,14.00,100,1,12.46,100,1,14.28,100,1,12.43,700,1,14.45,100,1,12.42,700,1,14.52,100,1,ARL,328614529
1887,2025-07-17T16:04:37.549684713Z,2025-07-17T16:04:37.549519006Z,10,2,1108,C,A,0,14.000000000,100,130,165707,273973481,13.11,100,1,13.65,15,1,13.00,2,1,13.66,100,1,12.98,200,2,13.68,15,1,12.86,100,1,13.69,100,1,12.73,100,1,13.80,200,2,12.71,100,1,13.94,2,1,12.50,700,1,14.28,100,1,12.46,100,1,14.45,100,1,12.43,700,1,14.52,100,1,12.42,700,1,14.56,800,2,ARL,327869193
1888,2025-07-17T16:04:37.549735824Z,2025-07-17T16:04:37.549570649Z,10,2,1108,A,A,0,13.930000000,100,130,165175,273973485,13.11,100,1,13.65,15,1,13.00,2,1,13.66,100,1,12.98,200,2,13.68,15,1,12.86,100,1,13.69,100,1,12.73,100,1,13.80,200,2,12.71,100,1,13.93,100,1,12.50,700,1,13.94,2,1,12.46,100,1,14.28,100,1,12.43,700,1,14.45,100,1,12.42,700,1,14.52,100,1,ARL,328616925
1889,2025-07-17T16:04:44.524526545Z,2025-07-17T16:04:44.524360626Z,10,2,1108,C,A,0,13.680000000,15,130,165919,274066152,13.11,100,1,13.65,15,1,13.00,2,1,13.66,100,1,12.98,200,2,13.69,100,1,12.86,100,1,13.80,200,2,12.73,100,1,13.93,100,1,12.71,100,1,13.94,2,1,12.50,700,1,14.28,100,1,12.46,100,1,14.45,100,1,12.43,700,1,14.52,100,1,12.42,700,1,14.56,800,2,ARL,328437797
1890,2025-07-17T16:04:45.528000143Z,2025-07-17T16:04:45.527835033Z,10,2,1108,A,A,0,13.630000000,15,130,165110,274088918,13.11,100,1,13.63,15,1,13.00,2,1,13.65,15,1,12.98,200,2,13.66,100,1,12.86,100,1,13.69,100,1,12.73,100,1,13.80,200,2,12.71,100,1,13.93,100,1,12.50,700,1,13.94,2,1,12.46,100,1,14.28,100,1,12.43,700,1,14.45,100,1,12.42,700,1,14.52,100,1,ARL,328780565
1891,2025-07-17T16:04:45.528629613Z,2025-07-17T16:04:45.528464092Z,10,2,1108,C,A,0,14.640000000,100,0,165521,274088922,13.11,100,1,13.63,15,1,13.00,2,1,13.65,15,1,12.98,200,2,13.66,100,1,12.86,100,1,13.69,100,1,12.73,100,1,13.80,200,2,12.71,100,1,13.93,100,1,12.50,700,1,13.94,2,1,12.46,100,1,14.28,100,1,12.43,700,1,14.45,100,1,12.42,700,1,14.52,100,1,ARL,327856309
1892,2025-07-17T16:04:45.528629613Z,2025-07-17T16:04:45.528464092Z,10,2,1108,A,A,0,14.520000000,100,130,165521,274088922,13.11,100,1,13.63,15,1,13.00,2,1,13.65,15,1,12.98,200,2,13.66,100,1,12.86,100,1,13.69,100,1,12.73,100,1,13.80,200,2,12.71,100,1,13.93,100,1,12.50,700,1,13.94,2,1,12.46,100,1,14.28,100,1,12.43,700,1,14.45,100,1,12.42,700,1,14.52,200,2,ARL,328780577
1893,2025-07-17T16:04:45.530418278Z,2025-07-17T16:04:45.530252804Z,10,2,1108,C,A,0,14.640000000,100,0,165474,274088937,13.11,100,1,13.63,15,1,13.00,2,1,13.65,15,1,12.98,200,2,13.66,100,1,12.86,100,1,13.69,100,1,12.73,100,1,13.80,200,2,12.71,100,1,13.93,100,1,12.50,700,1,13.94,2,1,12.46,100,1,14.28,100,1,12.43,700,1,14.45,100,1,12.42,700,1,14.52,200,2,ARL,327856297
1894,2025-07-17T16:04:45.530418278Z,2025-07-17T16:04:45.530252804Z,10,2,1108,A,A,0,14.520000000,100,130,165474,274088937,13.11,100,1,13.63,15,1,13.00,2,1,13.65,15,1,12.98,200,2,13.66,100,1,12.86,100,1,13.69,100,1,12.73,100,1,13.80,200,2,12.71,100,1,13.93,100,1,12.50,700,1,13.94,2,1,12.46,100,1,14.28,100,1,12.43,700,1,14.45,100,1,12.42,700,1,14.52,300,3,ARL,328780597
1895,2025-07-17T16:04:45.533067029Z,2025-07-17T16:04:45.532901874Z,10,2,1108,C,A,0,13.660000000,100,0,165155,274088955,13.11,100,1,13.63,15,1,13.00,2,1,13.65,15,1,12.98,200,2,13.69,100,1,12.86,100,1,13.80,200,2,12.73,100,1,13.93,100,1,12.71,100,1,13.94,2,1,12.50,700,1,14.28,100,1,12.46,100,1,14.45,100,1,12.43,700,1,14.52,300,3,12.42,700,1,14.56,800,2,ARL,328614509
1896,2025-07-17T16:04:45.533067029Z,2025-07-17T16:04:45.532901874Z,10,2,1108,A,A,0,13.640000000,100,130,165155,274088955,13.11,100,1,13.63,15,1,13.00,2,1,13.64,100,1,12.98,200,2,13.65,15,1,12.86,100,1,13.69,100,1,12.73,100,1,13.80,200,2,12.71,100,1,13.93,100,1,12.50,700,1,13.94,2,1,12.46,100,1,14.28,100,1,12.43,700,1,14.45,100,1,12.42,700,1,14.52,300,3,ARL,328780669
1897,2025-07-17T16:04:45.533804768Z,2025-07-17T16:04:45.533639142Z,10,2,1108,C,A,0,14.750000000,100,0,165626,274088957,13.11,100,1,13.63,15,1,13.00,2,1,13.64,100,1,12.98,200,2,13.65,15,1,12.86,100,1,13.69,100,1,12.73,100,1,13.80,200,2,12.71,100,1,13.93,100,1,12.50,700,1,13.94,2,1,12.46,100,1,14.28,100,1,12.43,700,1,14.45,100,1,12.42,700,1,14.52,300,3,ARL,328489481
1898,2025-07-17T16:04:45.533804768Z,2025-07-17T16:04:45.533639142Z,10,2,1108,A,A,0,14.700000000,100,130,165626,274088957,13.11,100,1,13.63,15,1,13.00,2,1,13.64,100,1,12.98,200,2,13.65,15,1,12.86,100,1,13.69,100,1,12.73,100,1,13.80,200,2,12.71,100,1,13.93,100,1,12.50,700,1,13.94,2,1,12.46,100,1,14.28,100,1,12.43,700,1,14.45,100,1,12.42,700,1,14.52,300,3,ARL,328780685
1899,2025-07-17T16:04:45.533870711Z,2025-07-17T16:04:45.533705428Z,10,2,1108,A,A,0,13.670000000,100,130,165283,274088959,13.11,100,1,13.63,15,1,13.00,2,1,13.64,100,1,12.98,200,2,13.65,15,1,12.86,100,1,13.67,100,1,12.73,100,1,13.69,100,1,12.71,100,1,13.80,200,2,12.50,700,1,13.93,100,1,12.46,100,1,13.94,2,1,12.43,700,1,14.28,100,1,12.42,700,1,14.45,100,1,ARL,328780689
1900,2025-07-17T16:04:45.563137443Z,2025-07-17T16:04:45.562972204Z,10,2,1108,C,A,0,13.690000000,100,130,165239,274089319,13.11,100,1,13.63,15,1,13.00,2,1,13.64,100,1,12.98,200,2,13.65,15,1,12.86,100,1,13.67,100,1,12.73,100,1,13.80,200,2,12.71,100,1,13.93,100,1,12.50,700,1,13.94,2,1,12.46,100,1,14.28,100,1,12.43,700,1,14.45,100,1,12.42,700,1,14.52,300,3,ARL,328606289
1901,2025-07-17T16:04:56.809749973Z,2025-07-17T16:04:56.809584701Z,10,2,1108,C,A,0,13.650000000,15,130,165272,274293432,13.11,100,1,13.63,15,1,13.00,2,1,13.64,100,1,12.98,200,2,13.67,100,1,12.86,100,1,13.80,200,2,12.73,100,1,13.93,100,1,12.71,100,1,13.94,2,1,12.50,700,1,14.28,100,1,12.46,100,1,14.45,100,1,12.43,700,1,14.52,300,3,12.42,700,1,14.56,800,2,ARL,328603377
1902,2025-07-17T16:04:57.827079009Z,2025-07-17T16:04:57.826913717Z,10,2,1108,A,A,0,13.610000000,15,130,165292,274310244,13.11,100,1,13.61,15,1,13.00,2,1,13.63,15,1,12.98,200,2,13.64,100,1,12.86,100,1,13.67,100,1,12.73,100,1,13.80,200,2,12.71,100,1,13.93,100,1,12.50,700,1,13.94,2,1,12.46,100,1,14.28,100,1,12.43,700,1,14.45,100,1,12.42,700,1,14.52,300,3,ARL,329068341
1903,2025-07-17T16:04:57.970616610Z,2025-07-17T16:04:57.970451236Z,10,2,1108,C,A,0,13.640000000,100,0,165374,274316281,13.11,100,1,13.61,15,1,13.00,2,1,13.63,15,1,12.98,200,2,13.67,100,1,12.86,100,1,13.80,200,2,12.73,100,1,13.93,100,1,12.71,100,1,13.94,2,1,12.50,700,1,14.28,100,1,12.46,100,1,14.45,100,1,12.43,700,1,14.52,300,3,12.42,700,1,14.56,800,2,ARL,328780669
1904,2025-07-17T16:04:57.970616610Z,2025-07-17T16:04:57.970451236Z,10,2,1108,A,A,0,13.620000000,100,130,165374,274316281,13.11,100,1,13.61,15,1,13.00,2,1,13.62,100,1,12.98,200,2,13.63,15,1,12.86,100,1,13.67,100,1,12.73,100,1,13.80,200,2,12.71,100,1,13.93,100,1,12.50,700,1,13.94,2,1,12.46,100,1,14.28,100,1,12.43,700,1,14.45,100,1,12.42,700,1,14.52,300,3,ARL,329074609
1905,2025-07-17T16:04:57.971360344Z,2025-07-17T16:04:57.971193734Z,10,2,1108,C,A,0,14.450000000,100,128,166610,274316507,13.11,100,1,13.61,15,1,13.00,2,1,13.62,100,1,12.98,200,2,13.63,15,1,12.86,100,1,13.67,100,1,12.73,100,1,13.80,200,2,12.71,100,1,13.93,100,1,12.50,700,1,13.94,2,1,12.46,100,1,14.28,100,1,12.43,700,1,14.52,300,3,12.42,700,1,14.56,800,2,ARL,325714601
1906,2025-07-17T16:04:57.971717511Z,2025-07-17T16:04:57.971552262Z,10,2,1108,A,A,0,14.230000000,100,130,165249,274316527,13.11,100,1,13.61,15,1,13.00,2,1,13.62,100,1,12.98,200,2,13.63,15,1,12.86,100,1,13.67,100,1,12.73,100,1,13.80,200,2,12.71,100,1,13.93,100,1,12.50,700,1,13.94,2,1,12.46,100,1,14.23,100,1,12.43,700,1,14.28,100,1,12.42,700,1,14.52,300,3,ARL,329074833
1907,2025-07-17T16:04:57.992131878Z,2025-07-17T16:04:57.991966904Z,10,2,1108,C,A,0,13.610000000,15,130,164974,274318490,13.11,100,1,13.62,100,1,13.00,2,1,13.63,15,1,12.98,200,2,13.67,100,1,12.86,100,1,13.80,200,2,12.73,100,1,13.93,100,1,12.71,100,1,13.94,2,1,12.50,700,1,14.23,100,1,12.46,100,1,14.28,100,1,12.43,700,1,14.52,300,3,12.42,700,1,14.56,800,2,ARL,329068341
1908,2025-07-17T16:04:57.993141438Z,2025-07-17T16:04:57.992976406Z,10,2,1108,C,A,0,13.620000000,100,130,165032,274318579,13.11,100,1,13.63,15,1,13.00,2,1,13.67,100,1,12.98,200,2,13.80,200,2,12.86,100,1,13.93,100,1,12.73,100,1,13.94,2,1,12.71,100,1,14.23,100,1,12.50,700,1,14.28,100,1,12.46,100,1,14.52,300,3,12.43,700,1,14.56,800,2,12.42,700,1,14.60,700,1,ARL,329074609
1909,2025-07-17T16:04:57.993309561Z,2025-07-17T16:04:57.993143873Z,10,2,1108,C,A,0,13.630000000,15,130,165688,274318603,13.11,100,1,13.67,100,1,13.00,2,1,13.80,200,2,12.98,200,2,13.93,100,1,12.86,100,1,13.94,2,1,12.73,100,1,14.23,100,1,12.71,100,1,14.28,100,1,12.50,700,1,14.52,300,3,12.46,100,1,14.56,800,2,12.43,700,1,14.60,700,1,12.42,700,1,14.68,1400,2,ARL,328780565
1910,2025-07-17T16:04:58.002259715Z,2025-07-17T16:04:58.002094377Z,10,2,1108,C,A,0,13.670000000,100,130,165338,274319058,13.11,100,1,13.80,200,2,13.00,2,1,13.93,100,1,12.98,200,2,13.94,2,1,12.86,100,1,14.23,100,1,12.73,100,1,14.28,100,1,12.71,100,1,14.52,300,3,12.50,700,1,14.56,800,2,12.46,100,1,14.60,700,1,12.43,700,1,14.68,1400,2,12.42,700,1,14.70,300,3,ARL,328780689
1911,2025-07-17T16:04:58.002989430Z,2025-07-17T16:04:58.002823841Z,10,2,1108,C,A,0,14.700000000,100,0,165589,274319069,13.11,100,1,13.80,200,2,13.00,2,1,13.93,100,1,12.98,200,2,13.94,2,1,12.86,100,1,14.23,100,1,12.73,100,1,14.28,100,1,12.71,100,1,14.52,300,3,12.50,700,1,14.56,800,2,12.46,100,1,14.60,700,1,12.43,700,1,14.68,1400,2,12.42,700,1,14.70,200,2,ARL,328780685
1912,2025-07-17T16:04:58.002989430Z,2025-07-17T16:04:58.002823841Z,10,2,1108,A,A,0,14.870000000,100,130,165589,274319069,13.11,100,1,13.80,200,2,13.00,2,1,13.93,100,1,12.98,200,2,13.94,2,1,12.86,100,1,14.23,100,1,12.73,100,1,14.28,100,1,12.71,100,1,14.52,300,3,12.50,700,1,14.56,800,2,12.46,100,1,14.60,700,1,12.43,700,1,14.68,1400,2,12.42,700,1,14.70,200,2,ARL,329078553
1913,2025-07-17T16:04:58.013904697Z,2025-07-17T16:04:58.013739242Z,10,2,1108,C,A,0,13.930000000,100,130,165455,274319298,13.11,100,1,13.80,200,2,13.00,2,1,13.94,2,1,12.98,200,2,14.23,100,1,12.86,100,1,14.28,100,1,12.73,100,1,14.52,300,3,12.71,100,1,14.56,800,2,12.50,700,1,14.60,700,1,12.46,100,1,14.68,1400,2,12.43,700,1,14.70,200,2,12.42,700,1,14.87,100,1,ARL,328616925
1914,2025-07-17T16:04:58.013959233Z,2025-07-17T16:04:58.013793974Z,10,2,1108,A,A,0,14.080000000,100,130,165259,274319304,13.11,100,1,13.80,200,2,13.00,2,1,13.94,2,1,12.98,200,2,14.08,100,1,12.86,100,1,14.23,100,1,12.73,100,1,14.28,100,1,12.71,100,1,14.52,300,3,12.50,700,1,14.56,800,2,12.46,100,1,14.60,700,1,12.43,700,1,14.68,1400,2,12.42,700,1,14.70,200,2,ARL,329078953
1915,2025-07-17T16:04:58.536617917Z,2025-07-17T16:04:58.536452621Z,10,2,1108,A,A,0,13.810000000,100,130,165296,274326535,13.11,100,1,13.80,200,2,13.00,2,1,13.81,100,1,12.98,200,2,13.94,2,1,12.86,100,1,14.08,100,1,12.73,100,1,14.23,100,1,12.71,100,1,14.28,100,1,12.50,700,1,14.52,300,3,12.46,100,1,14.56,800,2,12.43,700,1,14.60,700,1,12.42,700,1,14.68,1400,2,ARL,329088265
1916,2025-07-17T16:05:46.594131664Z,2025-07-17T16:05:46.593966383Z,10,2,1108,A,A,0,13.760000000,100,130,165281,275083968,13.11,100,1,13.76,100,1,13.00,2,1,13.80,200,2,12.98,200,2,13.81,100,1,12.86,100,1,13.94,2,1,12.73,100,1,14.08,100,1,12.71,100,1,14.23,100,1,12.50,700,1,14.28,100,1,12.46,100,1,14.52,300,3,12.43,700,1,14.56,800,2,12.42,700,1,14.60,700,1,ARL,330066537
1917,2025-07-17T16:05:46.594871336Z,2025-07-17T16:05:46.594705962Z,10,2,1108,C,A,0,14.870000000,100,0,165374,275083970,13.11,100,1,13.76,100,1,13.00,2,1,13.80,200,2,12.98,200,2,13.81,100,1,12.86,100,1,13.94,2,1,12.73,100,1,14.08,100,1,12.71,100,1,14.23,100,1,12.50,700,1,14.28,100,1,12.46,100,1,14.52,300,3,12.43,700,1,14.56,800,2,12.42,700,1,14.60,700,1,ARL,329078553
1918,2025-07-17T16:05:46.594871336Z,2025-07-17T16:05:46.594705962Z,10,2,1108,A,A,0,14.830000000,100,130,165374,275083970,13.11,100,1,13.76,100,1,13.00,2,1,13.80,200,2,12.98,200,2,13.81,100,1,12.86,100,1,13.94,2,1,12.73,100,1,14.08,100,1,12.71,100,1,14.23,100,1,12.50,700,1,14.28,100,1,12.46,100,1,14.52,300,3,12.43,700,1,14.56,800,2,12.42,700,1,14.60,700,1,ARL,330066553
1919,2025-07-17T16:05:46.996003552Z,2025-07-17T16:05:46.995837526Z,10,2,1108,C,A,0,13.810000000,100,0,166026,275092978,13.11,100,1,13.76,100,1,13.00,2,1,13.80,200,2,12.98,200,2,13.94,2,1,12.86,100,1,14.08,100,1,12.73,100,1,14.23,100,1,12.71,100,1,14.28,100,1,12.50,700,1,14.52,300,3,12.46,100,1,14.56,800,2,12.43,700,1,14.60,700,1,12.42,700,1,14.68,1400,2,ARL,329088265
1920,2025-07-17T16:05:46.996003552Z,2025-07-17T16:05:46.995837526Z,10,2,1108,A,A,0,13.770000000,100,130,166026,275092978,13.11,100,1,13.76,100,1,13.00,2,1,13.77,100,1,12.98,200,2,13.80,200,2,12.86,100,1,13.94,2,1,12.73,100,1,14.08,100,1,12.71,100,1,14.23,100,1,12.50,700,1,14.28,100,1,12.46,100,1,14.52,300,3,12.43,700,1,14.56,800,2,12.42,700,1,14.60,700,1,ARL,330075425
1921,2025-07-17T16:05:50.680333151Z,2025-07-17T16:05:50.680167632Z,10,2,1108,A,A,0,13.680000000,15,130,165519,275152014,13.11,100,1,13.68,15,1,13.00,2,1,13.76,100,1,12.98,200,2,13.77,100,1,12.86,100,1,13.80,200,2,12.73,100,1,13.94,2,1,12.71,100,1,14.08,100,1,12.50,700,1,14.23,100,1,12.46,100,1,14.28,100,1,12.43,700,1,14.52,300,3,12.42,700,1,14.56,800,2,ARL,330143813
1922,2025-07-17T16:05:50.697170320Z,2025-07-17T16:05:50.697005084Z,10,2,1108,A,A,0,13.720000000,100,130,165236,275152383,13.11,100,1,13.68,15,1,13.00,2,1,13.72,100,1,12.98,200,2,13.76,100,1,12.86,100,1,13.77,100,1,12.73,100,1,13.80,200,2,12.71,100,1,13.94,2,1,12.50,700,1,14.08,100,1,12.46,100,1,14.23,100,1,12.43,700,1,14.28,100,1,12.42,700,1,14.52,300,3,ARL,330144301
1923,2025-07-17T16:05:50.697905372Z,2025-07-17T16:05:50.697739933Z,10,2,1108,C,A,0,14.830000000,100,0,165439,275152385,13.11,100,1,13.68,15,1,13.00,2,1,13.72,100,1,12.98,200,2,13.76,100,1,12.86,100,1,13.77,100,1,12.73,100,1,13.80,200,2,12.71,100,1,13.94,2,1,12.50,700,1,14.08,100,1,12.46,100,1,14.23,100,1,12.43,700,1,14.28,100,1,12.42,700,1,14.52,300,3,ARL,330066553
1924,2025-07-17T16:05:50.697905372Z,2025-07-17T16:05:50.697739933Z,10,2,1108,A,A,0,14.780000000,100,130,165439,275152385,13.11,100,1,13.68,15,1,13.00,2,1,13.72,100,1,12.98,200,2,13.76,100,1,12.86,100,1,13.77,100,1,12.73,100,1,13.80,200,2,12.71,100,1,13.94,2,1,12.50,700,1,14.08,100,1,12.46,100,1,14.23,100,1,12.43,700,1,14.28,100,1,12.42,700,1,14.52,300,3,ARL,330144321
1925,2025-07-17T16:05:50.704531748Z,2025-07-17T16:05:50.704366332Z,10,2,1108,C,A,0,13.760000000,100,130,165416,275152443,13.11,100,1,13.68,15,1,13.00,2,1,13.72,100,1,12.98,200,2,13.77,100,1,12.86,100,1,13.80,200,2,12.73,100,1,13.94,2,1,12.71,100,1,14.08,100,1,12.50,700,1,14.23,100,1,12.46,100,1,14.28,100,1,12.43,700,1,14.52,300,3,12.42,700,1,14.56,800,2,ARL,330066537
1926,2025-07-17T16:05:50.708879311Z,2025-07-17T16:05:50.708714027Z,10,2,1108,C,A,0,14.080000000,100,130,165284,275152465,13.11,100,1,13.68,15,1,13.00,2,1,13.72,100,1,12.98,200,2,13.77,100,1,12.86,100,1,13.80,200,2,12.73,100,1,13.94,2,1,12.71,100,1,14.23,100,1,12.50,700,1,14.28,100,1,12.46,100,1,14.52,300,3,12.43,700,1,14.56,800,2,12.42,700,1,14.60,700,1,ARL,329078953
1927,2025-07-17T16:05:50.708931189Z,2025-07-17T16:05:50.708766050Z,10,2,1108,A,A,0,13.990000000,100,130,165139,275152466,13.11,100,1,13.68,15,1,13.00,2,1,13.72,100,1,12.98,200,2,13.77,100,1,12.86,100,1,13.80,200,2,12.73,100,1,13.94,2,1,12.71,100,1,13.99,100,1,12.50,700,1,14.23,100,1,12.46,100,1,14.28,100,1,12.43,700,1,14.52,300,3,12.42,700,1,14.56,800,2,ARL,330144513
1928,2025-07-17T16:05:50.913476268Z,2025-07-17T16:05:50.913310799Z,10,2,1108,C,A,0,13.770000000,100,0,165469,275159685,13.11,100,1,13.68,15,1,13.00,2,1,13.72,100,1,12.98,200,2,13.80,200,2,12.86,100,1,13.94,2,1,12.73,100,1,13.99,100,1,12.71,100,1,14.23,100,1,12.50,700,1,14.28,100,1,12.46,100,1,14.52,300,3,12.43,700,1,14.56,800,2,12.42,700,1,14.60,700,1,ARL,330075425
1929,2025-07-17T16:05:50.913476268Z,2025-07-17T16:05:50.913310799Z,10,2,1108,A,A,0,13.690000000,100,130,165469,275159685,13.11,100,1,13.68,15,1,13.00,2,1,13.69,100,1,12.98,200,2,13.72,100,1,12.86,100,1,13.80,200,2,12.73,100,1,13.94,2,1,12.71,100,1,13.99,100,1,12.50,700,1,14.23,100,1,12.46,100,1,14.28,100,1,12.43,700,1,14.52,300,3,12.42,700,1,14.56,800,2,ARL,330151389
1930,2025-07-17T16:05:59.704955970Z,2025-07-17T16:05:59.704790753Z,10,2,1108,A,A,0,13.640000000,15,130,165217,275325555,13.11,100,1,13.64,15,1,13.00,2,1,13.68,15,1,12.98,200,2,13.69,100,1,12.86,100,1,13.72,100,1,12.73,100,1,13.80,200,2,12.71,100,1,13.94,2,1,12.50,700,1,13.99,100,1,12.46,100,1,14.23,100,1,12.43,700,1,14.28,100,1,12.42,700,1,14.52,300,3,ARL,330357473
1931,2025-07-17T16:05:59.715090662Z,2025-07-17T16:05:59.714925412Z,10,2,1108,A,A,0,13.680000000,100,130,165250,275325807,13.11,100,1,13.64,15,1,13.00,2,1,13.68,115,2,12.98,200,2,13.69,100,1,12.86,100,1,13.72,100,1,12.73,100,1,13.80,200,2,12.71,100,1,13.94,2,1,12.50,700,1,13.99,100,1,12.46,100,1,14.23,100,1,12.43,700,1,14.28,100,1,12.42,700,1,14.52,300,3,ARL,330357633
1932,2025-07-17T16:05:59.722895750Z,2025-07-17T16:05:59.722730507Z,10,2,1108,C,A,0,13.720000000,100,130,165243,275325854,13.11,100,1,13.64,15,1,13.00,2,1,13.68,115,2,12.98,200,2,13.69,100,1,12.86,100,1,13.80,200,2,12.73,100,1,13.94,2,1,12.71,100,1,13.99,100,1,12.50,700,1,14.23,100,1,12.46,100,1,14.28,100,1,12.43,700,1,14.52,300,3,12.42,700,1,14.56,800,2,ARL,330144301
1933,2025-07-17T16:05:59.802762087Z,2025-07-17T16:05:59.802596747Z,10,2,1108,C,A,0,13.690000000,100,0,165340,275327082,13.11,100,1,13.64,15,1,13.00,2,1,13.68,115,2,12.98,200,2,13.80,200,2,12.86,100,1,13.94,2,1,12.73,100,1,13.99,100,1,12.71,100,1,14.23,100,1,12.50,700,1,14.28,100,1,12.46,100,1,14.52,300,3,12.43,700,1,14.56,800,2,12.42,700,1,14.60,700,1,ARL,330151389
1934,2025-07-17T16:05:59.802762087Z,2025-07-17T16:05:59.802596747Z,10,2,1108,A,A,0,13.650000000,100,130,165340,275327082,13.11,100,1,13.64,15,1,13.00,2,1,13.65,100,1,12.98,200,2,13.68,115,2,12.86,100,1,13.80,200,2,12.73,100,1,13.94,2,1,12.71,100,1,13.99,100,1,12.50,700,1,14.23,100,1,12.46,100,1,14.28,100,1,12.43,700,1,14.52,300,3,12.42,700,1,14.56,800,2,ARL,330359197
1935,2025-07-17T16:05:59.803504658Z,2025-07-17T16:05:59.803338996Z,10,2,1108,C,A,0,14.780000000,100,0,165662,275327093,13.11,100,1,13.64,15,1,13.00,2,1,13.65,100,1,12.98,200,2,13.68,115,2,12.86,100,1,13.80,200,2,12.73,100,1,13.94,2,1,12.71,100,1,13.99,100,1,12.50,700,1,14.23,100,1,12.46,100,1,14.28,100,1,12.43,700,1,14.52,300,3,12.42,700,1,14.56,800,2,ARL,330144321
1936,2025-07-17T16:05:59.803504658Z,2025-07-17T16:05:59.803338996Z,10,2,1108,A,A,0,14.710000000,100,130,165662,275327093,13.11,100,1,13.64,15,1,13.00,2,1,13.65,100,1,12.98,200,2,13.68,115,2,12.86,100,1,13.80,200,2,12.73,100,1,13.94,2,1,12.71,100,1,13.99,100,1,12.50,700,1,14.23,100,1,12.46,100,1,14.28,100,1,12.43,700,1,14.52,300,3,12.42,700,1,14.56,800,2,ARL,330359225
1937,2025-07-17T16:05:59.827787837Z,2025-07-17T16:05:59.827622529Z,10,2,1108,C,A,0,13.990000000,100,130,165308,275327416,13.11,100,1,13.64,15,1,13.00,2,1,13.65,100,1,12.98,200,2,13.68,115,2,12.86,100,1,13.80,200,2,12.73,100,1,13.94,2,1,12.71,100,1,14.23,100,1,12.50,700,1,14.28,100,1,12.46,100,1,14.52,300,3,12.43,700,1,14.56,800,2,12.42,700,1,14.60,700,1,ARL,330144513
1938,2025-07-17T16:05:59.827839802Z,2025-07-17T16:05:59.827674437Z,10,2,1108,A,A,0,13.920000000,100,130,165365,275327417,13.11,100,1,13.64,15,1,13.00,2,1,13.65,100,1,12.98,200,2,13.68,115,2,12.86,100,1,13.80,200,2,12.73,100,1,13.92,100,1,12.71,100,1,13.94,2,1,12.50,700,1,14.23,100,1,12.46,100,1,14.28,100,1,12.43,700,1,14.52,300,3,12.42,700,1,14.56,800,2,ARL,330359625
1939,2025-07-17T16:06:02.724446337Z,2025-07-17T16:06:02.724280161Z,10,2,1108,C,A,0,13.680000000,15,128,166176,275430576,13.11,100,1,13.64,15,1,13.00,2,1,13.65,100,1,12.98,200,2,13.68,100,1,12.86,100,1,13.80,200,2,12.73,100,1,13.92,100,1,12.71,100,1,13.94,2,1,12.50,700,1,14.23,100,1,12.46,100,1,14.28,100,1,12.43,700,1,14.52,300,3,12.42,700,1,14.56,800,2,ARL,330143813
1940,2025-07-17T16:06:03.729377770Z,2025-07-17T16:06:03.729212428Z,10,2,1108,A,A,0,13.620000000,15,130,165342,275517342,13.11,100,1,13.62,15,1,13.00,2,1,13.64,15,1,12.98,200,2,13.65,100,1,12.86,100,1,13.68,100,1,12.73,100,1,13.80,200,2,12.71,100,1,13.92,100,1,12.50,700,1,13.94,2,1,12.46,100,1,14.23,100,1,12.43,700,1,14.28,100,1,12.42,700,1,14.52,300,3,ARL,330577045
1941,2025-07-17T16:06:03.738497645Z,2025-07-17T16:06:03.738332427Z,10,2,1108,A,A,0,13.650000000,100,130,165218,275517997,13.11,100,1,13.62,15,1,13.00,2,1,13.64,15,1,12.98,200,2,13.65,200,2,12.86,100,1,13.68,100,1,12.73,100,1,13.80,200,2,12.71,100,1,13.92,100,1,12.50,700,1,13.94,2,1,12.46,100,1,14.23,100,1,12.43,700,1,14.28,100,1,12.42,700,1,14.52,300,3,ARL,330577773
1942,2025-07-17T16:06:03.747495669Z,2025-07-17T16:06:03.747330178Z,10,2,1108,C,A,0,13.680000000,100,130,165491,275518621,13.11,100,1,13.62,15,1,13.00,2,1,13.64,15,1,12.98,200,2,13.65,200,2,12.86,100,1,13.80,200,2,12.73,100,1,13.92,100,1,12.71,100,1,13.94,2,1,12.50,700,1,14.23,100,1,12.46,100,1,14.28,100,1,12.43,700,1,14.52,300,3,12.42,700,1,14.56,800,2,ARL,330357633
1943,2025-07-17T16:06:03.887274670Z,2025-07-17T16:06:03.887107153Z,10,2,1108,C,A,0,13.650000000,100,0,167517,275532429,13.11,100,1,13.62,15,1,13.00,2,1,13.64,15,1,12.98,200,2,13.65,100,1,12.86,100,1,13.80,200,2,12.73,100,1,13.92,100,1,12.71,100,1,13.94,2,1,12.50,700,1,14.23,100,1,12.46,100,1,14.28,100,1,12.43,700,1,14.52,300,3,12.42,700,1,14.56,800,2,ARL,330359197
1944,2025-07-17T16:06:03.887274670Z,2025-07-17T16:06:03.887107153Z,10,2,1108,A,A,0,13.630000000,100,130,167517,275532429,13.11,100,1,13.62,15,1,13.00,2,1,13.63,100,1,12.98,200,2,13.64,15,1,12.86,100,1,13.65,100,1,12.73,100,1,13.80,200,2,12.71,100,1,13.92,100,1,12.50,700,1,13.94,2,1,12.46,100,1,14.23,100,1,12.43,700,1,14.28,100,1,12.42,700,1,14.52,300,3,ARL,330592465
1945,2025-07-17T16:06:07.510050758Z,2025-07-17T16:06:07.509885114Z,10,2,1108,C,A,0,13.640000000,15,130,165644,275647392,13.11,100,1,13.62,15,1,13.00,2,1,13.63,100,1,12.98,200,2,13.65,100,1,12.86,100,1,13.80,200,2,12.73,100,1,13.92,100,1,12.71,100,1,13.94,2,1,12.50,700,1,14.23,100,1,12.46,100,1,14.28,100,1,12.43,700,1,14.52,300,3,12.42,700,1,14.56,800,2,ARL,330357473
1946,2025-07-17T16:06:09.885143909Z,2025-07-17T16:06:09.884978592Z,10,2,1108,A,A,0,13.600000000,15,130,165317,275699092,13.11,100,1,13.60,15,1,13.00,2,1,13.62,15,1,12.98,200,2,13.63,100,1,12.86,100,1,13.65,100,1,12.73,100,1,13.80,200,2,12.71,100,1,13.92,100,1,12.50,700,1,13.94,2,1,12.46,100,1,14.23,100,1,12.43,700,1,14.28,100,1,12.42,700,1,14.52,300,3,ARL,330788421
1947,2025-07-17T16:06:09.967608061Z,2025-07-17T16:06:09.967442600Z,10,2,1108,C,A,0,13.630000000,100,0,165461,275700261,13.11,100,1,13.60,15,1,13.00,2,1,13.62,15,1,12.98,200,2,13.65,100,1,12.86,100,1,13.80,200,2,12.73,100,1,13.92,100,1,12.71,100,1,13.94,2,1,12.50,700,1,14.23,100,1,12.46,100,1,14.28,100,1,12.43,700,1,14.52,300,3,12.42,700,1,14.56,800,2,ARL,330592465
1948,2025-07-17T16:06:09.967608061Z,2025-07-17T16:06:09.967442600Z,10,2,1108,A,A,0,13.610000000,100,130,165461,275700261,13.11,100,1,13.60,15,1,13.00,2,1,13.61,100,1,12.98,200,2,13.62,15,1,12.86,100,1,13.65,100,1,12.73,100,1,13.80,200,2,12.71,100,1,13.92,100,1,12.50,700,1,13.94,2,1,12.46,100,1,14.23,100,1,12.43,700,1,14.28,100,1,12.42,700,1,14.52,300,3,ARL,330789481
1949,2025-07-17T16:06:09.968352066Z,2025-07-17T16:06:09.968186617Z,10,2,1108,C,A,0,14.710000000,100,0,165449,275700270,13.11,100,1,13.60,15,1,13.00,2,1,13.61,100,1,12.98,200,2,13.62,15,1,12.86,100,1,13.65,100,1,12.73,100,1,13.80,200,2,12.71,100,1,13.92,100,1,12.50,700,1,13.94,2,1,12.46,100,1,14.23,100,1,12.43,700,1,14.28,100,1,12.42,700,1,14.52,300,3,ARL,330359225
1950,2025-07-17T16:06:09.968352066Z,2025-07-17T16:06:09.968186617Z,10,2,1108,A,A,0,14.670000000,100,130,165449,275700270,13.11,100,1,13.60,15,1,13.00,2,1,13.61,100,1,12.98,200,2,13.62,15,1,12.86,100,1,13.65,100,1,12.73,100,1,13.80,200,2,12.71,100,1,13.92,100,1,12.50,700,1,13.94,2,1,12.46,100,1,14.23,100,1,12.43,700,1,14.28,100,1,12.42,700,1,14.52,300,3,ARL,330789501
1951,2025-07-17T16:06:09.970040686Z,2025-07-17T16:06:09.969875190Z,10,2,1108,C,A,0,17.440000000,100,0,165496,275700282,13.11,100,1,13.60,15,1,13.00,2,1,13.61,100,1,12.98,200,2,13.62,15,1,12.86,100,1,13.65,100,1,12.73,100,1,13.80,200,2,12.71,100,1,13.92,100,1,12.50,700,1,13.94,2,1,12.46,100,1,14.23,100,1,12.43,700,1,14.28,100,1,12.42,700,1,14.52,300,3,ARL,327870217
1952,2025-07-17T16:06:09.970040686Z,2025-07-17T16:06:09.969875190Z,10,2,1108,A,A,0,17.290000000,100,130,165496,275700282,13.11,100,1,13.60,15,1,13.00,2,1,13.61,100,1,12.98,200,2,13.62,15,1,12.86,100,1,13.65,100,1,12.73,100,1,13.80,200,2,12.71,100,1,13.92,100,1,12.50,700,1,13.94,2,1,12.46,100,1,14.23,100,1,12.43,700,1,14.28,100,1,12.42,700,1,14.52,300,3,ARL,330789509
1953,2025-07-17T16:06:20.470889851Z,2025-07-17T16:06:20.470724464Z,10,2,1108,A,A,0,13.630000000,100,130,165387,275896138,13.11,100,1,13.60,15,1,13.00,2,1,13.61,100,1,12.98,200,2,13.62,15,1,12.86,100,1,13.63,100,1,12.73,100,1,13.65,100,1,12.71,100,1,13.80,200,2,12.50,700,1,13.92,100,1,12.46,100,1,13.94,2,1,12.43,700,1,14.23,100,1,12.42,700,1,14.28,100,1,ARL,331018065
1954,2025-07-17T16:06:20.477598578Z,2025-07-17T16:06:20.477432988Z,10,2,1108,C,A,0,13.650000000,100,130,165590,275896242,13.11,100,1,13.60,15,1,13.00,2,1,13.61,100,1,12.98,200,2,13.62,15,1,12.86,100,1,13.63,100,1,12.73,100,1,13.80,200,2,12.71,100,1,13.92,100,1,12.50,700,1,13.94,2,1,12.46,100,1,14.23,100,1,12.43,700,1,14.28,100,1,12.42,700,1,14.52,300,3,ARL,330577773
1955,2025-07-17T16:06:20.811164178Z,2025-07-17T16:06:20.810998706Z,10,2,1108,C,A,0,13.620000000,15,130,165472,275900161,13.11,100,1,13.60,15,1,13.00,2,1,13.61,100,1,12.98,200,2,13.63,100,1,12.86,100,1,13.80,200,2,12.73,100,1,13.92,100,1,12.71,100,1,13.94,2,1,12.50,700,1,14.23,100,1,12.46,100,1,14.28,100,1,12.43,700,1,14.52,300,3,12.42,700,1,14.56,800,2,ARL,330577045
1956,2025-07-17T16:06:22.151222819Z,2025-07-17T16:06:22.151057292Z,10,2,1108,A,A,0,13.580000000,15,130,165527,275926927,13.11,100,1,13.58,15,1,13.00,2,1,13.60,15,1,12.98,200,2,13.61,100,1,12.86,100,1,13.63,100,1,12.73,100,1,13.80,200,2,12.71,100,1,13.92,100,1,12.50,700,1,13.94,2,1,12.46,100,1,14.23,100,1,12.43,700,1,14.28,100,1,12.42,700,1,14.52,300,3,ARL,331050981
1957,2025-07-17T16:06:22.151491832Z,2025-07-17T16:06:22.151326300Z,10,2,1108,C,A,0,13.610000000,100,0,165532,275926940,13.11,100,1,13.58,15,1,13.00,2,1,13.60,15,1,12.98,200,2,13.63,100,1,12.86,100,1,13.80,200,2,12.73,100,1,13.92,100,1,12.71,100,1,13.94,2,1,12.50,700,1,14.23,100,1,12.46,100,1,14.28,100,1,12.43,700,1,14.52,300,3,12.42,700,1,14.56,800,2,ARL,330789481
1958,2025-07-17T16:06:22.151491832Z,2025-07-17T16:06:22.151326300Z,10,2,1108,A,A,0,13.590000000,100,130,165532,275926940,13.11,100,1,13.58,15,1,13.00,2,1,13.59,100,1,12.98,200,2,13.60,15,1,12.86,100,1,13.63,100,1,12.73,100,1,13.80,200,2,12.71,100,1,13.92,100,1,12.50,700,1,13.94,2,1,12.46,100,1,14.23,100,1,12.43,700,1,14.28,100,1,12.42,700,1,14.52,300,3,ARL,331050989
1959,2025-07-17T16:06:22.151761329Z,2025-07-17T16:06:22.151595415Z,10,2,1108,C,A,0,13.800000000,100,0,165914,275926966,13.11,100,1,13.58,15,1,13.00,2,1,13.59,100,1,12.98,200,2,13.60,15,1,12.86,100,1,13.63,100,1,12.73,100,1,13.80,100,1,12.71,100,1,13.92,100,1,12.50,700,1,13.94,2,1,12.46,100,1,14.23,100,1,12.43,700,1,14.28,100,1,12.42,700,1,14.52,300,3,ARL,328614525
1960,2025-07-17T16:06:22.151761329Z,2025-07-17T16:06:22.151595781Z,10,2,1108,C,A,0,13.800000000,100,130,165548,275926967,13.11,100,1,13.58,15,1,13.00,2,1,13.59,100,1,12.98,200,2,13.60,15,1,12.86,100,1,13.63,100,1,12.73,100,1,13.92,100,1,12.71,100,1,13.94,2,1,12.50,700,1,14.23,100,1,12.46,100,1,14.28,100,1,12.43,700,1,14.52,300,3,12.42,700,1,14.56,800,2,ARL,328614529
1961,2025-07-17T16:06:22.153148893Z,2025-07-17T16:06:22.152983326Z,10,2,1108,C,A,0,15.790000000,100,0,165567,275927034,13.11,100,1,13.58,15,1,13.00,2,1,13.59,100,1,12.98,200,2,13.60,15,1,12.86,100,1,13.63,100,1,12.73,100,1,13.92,100,1,12.71,100,1,13.94,2,1,12.50,700,1,14.23,100,1,12.46,100,1,14.28,100,1,12.43,700,1,14.52,300,3,12.42,700,1,14.56,800,2,ARL,327870361
1962,2025-07-17T16:06:22.153148893Z,2025-07-17T16:06:22.152983326Z,10,2,1108,A,A,0,15.630000000,100,130,165567,275927034,13.11,100,1,13.58,15,1,13.00,2,1,13.59,100,1,12.98,200,2,13.60,15,1,12.86,100,1,13.63,100,1,12.73,100,1,13.92,100,1,12.71,100,1,13.94,2,1,12.50,700,1,14.23,100,1,12.46,100,1,14.28,100,1,12.43,700,1,14.52,300,3,12.42,700,1,14.56,800,2,ARL,331051145
1963,2025-07-17T16:06:22.153916169Z,2025-07-17T16:06:22.153749481Z,10,2,1108,C,A,0,14.700000000,100,0,166688,275927046,13.11,100,1,13.58,15,1,13.00,2,1,13.59,100,1,12.98,200,2,13.60,15,1,12.86,100,1,13.63,100,1,12.73,100,1,13.92,100,1,12.71,100,1,13.94,2,1,12.50,700,1,14.23,100,1,12.46,100,1,14.28,100,1,12.43,700,1,14.52,300,3,12.42,700,1,14.56,800,2,ARL,327868421
1964,2025-07-17T16:06:22.153916169Z,2025-07-17T16:06:22.153749481Z,10,2,1108,A,A,0,14.550000000,100,130,166688,275927046,13.11,100,1,13.58,15,1,13.00,2,1,13.59,100,1,12.98,200,2,13.60,15,1,12.86,100,1,13.63,100,1,12.73,100,1,13.92,100,1,12.71,100,1,13.94,2,1,12.50,700,1,14.23,100,1,12.46,100,1,14.28,100,1,12.43,700,1,14.52,300,3,12.42,700,1,14.55,100,1,ARL,331051173
1965,2025-07-17T16:06:22.156070698Z,2025-07-17T16:06:22.155905240Z,10,2,1108,C,A,0,14.520000000,100,0,165458,275927117,13.11,100,1,13.58,15,1,13.00,2,1,13.59,100,1,12.98,200,2,13.60,15,1,12.86,100,1,13.63,100,1,12.73,100,1,13.92,100,1,12.71,100,1,13.94,2,1,12.50,700,1,14.23,100,1,12.46,100,1,14.28,100,1,12.43,700,1,14.52,200,2,12.42,700,1,14.55,100,1,ARL,327869529
1966,2025-07-17T16:06:22.156070698Z,2025-07-17T16:06:22.155905240Z,10,2,1108,A,A,0,14.380000000,100,130,165458,275927117,13.11,100,1,13.58,15,1,13.00,2,1,13.59,100,1,12.98,200,2,13.60,15,1,12.86,100,1,13.63,100,1,12.73,100,1,13.92,100,1,12.71,100,1,13.94,2,1,12.50,700,1,14.23,100,1,12.46,100,1,14.28,100,1,12.43,700,1,14.38,100,1,12.42,700,1,14.52,200,2,ARL,331051369
1967,2025-07-17T16:06:22.178044675Z,2025-07-17T16:06:22.177879233Z,10,2,1108,C,A,0,14.700000000,100,0,165442,275927444,13.11,100,1,13.58,15,1,13.00,2,1,13.59,100,1,12.98,200,2,13.60,15,1,12.86,100,1,13.63,100,1,12.73,100,1,13.92,100,1,12.71,100,1,13.94,2,1,12.50,700,1,14.23,100,1,12.46,100,1,14.28,100,1,12.43,700,1,14.38,100,1,12.42,700,1,14.52,200,2,ARL,327873009
1968,2025-07-17T16:06:22.178044675Z,2025-07-17T16:06:22.177879233Z,10,2,1108,A,A,0,14.550000000,100,130,165442,275927444,13.11,100,1,13.58,15,1,13.00,2,1,13.59,100,1,12.98,200,2,13.60,15,1,12.86,100,1,13.63,100,1,12.73,100,1,13.92,100,1,12.71,100,1,13.94,2,1,12.50,700,1,14.23,100,1,12.46,100,1,14.28,100,1,12.43,700,1,14.38,100,1,12.42,700,1,14.52,200,2,ARL,331052197
1969,2025-07-17T16:06:24.519511128Z,2025-07-17T16:06:24.519345743Z,10,2,1108,A,A,0,13.600000000,100,130,165385,275968354,13.11,100,1,13.58,15,1,13.00,2,1,13.59,100,1,12.98,200,2,13.60,115,2,12.86,100,1,13.63,100,1,12.73,100,1,13.92,100,1,12.71,100,1,13.94,2,1,12.50,700,1,14.23,100,1,12.46,100,1,14.28,100,1,12.43,700,1,14.38,100,1,12.42,700,1,14.52,200,2,ARL,331104725
1970,2025-07-17T16:06:24.526359716Z,2025-07-17T16:06:24.526194457Z,10,2,1108,C,A,0,13.630000000,100,130,165259,275968393,13.11,100,1,13.58,15,1,13.00,2,1,13.59,100,1,12.98,200,2,13.60,115,2,12.86,100,1,13.92,100,1,12.73,100,1,13.94,2,1,12.71,100,1,14.23,100,1,12.50,700,1,14.28,100,1,12.46,100,1,14.38,100,1,12.43,700,1,14.52,200,2,12.42,700,1,14.55,200,2,ARL,331018065
1971,2025-07-17T16:06:26.610345800Z,2025-07-17T16:06:26.610180184Z,10,2,1108,C,A,0,13.940000000,2,0,165616,276013080,13.11,100,1,13.58,15,1,13.00,2,1,13.59,100,1,12.98,200,2,13.60,115,2,12.86,100,1,13.92,100,1,12.73,100,1,14.23,100,1,12.71,100,1,14.28,100,1,12.50,700,1,14.38,100,1,12.46,100,1,14.52,200,2,12.43,700,1,14.55,200,2,12.42,700,1,14.56,800,2,ARL,328351217
1972,2025-07-17T16:06:26.610345800Z,2025-07-17T16:06:26.610180184Z,10,2,1108,A,A,0,13.850000000,2,130,165616,276013080,13.11,100,1,13.58,15,1,13.00,2,1,13.59,100,1,12.98,200,2,13.60,115,2,12.86,100,1,13.85,2,1,12.73,100,1,13.92,100,1,12.71,100,1,14.23,100,1,12.50,700,1,14.28,100,1,12.46,100,1,14.38,100,1,12.43,700,1,14.52,200,2,12.42,700,1,14.55,200,2,ARL,331155889
1973,2025-07-17T16:06:30.625877214Z,2025-07-17T16:06:30.625711923Z,10,2,1108,A,A,0,14.270000000,700,130,165291,276103282,13.11,100,1,13.58,15,1,13.00,2,1,13.59,100,1,12.98,200,2,13.60,115,2,12.86,100,1,13.85,2,1,12.73,100,1,13.92,100,1,12.71,100,1,14.23,100,1,12.50,700,1,14.27,700,1,12.46,100,1,14.28,100,1,12.43,700,1,14.38,100,1,12.42,700,1,14.52,200,2,ARL,331257169
1974,2025-07-17T16:06:30.625956307Z,2025-07-17T16:06:30.625790910Z,10,2,1108,C,A,0,14.680000000,700,130,165397,276103283,13.11,100,1,13.58,15,1,13.00,2,1,13.59,100,1,12.98,200,2,13.60,115,2,12.86,100,1,13.85,2,1,12.73,100,1,13.92,100,1,12.71,100,1,14.23,100,1,12.50,700,1,14.27,700,1,12.46,100,1,14.28,100,1,12.43,700,1,14.38,100,1,12.42,700,1,14.52,200,2,ARL,325716945
1975,2025-07-17T16:06:31.127827805Z,2025-07-17T16:06:31.127662311Z,10,2,1108,A,A,0,14.480000000,700,130,165494,276118990,13.11,100,1,13.58,15,1,13.00,2,1,13.59,100,1,12.98,200,2,13.60,115,2,12.86,100,1,13.85,2,1,12.73,100,1,13.92,100,1,12.71,100,1,14.23,100,1,12.50,700,1,14.27,700,1,12.46,100,1,14.28,100,1,12.43,700,1,14.38,100,1,12.42,700,1,14.48,700,1,ARL,331272997
1976,2025-07-17T16:06:31.128581831Z,2025-07-17T16:06:31.128416336Z,10,2,1108,C,A,0,14.680000000,700,130,165495,276119017,13.11,100,1,13.58,15,1,13.00,2,1,13.59,100,1,12.98,200,2,13.60,115,2,12.86,100,1,13.85,2,1,12.73,100,1,13.92,100,1,12.71,100,1,14.23,100,1,12.50,700,1,14.27,700,1,12.46,100,1,14.28,100,1,12.43,700,1,14.38,100,1,12.42,700,1,14.48,700,1,ARL,289932801
1977,2025-07-17T16:06:31.990649229Z,2025-07-17T16:06:31.990483799Z,10,2,1108,C,A,0,13.600000000,15,130,165430,276135226,13.11,100,1,13.58,15,1,13.00,2,1,13.59,100,1,12.98,200,2,13.60,100,1,12.86,100,1,13.85,2,1,12.73,100,1,13.92,100,1,12.71,100,1,14.23,100,1,12.50,700,1,14.27,700,1,12.46,100,1,14.28,100,1,12.43,700,1,14.38,100,1,12.42,700,1,14.48,700,1,ARL,330788421
1978,2025-07-17T16:06:42.812807096Z,2025-07-17T16:06:42.812641697Z,10,2,1108,A,A,0,13.560000000,15,130,165399,276276783,13.11,100,1,13.56,15,1,13.00,2,1,13.58,15,1,12.98,200,2,13.59,100,1,12.86,100,1,13.60,100,1,12.73,100,1,13.85,2,1,12.71,100,1,13.92,100,1,12.50,700,1,14.23,100,1,12.46,100,1,14.27,700,1,12.43,700,1,14.28,100,1,12.42,700,1,14.38,100,1,ARL,331488089
1979,2025-07-17T16:06:43.012965957Z,2025-07-17T16:06:43.012799164Z,10,2,1108,C,A,0,13.590000000,100,0,166793,276279311,13.11,100,1,13.56,15,1,13.00,2,1,13.58,15,1,12.98,200,2,13.60,100,1,12.86,100,1,13.85,2,1,12.73,100,1,13.92,100,1,12.71,100,1,14.23,100,1,12.50,700,1,14.27,700,1,12.46,100,1,14.28,100,1,12.43,700,1,14.38,100,1,12.42,700,1,14.48,700,1,ARL,331050989
1980,2025-07-17T16:06:43.012965957Z,2025-07-17T16:06:43.012799164Z,10,2,1108,A,A,0,13.570000000,100,128,166793,276279311,13.11,100,1,13.56,15,1,13.00,2,1,13.57,100,1,12.98,200,2,13.58,15,1,12.86,100,1,13.60,100,1,12.73,100,1,13.85,2,1,12.71,100,1,13.92,100,1,12.50,700,1,14.23,100,1,12.46,100,1,14.27,700,1,12.43,700,1,14.28,100,1,12.42,700,1,14.38,100,1,ARL,331491049
1981,2025-07-17T16:06:43.013716205Z,2025-07-17T16:06:43.013550575Z,10,2,1108,C,A,0,14.670000000,100,0,165630,276279331,13.11,100,1,13.56,15,1,13.00,2,1,13.57,100,1,12.98,200,2,13.58,15,1,12.86,100,1,13.60,100,1,12.73,100,1,13.85,2,1,12.71,100,1,13.92,100,1,12.50,700,1,14.23,100,1,12.46,100,1,14.27,700,1,12.43,700,1,14.28,100,1,12.42,700,1,14.38,100,1,ARL,330789501
1982,2025-07-17T16:06:43.013716205Z,2025-07-17T16:06:43.013550575Z,10,2,1108,A,A,0,14.620000000,100,130,165630,276279331,13.11,100,1,13.56,15,1,13.00,2,1,13.57,100,1,12.98,200,2,13.58,15,1,12.86,100,1,13.60,100,1,12.73,100,1,13.85,2,1,12.71,100,1,13.92,100,1,12.50,700,1,14.23,100,1,12.46,100,1,14.27,700,1,12.43,700,1,14.28,100,1,12.42,700,1,14.38,100,1,ARL,331491077
1983,2025-07-17T16:06:43.024656023Z,2025-07-17T16:06:43.024490355Z,10,2,1108,C,A,0,13.920000000,100,130,165668,276279620,13.11,100,1,13.56,15,1,13.00,2,1,13.57,100,1,12.98,200,2,13.58,15,1,12.86,100,1,13.60,100,1,12.73,100,1,13.85,2,1,12.71,100,1,14.23,100,1,12.50,700,1,14.27,700,1,12.46,100,1,14.28,100,1,12.43,700,1,14.38,100,1,12.42,700,1,14.48,700,1,ARL,330359625
1984,2025-07-17T16:06:43.024708304Z,2025-07-17T16:06:43.024543099Z,10,2,1108,A,A,0,13.840000000,100,130,165205,276279621,13.11,100,1,13.56,15,1,13.00,2,1,13.57,100,1,12.98,200,2,13.58,15,1,12.86,100,1,13.60,100,1,12.73,100,1,13.84,100,1,12.71,100,1,13.85,2,1,12.50,700,1,14.23,100,1,12.46,100,1,14.27,700,1,12.43,700,1,14.28,100,1,12.42,700,1,14.38,100,1,ARL,331491269
1985,2025-07-17T16:06:49.613941821Z,2025-07-17T16:06:49.613776144Z,10,2,1108,C,A,0,13.580000000,15,130,165677,276382302,13.11,100,1,13.56,15,1,13.00,2,1,13.57,100,1,12.98,200,2,13.60,100,1,12.86,100,1,13.84,100,1,12.73,100,1,13.85,2,1,12.71,100,1,14.23,100,1,12.50,700,1,14.27,700,1,12.46,100,1,14.28,100,1,12.43,700,1,14.38,100,1,12.42,700,1,14.48,700,1,ARL,331050981
1986,2025-07-17T16:06:50.618669843Z,2025-07-17T16:06:50.618504506Z,10,2,1108,A,A,0,13.540000000,15,130,165337,276408477,13.11,100,1,13.54,15,1,13.00,2,1,13.56,15,1,12.98,200,2,13.57,100,1,12.86,100,1,13.60,100,1,12.73,100,1,13.84,100,1,12.71,100,1,13.85,2,1,12.50,700,1,14.23,100,1,12.46,100,1,14.27,700,1,12.43,700,1,14.28,100,1,12.42,700,1,14.38,100,1,ARL,331666961
1987,2025-07-17T16:06:50.626438205Z,2025-07-17T16:06:50.626272828Z,10,2,1108,A,A,0,13.580000000,100,130,165377,276408566,13.11,100,1,13.54,15,1,13.00,2,1,13.56,15,1,12.98,200,2,13.57,100,1,12.86,100,1,13.58,100,1,12.73,100,1,13.60,100,1,12.71,100,1,13.84,100,1,12.50,700,1,13.85,2,1,12.46,100,1,14.23,100,1,12.43,700,1,14.27,700,1,12.42,700,1,14.28,100,1,ARL,331667121
1988,2025-07-17T16:06:50.633113557Z,2025-07-17T16:06:50.632947998Z,10,2,1108,C,A,0,13.600000000,100,130,165559,276408644,13.11,100,1,13.54,15,1,13.00,2,1,13.56,15,1,12.98,200,2,13.57,100,1,12.86,100,1,13.58,100,1,12.73,100,1,13.84,100,1,12.71,100,1,13.85,2,1,12.50,700,1,14.23,100,1,12.46,100,1,14.27,700,1,12.43,700,1,14.28,100,1,12.42,700,1,14.38,100,1,ARL,331104725
1989,2025-07-17T16:06:51.754576322Z,2025-07-17T16:06:51.754410704Z,10,2,1108,C,A,0,13.570000000,100,0,165618,276428315,13.11,100,1,13.54,15,1,13.00,2,1,13.56,15,1,12.98,200,2,13.58,100,1,12.86,100,1,13.84,100,1,12.73,100,1,13.85,2,1,12.71,100,1,14.23,100,1,12.50,700,1,14.27,700,1,12.46,100,1,14.28,100,1,12.43,700,1,14.38,100,1,12.42,700,1,14.48,700,1,ARL,331491049
1990,2025-07-17T16:06:51.754576322Z,2025-07-17T16:06:51.754410704Z,10,2,1108,A,A,0,13.550000000,100,130,165618,276428315,13.11,100,1,13.54,15,1,13.00,2,1,13.55,100,1,12.98,200,2,13.56,15,1,12.86,100,1,13.58,100,1,12.73,100,1,13.84,100,1,12.71,100,1,13.85,2,1,12.50,700,1,14.23,100,1,12.46,100,1,14.27,700,1,12.43,700,1,14.28,100,1,12.42,700,1,14.38,100,1,ARL,331694265
1991,2025-07-17T16:06:51.757403109Z,2025-07-17T16:06:51.757237300Z,10,2,1108,C,B,0,13.000000000,2,0,165809,276428333,13.11,100,1,13.54,15,1,12.98,200,2,13.55,100,1,12.86,100,1,13.56,15,1,12.73,100,1,13.58,100,1,12.71,100,1,13.84,100,1,12.50,700,1,13.85,2,1,12.46,100,1,14.23,100,1,12.43,700,1,14.27,700,1,12.42,700,1,14.28,100,1,12.37,700,1,14.38,100,1,ARL,325967705
1992,2025-07-17T16:06:51.757403109Z,2025-07-17T16:06:51.757237300Z,10,2,1108,A,B,0,12.900000000,2,130,165809,276428333,13.11,100,1,13.54,15,1,12.98,200,2,13.55,100,1,12.90,2,1,13.56,15,1,12.86,100,1,13.58,100,1,12.73,100,1,13.84,100,1,12.71,100,1,13.85,2,1,12.50,700,1,14.23,100,1,12.46,100,1,14.27,700,1,12.43,700,1,14.28,100,1,12.42,700,1,14.38,100,1,ARL,331694297
1993,2025-07-17T16:06:55.056300861Z,2025-07-17T16:06:55.056135380Z,10,2,1108,C,A,0,13.540000000,15,130,165481,276516227,13.11,100,1,13.55,100,1,12.98,200,2,13.56,15,1,12.90,2,1,13.58,100,1,12.86,100,1,13.84,100,1,12.73,100,1,13.85,2,1,12.71,100,1,14.23,100,1,12.50,700,1,14.27,700,1,12.46,100,1,14.28,100,1,12.43,700,1,14.38,100,1,12.42,700,1,14.48,700,1,ARL,331666961
1994,2025-07-17T16:06:55.056466231Z,2025-07-17T16:06:55.056301001Z,10,2,1108,C,A,0,13.560000000,15,130,165230,276516239,13.11,100,1,13.55,100,1,12.98,200,2,13.58,100,1,12.90,2,1,13.84,100,1,12.86,100,1,13.85,2,1,12.73,100,1,14.23,100,1,12.71,100,1,14.27,700,1,12.50,700,1,14.28,100,1,12.46,100,1,14.38,100,1,12.43,700,1,14.48,700,1,12.42,700,1,14.52,200,2,ARL,331488089
1995,2025-07-17T16:07:00.010995558Z,2025-07-17T16:07:00.010829521Z,10,2,1108,C,A,0,13.550000000,100,130,166037,276611719,13.11,100,1,13.58,100,1,12.98,200,2,13.84,100,1,12.90,2,1,13.85,2,1,12.86,100,1,14.23,100,1,12.73,100,1,14.27,700,1,12.71,100,1,14.28,100,1,12.50,700,1,14.38,100,1,12.46,100,1,14.48,700,1,12.43,700,1,14.52,200,2,12.42,700,1,14.55,200,2,ARL,331694265
1996,2025-07-17T16:07:00.023849180Z,2025-07-17T16:07:00.023683961Z,10,2,1108,C,A,0,13.580000000,100,130,165219,276613073,13.11,100,1,13.84,100,1,12.98,200,2,13.85,2,1,12.90,2,1,14.23,100,1,12.86,100,1,14.27,700,1,12.73,100,1,14.28,100,1,12.71,100,1,14.38,100,1,12.50,700,1,14.48,700,1,12.46,100,1,14.52,200,2,12.43,700,1,14.55,200,2,12.42,700,1,14.56,800,2,ARL,331667121
1997,2025-07-17T16:07:00.023917543Z,2025-07-17T16:07:00.023752163Z,10,2,1108,C,A,0,14.270000000,700,130,165380,276613077,13.11,100,1,13.84,100,1,12.98,200,2,13.85,2,1,12.90,2,1,14.23,100,1,12.86,100,1,14.28,100,1,12.73,100,1,14.38,100,1,12.71,100,1,14.48,700,1,12.50,700,1,14.52,200,2,12.46,100,1,14.55,200,2,12.43,700,1,14.56,800,2,12.42,700,1,14.60,700,1,ARL,331257169
1998,2025-07-17T16:07:00.023980805Z,2025-07-17T16:07:00.023815326Z,10,2,1108,A,A,0,14.510000000,700,130,165479,276613078,13.11,100,1,13.84,100,1,12.98,200,2,13.85,2,1,12.90,2,1,14.23,100,1,12.86,100,1,14.28,100,1,12.73,100,1,14.38,100,1,12.71,100,1,14.48,700,1,12.50,700,1,14.51,700,1,12.46,100,1,14.52,200,2,12.43,700,1,14.55,200,2,12.42,700,1,14.56,800,2,ARL,331926981
1999,2025-07-17T16:07:00.024590283Z,2025-07-17T16:07:00.024424816Z,10,2,1108,C,A,0,14.620000000,100,0,165467,276613110,13.11,100,1,13.84,100,1,12.98,200,2,13.85,2,1,12.90,2,1,14.23,100,1,12.86,100,1,14.28,100,1,12.73,100,1,14.38,100,1,12.71,100,1,14.48,700,1,12.50,700,1,14.51,700,1,12.46,100,1,14.52,200,2,12.43,700,1,14.55,200,2,12.42,700,1,14.56,800,2,ARL,331491077
2000,2025-07-17T16:07:00.024590283Z,2025-07-17T16:07:00.024424816Z,10,2,1108,A,A,0,14.880000000,100,130,165467,276613110,13.11,100,1,13.84,100,1,12.98,200,2,13.85,2,1,12.90,2,1,14.23,100,1,12.86,100,1,14.28,100,1,12.73,100,1,14.38,100,1,12.71,100,1,14.48,700,1,12.50,700,1,14.51,700,1,12.46,100,1,14.52,200,2,12.43,700,1,14.55,200,2,12.42,700,1,14.56,800,2,ARL,331927017
2001,2025-07-17T16:07:00.025231164Z,2025-07-17T16:07:00.025064913Z,10,2,1108,C,A,0,14.230000000,100,130,166251,276613157,13.11,100,1,13.84,100,1,12.98,200,2,13.85,2,1,12.90,2,1,14.28,100,1,12.86,100,1,14.38,100,1,12.73,100,1,14.48,700,1,12.71,100,1,14.51,700,1,12.50,700,1,14.52,200,2,12.46,100,1,14.55,200,2,12.43,700,1,14.56,800,2,12.42,700,1,14.60,700,1,ARL,329074833
2002,2025-07-17T16:07:00.025587549Z,2025-07-17T16:07:00.025422082Z,10,2,1108,A,A,0,14.460000000,100,130,165467,276613175,13.11,100,1,13.84,100,1,12.98,200,2,13.85,2,1,12.90,2,1,14.28,100,1,12.86,100,1,14.38,100,1,12.73,100,1,14.46,100,1,12.71,100,1,14.48,700,1,12.50,700,1,14.51,700,1,12.46,100,1,14.52,200,2,12.43,700,1,14.55,200,2,12.42,700,1,14.56,800,2,ARL,331927161
2003,2025-07-17T16:07:00.025793260Z,2025-07-17T16:07:00.025628157Z,10,2,1108,A,A,0,13.590000000,100,130,165103,276613194,13.11,100,1,13.59,100,1,12.98,200,2,13.84,100,1,12.90,2,1,13.85,2,1,12.86,100,1,14.28,100,1,12.73,100,1,14.38,100,1,12.71,100,1,14.46,100,1,12.50,700,1,14.48,700,1,12.46,100,1,14.51,700,1,12.43,700,1,14.52,200,2,12.42,700,1,14.55,200,2,ARL,331927177
2004,2025-07-17T16:07:00.026998695Z,2025-07-17T16:07:00.026833761Z,10,2,1108,C,A,0,13.590000000,100,130,164934,276613224,13.11,100,1,13.84,100,1,12.98,200,2,13.85,2,1,12.90,2,1,14.28,100,1,12.86,100,1,14.38,100,1,12.73,100,1,14.46,100,1,12.71,100,1,14.48,700,1,12.50,700,1,14.51,700,1,12.46,100,1,14.52,200,2,12.43,700,1,14.55,200,2,12.42,700,1,14.56,800,2,ARL,331927177
2005,2025-07-17T16:07:00.032762182Z,2025-07-17T16:07:00.032596898Z,10,2,1108,C,A,0,14.380000000,100,130,165284,276613329,13.11,100,1,13.84,100,1,12.98,200,2,13.85,2,1,12.90,2,1,14.28,100,1,12.86,100,1,14.46,100,1,12.73,100,1,14.48,700,1,12.71,100,1,14.51,700,1,12.50,700,1,14.52,200,2,12.46,100,1,14.55,200,2,12.43,700,1,14.56,800,2,12.42,700,1,14.60,700,1,ARL,331051369
2006,2025-07-17T16:07:00.032876947Z,2025-07-17T16:07:00.032711777Z,10,2,1108,A,A,0,14.630000000,100,130,165170,276613336,13.11,100,1,13.84,100,1,12.98,200,2,13.85,2,1,12.90,2,1,14.28,100,1,12.86,100,1,14.46,100,1,12.73,100,1,14.48,700,1,12.71,100,1,14.51,700,1,12.50,700,1,14.52,200,2,12.46,100,1,14.55,200,2,12.43,700,1,14.56,800,2,12.42,700,1,14.60,700,1,ARL,331927477
2007,2025-07-17T16:07:00.045525047Z,2025-07-17T16:07:00.045359807Z,10,2,1108,C,A,0,13.840000000,100,130,165240,276613663,13.11,100,1,13.85,2,1,12.98,200,2,14.28,100,1,12.90,2,1,14.46,100,1,12.86,100,1,14.48,700,1,12.73,100,1,14.51,700,1,12.71,100,1,14.52,200,2,12.50,700,1,14.55,200,2,12.46,100,1,14.56,800,2,12.43,700,1,14.60,700,1,12.42,700,1,14.63,100,1,ARL,331491269
2008,2025-07-17T16:07:00.045559272Z,2025-07-17T16:07:00.045394317Z,10,2,1108,C,A,0,14.510000000,700,130,164955,276613664,13.11,100,1,13.85,2,1,12.98,200,2,14.28,100,1,12.90,2,1,14.46,100,1,12.86,100,1,14.48,700,1,12.73,100,1,14.52,200,2,12.71,100,1,14.55,200,2,12.50,700,1,14.56,800,2,12.46,100,1,14.60,700,1,12.43,700,1,14.63,100,1,12.42,700,1,14.88,100,1,ARL,331926981
2009,2025-07-17T16:07:00.045574786Z,2025-07-17T16:07:00.045409635Z,10,2,1108,A,A,0,14.090000000,100,130,165151,276613665,13.11,100,1,13.85,2,1,12.98,200,2,14.09,100,1,12.90,2,1,14.28,100,1,12.86,100,1,14.46,100,1,12.73,100,1,14.48,700,1,12.71,100,1,14.52,200,2,12.50,700,1,14.55,200,2,12.46,100,1,14.56,800,2,12.43,700,1,14.60,700,1,12.42,700,1,14.63,100,1,ARL,331927857
2010,2025-07-17T16:07:00.046838602Z,2025-07-17T16:07:00.046672908Z,10,2,1108,C,A,0,14.090000000,100,130,165694,276613680,13.11,100,1,13.85,2,1,12.98,200,2,14.28,100,1,12.90,2,1,14.46,100,1,12.86,100,1,14.48,700,1,12.73,100,1,14.52,200,2,12.71,100,1,14.55,200,2,12.50,700,1,14.56,800,2,12.46,100,1,14.60,700,1,12.43,700,1,14.63,100,1,12.42,700,1,14.88,100,1,ARL,331927857
2011,2025-07-17T16:07:00.046887005Z,2025-07-17T16:07:00.046721624Z,10,2,1108,A,A,0,13.860000000,100,130,165381,276613681,13.11,100,1,13.85,2,1,12.98,200,2,13.86,100,1,12.90,2,1,14.28,100,1,12.86,100,1,14.46,100,1,12.73,100,1,14.48,700,1,12.71,100,1,14.52,200,2,12.50,700,1,14.55,200,2,12.46,100,1,14.56,800,2,12.43,700,1,14.60,700,1,12.42,700,1,14.63,100,1,ARL,331927877
2012,2025-07-17T16:07:00.047708936Z,2025-07-17T16:07:00.047544064Z,10,2,1108,C,A,0,13.860000000,100,130,164872,276613692,13.11,100,1,13.85,2,1,12.98,200,2,14.28,100,1,12.90,2,1,14.46,100,1,12.86,100,1,14.48,700,1,12.73,100,1,14.52,200,2,12.71,100,1,14.55,200,2,12.50,700,1,14.56,800,2,12.46,100,1,14.60,700,1,12.43,700,1,14.63,100,1,12.42,700,1,14.88,100,1,ARL,331927877
2013,2025-07-17T16:07:00.047755498Z,2025-07-17T16:07:00.047590313Z,10,2,1108,A,A,0,14.120000000,100,130,165185,276613693,13.11,100,1,13.85,2,1,12.98,200,2,14.12,100,1,12.90,2,1,14.28,100,1,12.86,100,1,14.46,100,1,12.73,100,1,14.48,700,1,12.71,100,1,14.52,200,2,12.50,700,1,14.55,200,2,12.46,100,1,14.56,800,2,12.43,700,1,14.60,700,1,12.42,700,1,14.63,100,1,ARL,331927921
2014,2025-07-17T16:07:00.053448670Z,2025-07-17T16:07:00.053283700Z,10,2,1108,C,A,0,14.120000000,100,130,164970,276613731,13.11,100,1,13.85,2,1,12.98,200,2,14.28,100,1,12.90,2,1,14.46,100,1,12.86,100,1,14.48,700,1,12.73,100,1,14.52,200,2,12.71,100,1,14.55,200,2,12.50,700,1,14.56,800,2,12.46,100,1,14.60,700,1,12.43,700,1,14.63,100,1,12.42,700,1,14.88,100,1,ARL,331927921
2015,2025-07-17T16:07:00.053495095Z,2025-07-17T16:07:00.053329959Z,10,2,1108,A,A,0,14.260000000,100,130,165136,276613732,13.11,100,1,13.85,2,1,12.98,200,2,14.26,100,1,12.90,2,1,14.28,100,1,12.86,100,1,14.46,100,1,12.73,100,1,14.48,700,1,12.71,100,1,14.52,200,2,12.50,700,1,14.55,200,2,12.46,100,1,14.56,800,2,12.43,700,1,14.60,700,1,12.42,700,1,14.63,100,1,ARL,331928009
2016,2025-07-17T16:07:00.057809857Z,2025-07-17T16:07:00.057644427Z,10,2,1108,C,A,0,14.550000000,100,0,165430,276613800,13.11,100,1,13.85,2,1,12.98,200,2,14.26,100,1,12.90,2,1,14.28,100,1,12.86,100,1,14.46,100,1,12.73,100,1,14.48,700,1,12.71,100,1,14.52,200,2,12.50,700,1,14.55,100,1,12.46,100,1,14.56,800,2,12.43,700,1,14.60,700,1,12.42,700,1,14.63,100,1,ARL,331052197
2017,2025-07-17T16:07:00.057809857Z,2025-07-17T16:07:00.057644427Z,10,2,1108,A,A,0,14.960000000,100,130,165430,276613800,13.11,100,1,13.85,2,1,12.98,200,2,14.26,100,1,12.90,2,1,14.28,100,1,12.86,100,1,14.46,100,1,12.73,100,1,14.48,700,1,12.71,100,1,14.52,200,2,12.50,700,1,14.55,100,1,12.46,100,1,14.56,800,2,12.43,700,1,14.60,700,1,12.42,700,1,14.63,100,1,ARL,331928129
2018,2025-07-17T16:07:00.070490835Z,2025-07-17T16:07:00.070325784Z,10,2,1108,C,A,0,14.260000000,100,130,165051,276614087,13.11,100,1,13.85,2,1,12.98,200,2,14.28,100,1,12.90,2,1,14.46,100,1,12.86,100,1,14.48,700,1,12.73,100,1,14.52,200,2,12.71,100,1,14.55,100,1,12.50,700,1,14.56,800,2,12.46,100,1,14.60,700,1,12.43,700,1,14.63,100,1,12.42,700,1,14.88,100,1,ARL,331928009
2019,2025-07-17T16:07:00.070539222Z,2025-07-17T16:07:00.070373975Z,10,2,1108,A,A,0,14.140000000,100,130,165247,276614089,13.11,100,1,13.85,2,1,12.98,200,2,14.14,100,1,12.90,2,1,14.28,100,1,12.86,100,1,14.46,100,1,12.73,100,1,14.48,700,1,12.71,100,1,14.52,200,2,12.50,700,1,14.55,100,1,12.46,100,1,14.56,800,2,12.43,700,1,14.60,700,1,12.42,700,1,14.63,100,1,ARL,331929033
2020,2025-07-17T16:07:00.071359350Z,2025-07-17T16:07:00.071194493Z,10,2,1108,C,A,0,14.140000000,100,130,164857,276614094,13.11,100,1,13.85,2,1,12.98,200,2,14.28,100,1,12.90,2,1,14.46,100,1,12.86,100,1,14.48,700,1,12.73,100,1,14.52,200,2,12.71,100,1,14.55,100,1,12.50,700,1,14.56,800,2,12.46,100,1,14.60,700,1,12.43,700,1,14.63,100,1,12.42,700,1,14.88,100,1,ARL,331929033
2021,2025-07-17T16:07:00.071405105Z,2025-07-17T16:07:00.071239867Z,10,2,1108,A,A,0,14.260000000,100,130,165238,276614095,13.11,100,1,13.85,2,1,12.98,200,2,14.26,100,1,12.90,2,1,14.28,100,1,12.86,100,1,14.46,100,1,12.73,100,1,14.48,700,1,12.71,100,1,14.52,200,2,12.50,700,1,14.55,100,1,12.46,100,1,14.56,800,2,12.43,700,1,14.60,700,1,12.42,700,1,14.63,100,1,ARL,331929041
2022,2025-07-17T16:07:00.074580946Z,2025-07-17T16:07:00.074415631Z,10,2,1108,C,A,0,14.880000000,100,0,165315,276614119,13.11,100,1,13.85,2,1,12.98,200,2,14.26,100,1,12.90,2,1,14.28,100,1,12.86,100,1,14.46,100,1,12.73,100,1,14.48,700,1,12.71,100,1,14.52,200,2,12.50,700,1,14.55,100,1,12.46,100,1,14.56,800,2,12.43,700,1,14.60,700,1,12.42,700,1,14.63,100,1,ARL,331927017
2023,2025-07-17T16:07:00.074580946Z,2025-07-17T16:07:00.074415631Z,10,2,1108,A,A,0,15.060000000,100,130,165315,276614119,13.11,100,1,13.85,2,1,12.98,200,2,14.26,100,1,12.90,2,1,14.28,100,1,12.86,100,1,14.46,100,1,12.73,100,1,14.48,700,1,12.71,100,1,14.52,200,2,12.50,700,1,14.55,100,1,12.46,100,1,14.56,800,2,12.43,700,1,14.60,700,1,12.42,700,1,14.63,100,1,ARL,331929065
2024,2025-07-17T16:07:00.085131263Z,2025-07-17T16:07:00.084965637Z,10,2,1108,C,A,0,15.070000000,100,0,165626,276614295,13.11,100,1,13.85,2,1,12.98,200,2,14.26,100,1,12.90,2,1,14.28,100,1,12.86,100,1,14.46,100,1,12.73,100,1,14.48,700,1,12.71,100,1,14.52,200,2,12.50,700,1,14.55,100,1,12.46,100,1,14.56,800,2,12.43,700,1,14.60,700,1,12.42,700,1,14.63,100,1,ARL,326837501
2025,2025-07-17T16:07:00.085131263Z,2025-07-17T16:07:00.084965637Z,10,2,1108,A,A,0,15.380000000,100,130,165626,276614295,13.11,100,1,13.85,2,1,12.98,200,2,14.26,100,1,12.90,2,1,14.28,100,1,12.86,100,1,14.46,100,1,12.73,100,1,14.48,700,1,12.71,100,1,14.52,200,2,12.50,700,1,14.55,100,1,12.46,100,1,14.56,800,2,12.43,700,1,14.60,700,1,12.42,700,1,14.63,100,1,ARL,331929445
2026,2025-07-17T16:07:00.090359757Z,2025-07-17T16:07:00.090194106Z,10,2,1108,C,A,0,14.550000000,100,0,165651,276614378,13.11,100,1,13.85,2,1,12.98,200,2,14.26,100,1,12.90,2,1,14.28,100,1,12.86,100,1,14.46,100,1,12.73,100,1,14.48,700,1,12.71,100,1,14.52,200,2,12.50,700,1,14.56,800,2,12.46,100,1,14.60,700,1,12.43,700,1,14.63,100,1,12.42,700,1,14.96,100,1,ARL,331051173
2027,2025-07-17T16:07:00.090359757Z,2025-07-17T16:07:00.090194106Z,10,2,1108,A,A,0,14.960000000,100,130,165651,276614378,13.11,100,1,13.85,2,1,12.98,200,2,14.26,100,1,12.90,2,1,14.28,100,1,12.86,100,1,14.46,100,1,12.73,100,1,14.48,700,1,12.71,100,1,14.52,200,2,12.50,700,1,14.56,800,2,12.46,100,1,14.60,700,1,12.43,700,1,14.63,100,1,12.42,700,1,14.96,200,2,ARL,331929633
2028,2025-07-17T16:07:00.102092147Z,2025-07-17T16:07:00.101927028Z,10,2,1108,A,A,0,14.680000000,700,130,165119,276614699,13.11,100,1,13.85,2,1,12.98,200,2,14.26,100,1,12.90,2,1,14.28,100,1,12.86,100,1,14.46,100,1,12.73,100,1,14.48,700,1,12.71,100,1,14.52,200,2,12.50,700,1,14.56,800,2,12.46,100,1,14.60,700,1,12.43,700,1,14.63,100,1,12.42,700,1,14.68,700,1,ARL,331929977
2029,2025-07-17T16:07:00.287582448Z,2025-07-17T16:07:00.287416733Z,10,2,1108,C,A,0,17.290000000,100,0,165715,276617288,13.11,100,1,13.85,2,1,12.98,200,2,14.26,100,1,12.90,2,1,14.28,100,1,12.86,100,1,14.46,100,1,12.73,100,1,14.48,700,1,12.71,100,1,14.52,200,2,12.50,700,1,14.56,800,2,12.46,100,1,14.60,700,1,12.43,700,1,14.63,100,1,12.42,700,1,14.68,700,1,ARL,330789509
2030,2025-07-17T16:07:00.287582448Z,2025-07-17T16:07:00.287416733Z,10,2,1108,A,A,0,17.760000000,100,130,165715,276617288,13.11,100,1,13.85,2,1,12.98,200,2,14.26,100,1,12.90,2,1,14.28,100,1,12.86,100,1,14.46,100,1,12.73,100,1,14.48,700,1,12.71,100,1,14.52,200,2,12.50,700,1,14.56,800,2,12.46,100,1,14.60,700,1,12.43,700,1,14.63,100,1,12.42,700,1,14.68,700,1,ARL,331934277
2031,2025-07-17T16:07:00.293620434Z,2025-07-17T16:07:00.293454856Z,10,2,1108,C,A,0,15.630000000,100,0,165578,276617317,13.11,100,1,13.85,2,1,12.98,200,2,14.26,100,1,12.90,2,1,14.28,100,1,12.86,100,1,14.46,100,1,12.73,100,1,14.48,700,1,12.71,100,1,14.52,200,2,12.50,700,1,14.56,800,2,12.46,100,1,14.60,700,1,12.43,700,1,14.63,100,1,12.42,700,1,14.68,700,1,ARL,331051145
2032,2025-07-17T16:07:00.293620434Z,2025-07-17T16:07:00.293454856Z,10,2,1108,A,A,0,16.080000000,100,130,165578,276617317,13.11,100,1,13.85,2,1,12.98,200,2,14.26,100,1,12.90,2,1,14.28,100,1,12.86,100,1,14.46,100,1,12.73,100,1,14.48,700,1,12.71,100,1,14.52,200,2,12.50,700,1,14.56,800,2,12.46,100,1,14.60,700,1,12.43,700,1,14.63,100,1,12.42,700,1,14.68,700,1,ARL,331934377
2033,2025-07-17T16:07:00.494657495Z,2025-07-17T16:07:00.494492099Z,10,2,1108,A,A,0,13.860000000,100,130,165396,276622423,13.11,100,1,13.85,2,1,12.98,200,2,13.86,100,1,12.90,2,1,14.26,100,1,12.86,100,1,14.28,100,1,12.73,100,1,14.46,100,1,12.71,100,1,14.48,700,1,12.50,700,1,14.52,200,2,12.46,100,1,14.56,800,2,12.43,700,1,14.60,700,1,12.42,700,1,14.63,100,1,ARL,331942821
2034,2025-07-17T16:07:00.495318245Z,2025-07-17T16:07:00.495152219Z,10,2,1108,C,B,0,12.360000000,100,0,166026,276622452,13.11,100,1,13.85,2,1,12.98,200,2,13.86,100,1,12.90,2,1,14.26,100,1,12.86,100,1,14.28,100,1,12.73,100,1,14.46,100,1,12.71,100,1,14.48,700,1,12.50,700,1,14.52,200,2,12.46,100,1,14.56,800,2,12.43,700,1,14.60,700,1,12.42,700,1,14.63,100,1,ARL,288723817
2035,2025-07-17T16:07:00.495318245Z,2025-07-17T16:07:00.495152219Z,10,2,1108,A,B,0,12.490000000,100,130,166026,276622452,13.11,100,1,13.85,2,1,12.98,200,2,13.86,100,1,12.90,2,1,14.26,100,1,12.86,100,1,14.28,100,1,12.73,100,1,14.46,100,1,12.71,100,1,14.48,700,1,12.50,700,1,14.52,200,2,12.49,100,1,14.56,800,2,12.46,100,1,14.60,700,1,12.43,700,1,14.63,100,1,ARL,331942901
2036,2025-07-17T16:07:00.495398644Z,2025-07-17T16:07:00.495233001Z,10,2,1108,C,A,0,15.060000000,100,0,165643,276622455,13.11,100,1,13.85,2,1,12.98,200,2,13.86,100,1,12.90,2,1,14.26,100,1,12.86,100,1,14.28,100,1,12.73,100,1,14.46,100,1,12.71,100,1,14.48,700,1,12.50,700,1,14.52,200,2,12.49,100,1,14.56,800,2,12.46,100,1,14.60,700,1,12.43,700,1,14.63,100,1,ARL,331929065
2037,2025-07-17T16:07:00.495398644Z,2025-07-17T16:07:00.495233001Z,10,2,1108,A,A,0,14.930000000,100,130,165643,276622455,13.11,100,1,13.85,2,1,12.98,200,2,13.86,100,1,12.90,2,1,14.26,100,1,12.86,100,1,14.28,100,1,12.73,100,1,14.46,100,1,12.71,100,1,14.48,700,1,12.50,700,1,14.52,200,2,12.49,100,1,14.56,800,2,12.46,100,1,14.60,700,1,12.43,700,1,14.63,100,1,ARL,331942913
2038,2025-07-17T16:07:00.495989598Z,2025-07-17T16:07:00.495823953Z,10,2,1108,C,B,0,12.360000000,100,0,165645,276622469,13.11,100,1,13.85,2,1,12.98,200,2,13.86,100,1,12.90,2,1,14.26,100,1,12.86,100,1,14.28,100,1,12.73,100,1,14.46,100,1,12.71,100,1,14.48,700,1,12.50,700,1,14.52,200,2,12.49,100,1,14.56,800,2,12.46,100,1,14.60,700,1,12.43,700,1,14.63,100,1,ARL,288723813
2039,2025-07-17T16:07:00.495989598Z,2025-07-17T16:07:00.495823953Z,10,2,1108,A,B,0,12.490000000,100,130,165645,276622469,13.11,100,1,13.85,2,1,12.98,200,2,13.86,100,1,12.90,2,1,14.26,100,1,12.86,100,1,14.28,100,1,12.73,100,1,14.46,100,1,12.71,100,1,14.48,700,1,12.50,700,1,14.52,200,2,12.49,200,2,14.56,800,2,12.46,100,1,14.60,700,1,12.43,700,1,14.63,100,1,ARL,331942945
2040,2025-07-17T16:07:00.496483460Z,2025-07-17T16:07:00.496317847Z,10,2,1108,C,A,0,17.760000000,100,0,165613,276622478,13.11,100,1,13.85,2,1,12.98,200,2,13.86,100,1,12.90,2,1,14.26,100,1,12.86,100,1,14.28,100,1,12.73,100,1,14.46,100,1,12.71,100,1,14.48,700,1,12.50,700,1,14.52,200,2,12.49,200,2,14.56,800,2,12.46,100,1,14.60,700,1,12.43,700,1,14.63,100,1,ARL,331934277
2041,2025-07-17T16:07:00.496483460Z,2025-07-17T16:07:00.496317847Z,10,2,1108,A,A,0,17.610000000,100,130,165613,276622478,13.11,100,1,13.85,2,1,12.98,200,2,13.86,100,1,12.90,2,1,14.26,100,1,12.86,100,1,14.28,100,1,12.73,100,1,14.46,100,1,12.71,100,1,14.48,700,1,12.50,700,1,14.52,200,2,12.49,200,2,14.56,800,2,12.46,100,1,14.60,700,1,12.43,700,1,14.63,100,1,ARL,331942981
2042,2025-07-17T16:07:00.499666149Z,2025-07-17T16:07:00.499501052Z,10,2,1108,C,A,0,14.260000000,100,130,165097,276622569,13.11,100,1,13.85,2,1,12.98,200,2,13.86,100,1,12.90,2,1,14.28,100,1,12.86,100,1,14.46,100,1,12.73,100,1,14.48,700,1,12.71,100,1,14.52,200,2,12.50,700,1,14.56,800,2,12.49,200,2,14.60,700,1,12.46,100,1,14.63,100,1,12.43,700,1,14.68,700,1,ARL,331929041
2043,2025-07-17T16:07:00.499714918Z,2025-07-17T16:07:00.499549738Z,10,2,1108,A,A,0,14.140000000,100,130,165180,276622571,13.11,100,1,13.85,2,1,12.98,200,2,13.86,100,1,12.90,2,1,14.14,100,1,12.86,100,1,14.28,100,1,12.73,100,1,14.46,100,1,12.71,100,1,14.48,700,1,12.50,700,1,14.52,200,2,12.49,200,2,14.56,800,2,12.46,100,1,14.60,700,1,12.43,700,1,14.63,100,1,ARL,331943133
2044,2025-07-17T16:07:22.814941809Z,2025-07-17T16:07:22.814776694Z,10,2,1108,A,A,0,13.690000000,15,130,165115,276946179,13.11,100,1,13.69,15,1,12.98,200,2,13.85,2,1,12.90,2,1,13.86,100,1,12.86,100,1,14.14,100,1,12.73,100,1,14.28,100,1,12.71,100,1,14.46,100,1,12.50,700,1,14.48,700,1,12.49,200,2,14.52,200,2,12.46,100,1,14.56,800,2,12.43,700,1,14.60,700,1,ARL,332385317
2045,2025-07-17T16:07:22.815057507Z,2025-07-17T16:07:22.814891345Z,10,2,1108,C,A,0,13.860000000,100,0,166162,276946183,13.11,100,1,13.69,15,1,12.98,200,2,13.85,2,1,12.90,2,1,14.14,100,1,12.86,100,1,14.28,100,1,12.73,100,1,14.46,100,1,12.71,100,1,14.48,700,1,12.50,700,1,14.52,200,2,12.49,200,2,14.56,800,2,12.46,100,1,14.60,700,1,12.43,700,1,14.63,100,1,ARL,331942821
2046,2025-07-17T16:07:22.815057507Z,2025-07-17T16:07:22.814891345Z,10,2,1108,A,A,0,13.700000000,100,130,166162,276946183,13.11,100,1,13.69,15,1,12.98,200,2,13.70,100,1,12.90,2,1,13.85,2,1,12.86,100,1,14.14,100,1,12.73,100,1,14.28,100,1,12.71,100,1,14.46,100,1,12.50,700,1,14.48,700,1,12.49,200,2,14.52,200,2,12.46,100,1,14.56,800,2,12.43,700,1,14.60,700,1,ARL,332385325
2047,2025-07-17T16:07:22.815790890Z,2025-07-17T16:07:22.815625345Z,10,2,1108,C,A,0,14.930000000,100,0,165545,276946264,13.11,100,1,13.69,15,1,12.98,200,2,13.70,100,1,12.90,2,1,13.85,2,1,12.86,100,1,14.14,100,1,12.73,100,1,14.28,100,1,12.71,100,1,14.46,100,1,12.50,700,1,14.48,700,1,12.49,200,2,14.52,200,2,12.46,100,1,14.56,800,2,12.43,700,1,14.60,700,1,ARL,331942913
2048,2025-07-17T16:07:22.815790890Z,2025-07-17T16:07:22.815625345Z,10,2,1108,A,A,0,14.760000000,100,130,165545,276946264,13.11,100,1,13.69,15,1,12.98,200,2,13.70,100,1,12.90,2,1,13.85,2,1,12.86,100,1,14.14,100,1,12.73,100,1,14.28,100,1,12.71,100,1,14.46,100,1,12.50,700,1,14.48,700,1,12.49,200,2,14.52,200,2,12.46,100,1,14.56,800,2,12.43,700,1,14.60,700,1,ARL,332385501
2049,2025-07-17T16:07:22.817507809Z,2025-07-17T16:07:22.817341789Z,10,2,1108,C,A,0,14.960000000,100,0,166020,276946309,13.11,100,1,13.69,15,1,12.98,200,2,13.70,100,1,12.90,2,1,13.85,2,1,12.86,100,1,14.14,100,1,12.73,100,1,14.28,100,1,12.71,100,1,14.46,100,1,12.50,700,1,14.48,700,1,12.49,200,2,14.52,200,2,12.46,100,1,14.56,800,2,12.43,700,1,14.60,700,1,ARL,331929633
2050,2025-07-17T16:07:22.817507809Z,2025-07-17T16:07:22.817341789Z,10,2,1108,A,A,0,14.660000000,100,130,166020,276946309,13.11,100,1,13.69,15,1,12.98,200,2,13.70,100,1,12.90,2,1,13.85,2,1,12.86,100,1,14.14,100,1,12.73,100,1,14.28,100,1,12.71,100,1,14.46,100,1,12.50,700,1,14.48,700,1,12.49,200,2,14.52,200,2,12.46,100,1,14.56,800,2,12.43,700,1,14.60,700,1,ARL,332385565
2051,2025-07-17T16:07:22.817624699Z,2025-07-17T16:07:22.817459170Z,10,2,1108,C,A,0,15.380000000,100,0,165529,276946313,13.11,100,1,13.69,15,1,12.98,200,2,13.70,100,1,12.90,2,1,13.85,2,1,12.86,100,1,14.14,100,1,12.73,100,1,14.28,100,1,12.71,100,1,14.46,100,1,12.50,700,1,14.48,700,1,12.49,200,2,14.52,200,2,12.46,100,1,14.56,800,2,12.43,700,1,14.60,700,1,ARL,331929445
2052,2025-07-17T16:07:22.817624699Z,2025-07-17T16:07:22.817459170Z,10,2,1108,A,A,0,15.070000000,100,130,165529,276946313,13.11,100,1,13.69,15,1,12.98,200,2,13.70,100,1,12.90,2,1,13.85,2,1,12.86,100,1,14.14,100,1,12.73,100,1,14.28,100,1,12.71,100,1,14.46,100,1,12.50,700,1,14.48,700,1,12.49,200,2,14.52,200,2,12.46,100,1,14.56,800,2,12.43,700,1,14.60,700,1,ARL,332385569
2053,2025-07-17T16:07:22.818565766Z,2025-07-17T16:07:22.818400003Z,10,2,1108,C,A,0,16.080000000,100,0,165763,276946327,13.11,100,1,13.69,15,1,12.98,200,2,13.70,100,1,12.90,2,1,13.85,2,1,12.86,100,1,14.14,100,1,12.73,100,1,14.28,100,1,12.71,100,1,14.46,100,1,12.50,700,1,14.48,700,1,12.49,200,2,14.52,200,2,12.46,100,1,14.56,800,2,12.43,700,1,14.60,700,1,ARL,331934377
2054,2025-07-17T16:07:22.818565766Z,2025-07-17T16:07:22.818400003Z,10,2,1108,A,A,0,15.760000000,100,130,165763,276946327,13.11,100,1,13.69,15,1,12.98,200,2,13.70,100,1,12.90,2,1,13.85,2,1,12.86,100,1,14.14,100,1,12.73,100,1,14.28,100,1,12.71,100,1,14.46,100,1,12.50,700,1,14.48,700,1,12.49,200,2,14.52,200,2,12.46,100,1,14.56,800,2,12.43,700,1,14.60,700,1,ARL,332385585
2055,2025-07-17T16:07:22.819710983Z,2025-07-17T16:07:22.819545360Z,10,2,1108,C,A,0,17.610000000,100,0,165623,276946336,13.11,100,1,13.69,15,1,12.98,200,2,13.70,100,1,12.90,2,1,13.85,2,1,12.86,100,1,14.14,100,1,12.73,100,1,14.28,100,1,12.71,100,1,14.46,100,1,12.50,700,1,14.48,700,1,12.49,200,2,14.52,200,2,12.46,100,1,14.56,800,2,12.43,700,1,14.60,700,1,ARL,331942981
2056,2025-07-17T16:07:22.819710983Z,2025-07-17T16:07:22.819545360Z,10,2,1108,A,A,0,17.400000000,100,130,165623,276946336,13.11,100,1,13.69,15,1,12.98,200,2,13.70,100,1,12.90,2,1,13.85,2,1,12.86,100,1,14.14,100,1,12.73,100,1,14.28,100,1,12.71,100,1,14.46,100,1,12.50,700,1,14.48,700,1,12.49,200,2,14.52,200,2,12.46,100,1,14.56,800,2,12.43,700,1,14.60,700,1,ARL,332385593
2057,2025-07-17T16:07:22.819772408Z,2025-07-17T16:07:22.819606945Z,10,2,1108,C,A,0,14.630000000,100,0,165463,276946337,13.11,100,1,13.69,15,1,12.98,200,2,13.70,100,1,12.90,2,1,13.85,2,1,12.86,100,1,14.14,100,1,12.73,100,1,14.28,100,1,12.71,100,1,14.46,100,1,12.50,700,1,14.48,700,1,12.49,200,2,14.52,200,2,12.46,100,1,14.56,800,2,12.43,700,1,14.60,700,1,ARL,331927477
2058,2025-07-17T16:07:22.819772408Z,2025-07-17T16:07:22.819606945Z,10,2,1108,A,A,0,14.490000000,100,130,165463,276946337,13.11,100,1,13.69,15,1,12.98,200,2,13.70,100,1,12.90,2,1,13.85,2,1,12.86,100,1,14.14,100,1,12.73,100,1,14.28,100,1,12.71,100,1,14.46,100,1,12.50,700,1,14.48,700,1,12.49,200,2,14.49,100,1,12.46,100,1,14.52,200,2,12.43,700,1,14.56,800,2,ARL,332385597
2059,2025-07-17T16:07:22.821165451Z,2025-07-17T16:07:22.821000003Z,10,2,1108,C,A,0,14.140000000,100,130,165448,276946343,13.11,100,1,13.69,15,1,12.98,200,2,13.70,100,1,12.90,2,1,13.85,2,1,12.86,100,1,14.28,100,1,12.73,100,1,14.46,100,1,12.71,100,1,14.48,700,1,12.50,700,1,14.49,100,1,12.49,200,2,14.52,200,2,12.46,100,1,14.56,800,2,12.43,700,1,14.60,700,1,ARL,331943133
2060,2025-07-17T16:07:22.821218207Z,2025-07-17T16:07:22.821052982Z,10,2,1108,A,A,0,13.970000000,100,130,165225,276946344,13.11,100,1,13.69,15,1,12.98,200,2,13.70,100,1,12.90,2,1,13.85,2,1,12.86,100,1,13.97,100,1,12.73,100,1,14.28,100,1,12.71,100,1,14.46,100,1,12.50,700,1,14.48,700,1,12.49,200,2,14.49,100,1,12.46,100,1,14.52,200,2,12.43,700,1,14.56,800,2,ARL,332385613
2061,2025-07-17T16:07:22.832119220Z,2025-07-17T16:07:22.831949887Z,10,2,1108,C,A,0,14.960000000,100,0,169333,276946801,13.11,100,1,13.69,15,1,12.98,200,2,13.70,100,1,12.90,2,1,13.85,2,1,12.86,100,1,13.97,100,1,12.73,100,1,14.28,100,1,12.71,100,1,14.46,100,1,12.50,700,1,14.48,700,1,12.49,200,2,14.49,100,1,12.46,100,1,14.52,200,2,12.43,700,1,14.56,800,2,ARL,331928129
2062,2025-07-17T16:07:22.832119220Z,2025-07-17T16:07:22.831949887Z,10,2,1108,A,A,0,14.660000000,100,128,169333,276946801,13.11,100,1,13.69,15,1,12.98,200,2,13.70,100,1,12.90,2,1,13.85,2,1,12.86,100,1,13.97,100,1,12.73,100,1,14.28,100,1,12.71,100,1,14.46,100,1,12.50,700,1,14.48,700,1,12.49,200,2,14.49,100,1,12.46,100,1,14.52,200,2,12.43,700,1,14.56,800,2,ARL,332386121
2063,2025-07-17T16:07:28.273823608Z,2025-07-17T16:07:28.273658191Z,10,2,1108,C,A,0,13.690000000,15,130,165417,277012951,13.11,100,1,13.70,100,1,12.98,200,2,13.85,2,1,12.90,2,1,13.97,100,1,12.86,100,1,14.28,100,1,12.73,100,1,14.46,100,1,12.71,100,1,14.48,700,1,12.50,700,1,14.49,100,1,12.49,200,2,14.52,200,2,12.46,100,1,14.56,800,2,12.43,700,1,14.60,700,1,ARL,332385317
2064,2025-07-17T16:07:28.700981149Z,2025-07-17T16:07:28.700815737Z,10,2,1108,C,A,0,13.700000000,100,130,165412,277019711,13.11,100,1,13.85,2,1,12.98,200,2,13.97,100,1,12.90,2,1,14.28,100,1,12.86,100,1,14.46,100,1,12.73,100,1,14.48,700,1,12.71,100,1,14.49,100,1,12.50,700,1,14.52,200,2,12.49,200,2,14.56,800,2,12.46,100,1,14.60,700,1,12.43,700,1,14.66,200,2,ARL,332385325
2065,2025-07-17T16:07:28.701396669Z,2025-07-17T16:07:28.701230409Z,10,2,1108,C,B,0,12.900000000,2,0,166260,277019718,13.11,100,1,13.85,2,1,12.98,200,2,13.97,100,1,12.86,100,1,14.28,100,1,12.73,100,1,14.46,100,1,12.71,100,1,14.48,700,1,12.50,700,1,14.49,100,1,12.49,200,2,14.52,200,2,12.46,100,1,14.56,800,2,12.43,700,1,14.60,700,1,12.42,700,1,14.66,200,2,ARL,331694297
2066,2025-07-17T16:07:28.701396669Z,2025-07-17T16:07:28.701230409Z,10,2,1108,A,B,0,13.010000000,2,130,166260,277019718,13.11,100,1,13.85,2,1,13.01,2,1,13.97,100,1,12.98,200,2,14.28,100,1,12.86,100,1,14.46,100,1,12.73,100,1,14.48,700,1,12.71,100,1,14.49,100,1,12.50,700,1,14.52,200,2,12.49,200,2,14.56,800,2,12.46,100,1,14.60,700,1,12.43,700,1,14.66,200,2,ARL,332494213
2067,2025-07-17T16:07:28.701713232Z,2025-07-17T16:07:28.701547540Z,10,2,1108,C,A,0,14.760000000,100,0,165692,277019720,13.11,100,1,13.85,2,1,13.01,2,1,13.97,100,1,12.98,200,2,14.28,100,1,12.86,100,1,14.46,100,1,12.73,100,1,14.48,700,1,12.71,100,1,14.49,100,1,12.50,700,1,14.52,200,2,12.49,200,2,14.56,800,2,12.46,100,1,14.60,700,1,12.43,700,1,14.66,200,2,ARL,332385501
2068,2025-07-17T16:07:28.701713232Z,2025-07-17T16:07:28.701547540Z,10,2,1108,A,A,0,14.820000000,100,130,165692,277019720,13.11,100,1,13.85,2,1,13.01,2,1,13.97,100,1,12.98,200,2,14.28,100,1,12.86,100,1,14.46,100,1,12.73,100,1,14.48,700,1,12.71,100,1,14.49,100,1,12.50,700,1,14.52,200,2,12.49,200,2,14.56,800,2,12.46,100,1,14.60,700,1,12.43,700,1,14.66,200,2,ARL,332494229
2069,2025-07-17T16:07:28.702166297Z,2025-07-17T16:07:28.702000772Z,10,2,1108,C,A,0,15.760000000,100,0,165525,277019722,13.11,100,1,13.85,2,1,13.01,2,1,13.97,100,1,12.98,200,2,14.28,100,1,12.86,100,1,14.46,100,1,12.73,100,1,14.48,700,1,12.71,100,1,14.49,100,1,12.50,700,1,14.52,200,2,12.49,200,2,14.56,800,2,12.46,100,1,14.60,700,1,12.43,700,1,14.66,200,2,ARL,332385585
2070,2025-07-17T16:07:28.702166297Z,2025-07-17T16:07:28.702000772Z,10,2,1108,A,A,0,16.010000000,100,130,165525,277019722,13.11,100,1,13.85,2,1,13.01,2,1,13.97,100,1,12.98,200,2,14.28,100,1,12.86,100,1,14.46,100,1,12.73,100,1,14.48,700,1,12.71,100,1,14.49,100,1,12.50,700,1,14.52,200,2,12.49,200,2,14.56,800,2,12.46,100,1,14.60,700,1,12.43,700,1,14.66,200,2,ARL,332494245
2071,2025-07-17T16:07:28.702642020Z,2025-07-17T16:07:28.702476699Z,10,2,1108,C,A,0,14.660000000,100,0,165321,277019729,13.11,100,1,13.85,2,1,13.01,2,1,13.97,100,1,12.98,200,2,14.28,100,1,12.86,100,1,14.46,100,1,12.73,100,1,14.48,700,1,12.71,100,1,14.49,100,1,12.50,700,1,14.52,200,2,12.49,200,2,14.56,800,2,12.46,100,1,14.60,700,1,12.43,700,1,14.66,100,1,ARL,332386121
2072,2025-07-17T16:07:28.702642020Z,2025-07-17T16:07:28.702476699Z,10,2,1108,A,A,0,14.950000000,100,130,165321,277019729,13.11,100,1,13.85,2,1,13.01,2,1,13.97,100,1,12.98,200,2,14.28,100,1,12.86,100,1,14.46,100,1,12.73,100,1,14.48,700,1,12.71,100,1,14.49,100,1,12.50,700,1,14.52,200,2,12.49,200,2,14.56,800,2,12.46,100,1,14.60,700,1,12.43,700,1,14.66,100,1,ARL,332494281
2073,2025-07-17T16:07:28.703523092Z,2025-07-17T16:07:28.703357714Z,10,2,1108,C,A,0,14.660000000,100,0,165378,277019733,13.11,100,1,13.85,2,1,13.01,2,1,13.97,100,1,12.98,200,2,14.28,100,1,12.86,100,1,14.46,100,1,12.73,100,1,14.48,700,1,12.71,100,1,14.49,100,1,12.50,700,1,14.52,200,2,12.49,200,2,14.56,800,2,12.46,100,1,14.60,700,1,12.43,700,1,14.68,700,1,ARL,332385565
2074,2025-07-17T16:07:28.703523092Z,2025-07-17T16:07:28.703357714Z,10,2,1108,A,A,0,14.950000000,100,130,165378,277019733,13.11,100,1,13.85,2,1,13.01,2,1,13.97,100,1,12.98,200,2,14.28,100,1,12.86,100,1,14.46,100,1,12.73,100,1,14.48,700,1,12.71,100,1,14.49,100,1,12.50,700,1,14.52,200,2,12.49,200,2,14.56,800,2,12.46,100,1,14.60,700,1,12.43,700,1,14.68,700,1,ARL,332494285
2075,2025-07-17T16:07:28.703920336Z,2025-07-17T16:07:28.703754662Z,10,2,1108,C,A,0,15.070000000,100,0,165674,277019735,13.11,100,1,13.85,2,1,13.01,2,1,13.97,100,1,12.98,200,2,14.28,100,1,12.86,100,1,14.46,100,1,12.73,100,1,14.48,700,1,12.71,100,1,14.49,100,1,12.50,700,1,14.52,200,2,12.49,200,2,14.56,800,2,12.46,100,1,14.60,700,1,12.43,700,1,14.68,700,1,ARL,332385569
2076,2025-07-17T16:07:28.703920336Z,2025-07-17T16:07:28.703754662Z,10,2,1108,A,A,0,15.370000000,100,130,165674,277019735,13.11,100,1,13.85,2,1,13.01,2,1,13.97,100,1,12.98,200,2,14.28,100,1,12.86,100,1,14.46,100,1,12.73,100,1,14.48,700,1,12.71,100,1,14.49,100,1,12.50,700,1,14.52,200,2,12.49,200,2,14.56,800,2,12.46,100,1,14.60,700,1,12.43,700,1,14.68,700,1,ARL,332494289
2077,2025-07-17T16:07:28.704198103Z,2025-07-17T16:07:28.704032725Z,10,2,1108,C,A,0,17.400000000,100,0,165378,277019738,13.11,100,1,13.85,2,1,13.01,2,1,13.97,100,1,12.98,200,2,14.28,100,1,12.86,100,1,14.46,100,1,12.73,100,1,14.48,700,1,12.71,100,1,14.49,100,1,12.50,700,1,14.52,200,2,12.49,200,2,14.56,800,2,12.46,100,1,14.60,700,1,12.43,700,1,14.68,700,1,ARL,332385593
2078,2025-07-17T16:07:28.704198103Z,2025-07-17T16:07:28.704032725Z,10,2,1108,A,A,0,17.750000000,100,130,165378,277019738,13.11,100,1,13.85,2,1,13.01,2,1,13.97,100,1,12.98,200,2,14.28,100,1,12.86,100,1,14.46,100,1,12.73,100,1,14.48,700,1,12.71,100,1,14.49,100,1,12.50,700,1,14.52,200,2,12.49,200,2,14.56,800,2,12.46,100,1,14.60,700,1,12.43,700,1,14.68,700,1,ARL,332494297
2079,2025-07-17T16:07:28.724201840Z,2025-07-17T16:07:28.724036175Z,10,2,1108,C,A,0,13.970000000,100,130,165665,277019926,13.11,100,1,13.85,2,1,13.01,2,1,14.28,100,1,12.98,200,2,14.46,100,1,12.86,100,1,14.48,700,1,12.73,100,1,14.49,100,1,12.71,100,1,14.52,200,2,12.50,700,1,14.56,800,2,12.49,200,2,14.60,700,1,12.46,100,1,14.68,700,1,12.43,700,1,14.82,100,1,ARL,332385613
2080,2025-07-17T16:07:28.724250835Z,2025-07-17T16:07:28.724085453Z,10,2,1108,A,A,0,14.200000000,100,130,165382,277019929,13.11,100,1,13.85,2,1,13.01,2,1,14.20,100,1,12.98,200,2,14.28,100,1,12.86,100,1,14.46,100,1,12.73,100,1,14.48,700,1,12.71,100,1,14.49,100,1,12.50,700,1,14.52,200,2,12.49,200,2,14.56,800,2,12.46,100,1,14.60,700,1,12.43,700,1,14.68,700,1,ARL,332494893
2081,2025-07-17T16:07:28.751828120Z,2025-07-17T16:07:28.751662660Z,10,2,1108,C,A,0,14.820000000,100,0,165460,277020284,13.11,100,1,13.85,2,1,13.01,2,1,14.20,100,1,12.98,200,2,14.28,100,1,12.86,100,1,14.46,100,1,12.73,100,1,14.48,700,1,12.71,100,1,14.49,100,1,12.50,700,1,14.52,200,2,12.49,200,2,14.56,800,2,12.46,100,1,14.60,700,1,12.43,700,1,14.68,700,1,ARL,332494229
2082,2025-07-17T16:07:28.751828120Z,2025-07-17T16:07:28.751662660Z,10,2,1108,A,A,0,15.050000000,100,130,165460,277020284,13.11,100,1,13.85,2,1,13.01,2,1,14.20,100,1,12.98,200,2,14.28,100,1,12.86,100,1,14.46,100,1,12.73,100,1,14.48,700,1,12.71,100,1,14.49,100,1,12.50,700,1,14.52,200,2,12.49,200,2,14.56,800,2,12.46,100,1,14.60,700,1,12.43,700,1,14.68,700,1,ARL,332495781
2083,2025-07-17T16:07:28.831160987Z,2025-07-17T16:07:28.830995364Z,10,2,1108,C,A,0,14.490000000,100,130,165623,277021007,13.11,100,1,13.85,2,1,13.01,2,1,14.20,100,1,12.98,200,2,14.28,100,1,12.86,100,1,14.46,100,1,12.73,100,1,14.48,700,1,12.71,100,1,14.52,200,2,12.50,700,1,14.56,800,2,12.49,200,2,14.60,700,1,12.46,100,1,14.68,700,1,12.43,700,1,14.95,200,2,ARL,332385597
2084,2025-07-17T16:07:28.831291377Z,2025-07-17T16:07:28.831125667Z,10,2,1108,A,A,0,14.770000000,100,130,165710,277021012,13.11,100,1,13.85,2,1,13.01,2,1,14.20,100,1,12.98,200,2,14.28,100,1,12.86,100,1,14.46,100,1,12.73,100,1,14.48,700,1,12.71,100,1,14.52,200,2,12.50,700,1,14.56,800,2,12.49,200,2,14.60,700,1,12.46,100,1,14.68,700,1,12.43,700,1,14.77,100,1,ARL,332497653
2085,2025-07-17T16:07:29.214667270Z,2025-07-17T16:07:29.214500816Z,10,2,1108,A,A,0,13.860000000,100,128,166454,277029015,13.11,100,1,13.85,2,1,13.01,2,1,13.86,100,1,12.98,200,2,14.20,100,1,12.86,100,1,14.28,100,1,12.73,100,1,14.46,100,1,12.71,100,1,14.48,700,1,12.50,700,1,14.52,200,2,12.49,200,2,14.56,800,2,12.46,100,1,14.60,700,1,12.43,700,1,14.68,700,1,ARL,332508813
2086,2025-07-17T16:07:29.215458844Z,2025-07-17T16:07:29.215292291Z,10,2,1108,C,A,0,15.050000000,100,0,166553,277029273,13.11,100,1,13.85,2,1,13.01,2,1,13.86,100,1,12.98,200,2,14.20,100,1,12.86,100,1,14.28,100,1,12.73,100,1,14.46,100,1,12.71,100,1,14.48,700,1,12.50,700,1,14.52,200,2,12.49,200,2,14.56,800,2,12.46,100,1,14.60,700,1,12.43,700,1,14.68,700,1,ARL,332495781
2087,2025-07-17T16:07:29.215458844Z,2025-07-17T16:07:29.215292291Z,10,2,1108,A,A,0,14.930000000,100,128,166553,277029273,13.11,100,1,13.85,2,1,13.01,2,1,13.86,100,1,12.98,200,2,14.20,100,1,12.86,100,1,14.28,100,1,12.73,100,1,14.46,100,1,12.71,100,1,14.48,700,1,12.50,700,1,14.52,200,2,12.49,200,2,14.56,800,2,12.46,100,1,14.60,700,1,12.43,700,1,14.68,700,1,ARL,332508997
2088,2025-07-17T16:08:20.816252850Z,2025-07-17T16:08:20.816087447Z,10,2,1108,A,A,0,13.680000000,15,130,165403,277732167,13.11,100,1,13.68,15,1,13.01,2,1,13.85,2,1,12.98,200,2,13.86,100,1,12.86,100,1,14.20,100,1,12.73,100,1,14.28,100,1,12.71,100,1,14.46,100,1,12.50,700,1,14.48,700,1,12.49,200,2,14.52,200,2,12.46,100,1,14.56,800,2,12.43,700,1,14.60,700,1,ARL,333436357
2089,2025-07-17T16:08:20.816366205Z,2025-07-17T16:08:20.816200644Z,10,2,1108,C,A,0,13.860000000,100,0,165561,277732170,13.11,100,1,13.68,15,1,13.01,2,1,13.85,2,1,12.98,200,2,14.20,100,1,12.86,100,1,14.28,100,1,12.73,100,1,14.46,100,1,12.71,100,1,14.48,700,1,12.50,700,1,14.52,200,2,12.49,200,2,14.56,800,2,12.46,100,1,14.60,700,1,12.43,700,1,14.68,700,1,ARL,332508813
2090,2025-07-17T16:08:20.816366205Z,2025-07-17T16:08:20.816200644Z,10,2,1108,A,A,0,13.690000000,100,130,165561,277732170,13.11,100,1,13.68,15,1,13.01,2,1,13.69,100,1,12.98,200,2,13.85,2,1,12.86,100,1,14.20,100,1,12.73,100,1,14.28,100,1,12.71,100,1,14.46,100,1,12.50,700,1,14.48,700,1,12.49,200,2,14.52,200,2,12.46,100,1,14.56,800,2,12.43,700,1,14.60,700,1,ARL,333436361
2091,2025-07-17T16:08:20.817097587Z,2025-07-17T16:08:20.816932150Z,10,2,1108,C,A,0,14.930000000,100,0,165437,277732194,13.11,100,1,13.68,15,1,13.01,2,1,13.69,100,1,12.98,200,2,13.85,2,1,12.86,100,1,14.20,100,1,12.73,100,1,14.28,100,1,12.71,100,1,14.46,100,1,12.50,700,1,14.48,700,1,12.49,200,2,14.52,200,2,12.46,100,1,14.56,800,2,12.43,700,1,14.60,700,1,ARL,332508997
2092,2025-07-17T16:08:20.817097587Z,2025-07-17T16:08:20.816932150Z,10,2,1108,A,A,0,14.750000000,100,130,165437,277732194,13.11,100,1,13.68,15,1,13.01,2,1,13.69,100,1,12.98,200,2,13.85,2,1,12.86,100,1,14.20,100,1,12.73,100,1,14.28,100,1,12.71,100,1,14.46,100,1,12.50,700,1,14.48,700,1,12.49,200,2,14.52,200,2,12.46,100,1,14.56,800,2,12.43,700,1,14.60,700,1,ARL,333436397
2093,2025-07-17T16:08:20.818725102Z,2025-07-17T16:08:20.818559377Z,10,2,1108,C,A,0,15.370000000,100,0,165725,277732213,13.11,100,1,13.68,15,1,13.01,2,1,13.69,100,1,12.98,200,2,13.85,2,1,12.86,100,1,14.20,100,1,12.73,100,1,14.28,100,1,12.71,100,1,14.46,100,1,12.50,700,1,14.48,700,1,12.49,200,2,14.52,200,2,12.46,100,1,14.56,800,2,12.43,700,1,14.60,700,1,ARL,332494289
2094,2025-07-17T16:08:20.818725102Z,2025-07-17T16:08:20.818559377Z,10,2,1108,A,A,0,15.060000000,100,130,165725,277732213,13.11,100,1,13.68,15,1,13.01,2,1,13.69,100,1,12.98,200,2,13.85,2,1,12.86,100,1,14.20,100,1,12.73,100,1,14.28,100,1,12.71,100,1,14.46,100,1,12.50,700,1,14.48,700,1,12.49,200,2,14.52,200,2,12.46,100,1,14.56,800,2,12.43,700,1,14.60,700,1,ARL,333436421
2095,2025-07-17T16:08:20.819130820Z,2025-07-17T16:08:20.818965359Z,10,2,1108,C,A,0,14.950000000,100,0,165461,277732216,13.11,100,1,13.68,15,1,13.01,2,1,13.69,100,1,12.98,200,2,13.85,2,1,12.86,100,1,14.20,100,1,12.73,100,1,14.28,100,1,12.71,100,1,14.46,100,1,12.50,700,1,14.48,700,1,12.49,200,2,14.52,200,2,12.46,100,1,14.56,800,2,12.43,700,1,14.60,700,1,ARL,332494285
2096,2025-07-17T16:08:20.819130820Z,2025-07-17T16:08:20.818965359Z,10,2,1108,A,A,0,14.650000000,100,130,165461,277732216,13.11,100,1,13.68,15,1,13.01,2,1,13.69,100,1,12.98,200,2,13.85,2,1,12.86,100,1,14.20,100,1,12.73,100,1,14.28,100,1,12.71,100,1,14.46,100,1,12.50,700,1,14.48,700,1,12.49,200,2,14.52,200,2,12.46,100,1,14.56,800,2,12.43,700,1,14.60,700,1,ARL,333436425
2097,2025-07-17T16:08:20.819767091Z,2025-07-17T16:08:20.819601669Z,10,2,1108,C,A,0,17.750000000,100,0,165422,277732221,13.11,100,1,13.68,15,1,13.01,2,1,13.69,100,1,12.98,200,2,13.85,2,1,12.86,100,1,14.20,100,1,12.73,100,1,14.28,100,1,12.71,100,1,14.46,100,1,12.50,700,1,14.48,700,1,12.49,200,2,14.52,200,2,12.46,100,1,14.56,800,2,12.43,700,1,14.60,700,1,ARL,332494297
2098,2025-07-17T16:08:20.819767091Z,2025-07-17T16:08:20.819601669Z,10,2,1108,A,A,0,17.390000000,100,130,165422,277732221,13.11,100,1,13.68,15,1,13.01,2,1,13.69,100,1,12.98,200,2,13.85,2,1,12.86,100,1,14.20,100,1,12.73,100,1,14.28,100,1,12.71,100,1,14.46,100,1,12.50,700,1,14.48,700,1,12.49,200,2,14.52,200,2,12.46,100,1,14.56,800,2,12.43,700,1,14.60,700,1,ARL,333436441
2099,2025-07-17T16:08:20.820666169Z,2025-07-17T16:08:20.820500575Z,10,2,1108,C,A,0,16.010000000,100,0,165594,277732228,13.11,100,1,13.68,15,1,13.01,2,1,13.69,100,1,12.98,200,2,13.85,2,1,12.86,100,1,14.20,100,1,12.73,100,1,14.28,100,1,12.71,100,1,14.46,100,1,12.50,700,1,14.48,700,1,12.49,200,2,14.52,200,2,12.46,100,1,14.56,800,2,12.43,700,1,14.60,700,1,ARL,332494245
2100,2025-07-17T16:08:20.820666169Z,2025-07-17T16:08:20.820500575Z,10,2,1108,A,A,0,15.750000000,100,130,165594,277732228,13.11,100,1,13.68,15,1,13.01,2,1,13.69,100,1,12.98,200,2,13.85,2,1,12.86,100,1,14.20,100,1,12.73,100,1,14.28,100,1,12.71,100,1,14.46,100,1,12.50,700,1,14.48,700,1,12.49,200,2,14.52,200,2,12.46,100,1,14.56,800,2,12.43,700,1,14.60,700,1,ARL,333436449
2101,2025-07-17T16:08:20.822089544Z,2025-07-17T16:08:20.821924168Z,10,2,1108,C,A,0,14.200000000,100,130,165376,277732239,13.11,100,1,13.68,15,1,13.01,2,1,13.69,100,1,12.98,200,2,13.85,2,1,12.86,100,1,14.28,100,1,12.73,100,1,14.46,100,1,12.71,100,1,14.48,700,1,12.50,700,1,14.52,200,2,12.49,200,2,14.56,800,2,12.46,100,1,14.60,700,1,12.43,700,1,14.65,100,1,ARL,332494893
2102,2025-07-17T16:08:20.822139541Z,2025-07-17T16:08:20.821974299Z,10,2,1108,A,A,0,13.960000000,100,130,165242,277732240,13.11,100,1,13.68,15,1,13.01,2,1,13.69,100,1,12.98,200,2,13.85,2,1,12.86,100,1,13.96,100,1,12.73,100,1,14.28,100,1,12.71,100,1,14.46,100,1,12.50,700,1,14.48,700,1,12.49,200,2,14.52,200,2,12.46,100,1,14.56,800,2,12.43,700,1,14.60,700,1,ARL,333436473
2103,2025-07-17T16:08:20.830110499Z,2025-07-17T16:08:20.829945074Z,10,2,1108,C,A,0,14.950000000,100,0,165425,277732299,13.11,100,1,13.68,15,1,13.01,2,1,13.69,100,1,12.98,200,2,13.85,2,1,12.86,100,1,13.96,100,1,12.73,100,1,14.28,100,1,12.71,100,1,14.46,100,1,12.50,700,1,14.48,700,1,12.49,200,2,14.52,200,2,12.46,100,1,14.56,800,2,12.43,700,1,14.60,700,1,ARL,332494281
2104,2025-07-17T16:08:20.830110499Z,2025-07-17T16:08:20.829945074Z,10,2,1108,A,A,0,14.650000000,100,130,165425,277732299,13.11,100,1,13.68,15,1,13.01,2,1,13.69,100,1,12.98,200,2,13.85,2,1,12.86,100,1,13.96,100,1,12.73,100,1,14.28,100,1,12.71,100,1,14.46,100,1,12.50,700,1,14.48,700,1,12.49,200,2,14.52,200,2,12.46,100,1,14.56,800,2,12.43,700,1,14.60,700,1,ARL,333436589
2105,2025-07-17T16:08:20.966229266Z,2025-07-17T16:08:20.966063681Z,10,2,1108,C,A,0,14.770000000,100,0,165585,277733304,13.11,100,1,13.68,15,1,13.01,2,1,13.69,100,1,12.98,200,2,13.85,2,1,12.86,100,1,13.96,100,1,12.73,100,1,14.28,100,1,12.71,100,1,14.46,100,1,12.50,700,1,14.48,700,1,12.49,200,2,14.52,200,2,12.46,100,1,14.56,800,2,12.43,700,1,14.60,700,1,ARL,332497653
2106,2025-07-17T16:08:20.966229266Z,2025-07-17T16:08:20.966063681Z,10,2,1108,A,A,0,14.480000000,100,130,165585,277733304,13.11,100,1,13.68,15,1,13.01,2,1,13.69,100,1,12.98,200,2,13.85,2,1,12.86,100,1,13.96,100,1,12.73,100,1,14.28,100,1,12.71,100,1,14.46,100,1,12.50,700,1,14.48,800,2,12.49,200,2,14.52,200,2,12.46,100,1,14.56,800,2,12.43,700,1,14.60,700,1,ARL,333438545
2107,2025-07-17T16:08:22.998168186Z,2025-07-17T16:08:22.998002821Z,10,2,1108,C,A,0,13.680000000,15,130,165365,277766492,13.11,100,1,13.69,100,1,13.01,2,1,13.85,2,1,12.98,200,2,13.96,100,1,12.86,100,1,14.28,100,1,12.73,100,1,14.46,100,1,12.71,100,1,14.48,800,2,12.50,700,1,14.52,200,2,12.49,200,2,14.56,800,2,12.46,100,1,14.60,700,1,12.43,700,1,14.65,200,2,ARL,333436357
2108,2025-07-17T16:08:27.482509684Z,2025-07-17T16:08:27.482344236Z,10,2,1108,C,A,0,13.690000000,100,130,165448,277841171,13.11,100,1,13.85,2,1,13.01,2,1,13.96,100,1,12.98,200,2,14.28,100,1,12.86,100,1,14.46,100,1,12.73,100,1,14.48,800,2,12.71,100,1,14.52,200,2,12.50,700,1,14.56,800,2,12.49,200,2,14.60,700,1,12.46,100,1,14.65,200,2,12.43,700,1,14.68,700,1,ARL,333436361
2109,2025-07-17T16:08:27.483241007Z,2025-07-17T16:08:27.483075481Z,10,2,1108,C,A,0,14.750000000,100,0,165526,277841175,13.11,100,1,13.85,2,1,13.01,2,1,13.96,100,1,12.98,200,2,14.28,100,1,12.86,100,1,14.46,100,1,12.73,100,1,14.48,800,2,12.71,100,1,14.52,200,2,12.50,700,1,14.56,800,2,12.49,200,2,14.60,700,1,12.46,100,1,14.65,200,2,12.43,700,1,14.68,700,1,ARL,333436397
2110,2025-07-17T16:08:27.483241007Z,2025-07-17T16:08:27.483075481Z,10,2,1108,A,A,0,14.990000000,100,130,165526,277841175,13.11,100,1,13.85,2,1,13.01,2,1,13.96,100,1,12.98,200,2,14.28,100,1,12.86,100,1,14.46,100,1,12.73,100,1,14.48,800,2,12.71,100,1,14.52,200,2,12.50,700,1,14.56,800,2,12.49,200,2,14.60,700,1,12.46,100,1,14.65,200,2,12.43,700,1,14.68,700,1,ARL,333581389
2111,2025-07-17T16:08:27.483585892Z,2025-07-17T16:08:27.483420069Z,10,2,1108,C,A,0,14.520000000,100,0,165823,277841178,13.11,100,1,13.85,2,1,13.01,2,1,13.96,100,1,12.98,200,2,14.28,100,1,12.86,100,1,14.46,100,1,12.73,100,1,14.48,800,2,12.71,100,1,14.52,100,1,12.50,700,1,14.56,800,2,12.49,200,2,14.60,700,1,12.46,100,1,14.65,200,2,12.43,700,1,14.68,700,1,ARL,328780577
2112,2025-07-17T16:08:27.483585892Z,2025-07-17T16:08:27.483420069Z,10,2,1108,A,A,0,14.740000000,100,130,165823,277841178,13.11,100,1,13.85,2,1,13.01,2,1,13.96,100,1,12.98,200,2,14.28,100,1,12.86,100,1,14.46,100,1,12.73,100,1,14.48,800,2,12.71,100,1,14.52,100,1,12.50,700,1,14.56,800,2,12.49,200,2,14.60,700,1,12.46,100,1,14.65,200,2,12.43,700,1,14.68,700,1,ARL,333581393
2113,2025-07-17T16:08:27.484079224Z,2025-07-17T16:08:27.483913735Z,10,2,1108,C,A,0,14.650000000,100,0,165489,277841218,13.11,100,1,13.85,2,1,13.01,2,1,13.96,100,1,12.98,200,2,14.28,100,1,12.86,100,1,14.46,100,1,12.73,100,1,14.48,800,2,12.71,100,1,14.52,100,1,12.50,700,1,14.56,800,2,12.49,200,2,14.60,700,1,12.46,100,1,14.65,100,1,12.43,700,1,14.68,700,1,ARL,333436589
2114,2025-07-17T16:08:27.484079224Z,2025-07-17T16:08:27.483913735Z,10,2,1108,A,A,0,14.940000000,100,130,165489,277841218,13.11,100,1,13.85,2,1,13.01,2,1,13.96,100,1,12.98,200,2,14.28,100,1,12.86,100,1,14.46,100,1,12.73,100,1,14.48,800,2,12.71,100,1,14.52,100,1,12.50,700,1,14.56,800,2,12.49,200,2,14.60,700,1,12.46,100,1,14.65,100,1,12.43,700,1,14.68,700,1,ARL,333581409
2115,2025-07-17T16:08:27.484859188Z,2025-07-17T16:08:27.484693568Z,10,2,1108,C,A,0,17.390000000,100,0,165620,277841226,13.11,100,1,13.85,2,1,13.01,2,1,13.96,100,1,12.98,200,2,14.28,100,1,12.86,100,1,14.46,100,1,12.73,100,1,14.48,800,2,12.71,100,1,14.52,100,1,12.50,700,1,14.56,800,2,12.49,200,2,14.60,700,1,12.46,100,1,14.65,100,1,12.43,700,1,14.68,700,1,ARL,333436441
2116,2025-07-17T16:08:27.484859188Z,2025-07-17T16:08:27.484693568Z,10,2,1108,A,A,0,17.730000000,100,130,165620,277841226,13.11,100,1,13.85,2,1,13.01,2,1,13.96,100,1,12.98,200,2,14.28,100,1,12.86,100,1,14.46,100,1,12.73,100,1,14.48,800,2,12.71,100,1,14.52,100,1,12.50,700,1,14.56,800,2,12.49,200,2,14.60,700,1,12.46,100,1,14.65,100,1,12.43,700,1,14.68,700,1,ARL,333581425
2117,2025-07-17T16:08:27.484965957Z,2025-07-17T16:08:27.484800296Z,10,2,1108,C,A,0,14.650000000,100,0,165661,277841228,13.11,100,1,13.85,2,1,13.01,2,1,13.96,100,1,12.98,200,2,14.28,100,1,12.86,100,1,14.46,100,1,12.73,100,1,14.48,800,2,12.71,100,1,14.52,100,1,12.50,700,1,14.56,800,2,12.49,200,2,14.60,700,1,12.46,100,1,14.68,700,1,12.43,700,1,14.74,100,1,ARL,333436425
2118,2025-07-17T16:08:27.484965957Z,2025-07-17T16:08:27.484800296Z,10,2,1108,A,A,0,14.940000000,100,130,165661,277841228,13.11,100,1,13.85,2,1,13.01,2,1,13.96,100,1,12.98,200,2,14.28,100,1,12.86,100,1,14.46,100,1,12.73,100,1,14.48,800,2,12.71,100,1,14.52,100,1,12.50,700,1,14.56,800,2,12.49,200,2,14.60,700,1,12.46,100,1,14.68,700,1,12.43,700,1,14.74,100,1,ARL,333581429
2119,2025-07-17T16:08:27.484978859Z,2025-07-17T16:08:27.484813280Z,10,2,1108,C,A,0,15.750000000,100,0,165579,277841229,13.11,100,1,13.85,2,1,13.01,2,1,13.96,100,1,12.98,200,2,14.28,100,1,12.86,100,1,14.46,100,1,12.73,100,1,14.48,800,2,12.71,100,1,14.52,100,1,12.50,700,1,14.56,800,2,12.49,200,2,14.60,700,1,12.46,100,1,14.68,700,1,12.43,700,1,14.74,100,1,ARL,333436449
2120,2025-07-17T16:08:27.484978859Z,2025-07-17T16:08:27.484813280Z,10,2,1108,A,A,0,16.060000000,100,130,165579,277841229,13.11,100,1,13.85,2,1,13.01,2,1,13.96,100,1,12.98,200,2,14.28,100,1,12.86,100,1,14.46,100,1,12.73,100,1,14.48,800,2,12.71,100,1,14.52,100,1,12.50,700,1,14.56,800,2,12.49,200,2,14.60,700,1,12.46,100,1,14.68,700,1,12.43,700,1,14.74,100,1,ARL,333581433
2121,2025-07-17T16:08:27.485352204Z,2025-07-17T16:08:27.485186411Z,10,2,1108,C,A,0,15.060000000,100,0,165793,277841231,13.11,100,1,13.85,2,1,13.01,2,1,13.96,100,1,12.98,200,2,14.28,100,1,12.86,100,1,14.46,100,1,12.73,100,1,14.48,800,2,12.71,100,1,14.52,100,1,12.50,700,1,14.56,800,2,12.49,200,2,14.60,700,1,12.46,100,1,14.68,700,1,12.43,700,1,14.74,100,1,ARL,333436421
2122,2025-07-17T16:08:27.485352204Z,2025-07-17T16:08:27.485186411Z,10,2,1108,A,A,0,15.360000000,100,130,165793,277841231,13.11,100,1,13.85,2,1,13.01,2,1,13.96,100,1,12.98,200,2,14.28,100,1,12.86,100,1,14.46,100,1,12.73,100,1,14.48,800,2,12.71,100,1,14.52,100,1,12.50,700,1,14.56,800,2,12.49,200,2,14.60,700,1,12.46,100,1,14.68,700,1,12.43,700,1,14.74,100,1,ARL,333581441
2123,2025-07-17T16:08:27.487263276Z,2025-07-17T16:08:27.487097702Z,10,2,1108,C,A,0,14.520000000,100,0,165574,277841319,13.11,100,1,13.85,2,1,13.01,2,1,13.96,100,1,12.98,200,2,14.28,100,1,12.86,100,1,14.46,100,1,12.73,100,1,14.48,800,2,12.71,100,1,14.56,800,2,12.50,700,1,14.60,700,1,12.49,200,2,14.68,700,1,12.46,100,1,14.74,100,1,12.43,700,1,14.94,200,2,ARL,328780597
2124,2025-07-17T16:08:27.487263276Z,2025-07-17T16:08:27.487097702Z,10,2,1108,A,A,0,14.740000000,100,130,165574,277841319,13.11,100,1,13.85,2,1,13.01,2,1,13.96,100,1,12.98,200,2,14.28,100,1,12.86,100,1,14.46,100,1,12.73,100,1,14.48,800,2,12.71,100,1,14.56,800,2,12.50,700,1,14.60,700,1,12.49,200,2,14.68,700,1,12.46,100,1,14.74,200,2,12.43,700,1,14.94,200,2,ARL,333581481
2125,2025-07-17T16:08:27.492258906Z,2025-07-17T16:08:27.492093401Z,10,2,1108,C,A,0,14.480000000,100,130,165505,277841396,13.11,100,1,13.85,2,1,13.01,2,1,13.96,100,1,12.98,200,2,14.28,100,1,12.86,100,1,14.46,100,1,12.73,100,1,14.48,700,1,12.71,100,1,14.56,800,2,12.50,700,1,14.60,700,1,12.49,200,2,14.68,700,1,12.46,100,1,14.74,200,2,12.43,700,1,14.94,200,2,ARL,333438545
2126,2025-07-17T16:08:27.492385750Z,2025-07-17T16:08:27.492220454Z,10,2,1108,A,A,0,14.750000000,100,130,165296,277841397,13.11,100,1,13.85,2,1,13.01,2,1,13.96,100,1,12.98,200,2,14.28,100,1,12.86,100,1,14.46,100,1,12.73,100,1,14.48,700,1,12.71,100,1,14.56,800,2,12.50,700,1,14.60,700,1,12.49,200,2,14.68,700,1,12.46,100,1,14.74,200,2,12.43,700,1,14.75,100,1,ARL,333581569
2127,2025-07-17T16:08:27.496936122Z,2025-07-17T16:08:27.496770678Z,10,2,1108,C,A,0,13.960000000,100,130,165444,277841427,13.11,100,1,13.85,2,1,13.01,2,1,14.28,100,1,12.98,200,2,14.46,100,1,12.86,100,1,14.48,700,1,12.73,100,1,14.56,800,2,12.71,100,1,14.60,700,1,12.50,700,1,14.68,700,1,12.49,200,2,14.74,200,2,12.46,100,1,14.75,100,1,12.43,700,1,14.94,200,2,ARL,333436473
2128,2025-07-17T16:08:27.496987832Z,2025-07-17T16:08:27.496822540Z,10,2,1108,A,A,0,14.190000000,100,130,165292,277841428,13.11,100,1,13.85,2,1,13.01,2,1,14.19,100,1,12.98,200,2,14.28,100,1,12.86,100,1,14.46,100,1,12.73,100,1,14.48,700,1,12.71,100,1,14.56,800,2,12.50,700,1,14.60,700,1,12.49,200,2,14.68,700,1,12.46,100,1,14.74,200,2,12.43,700,1,14.75,100,1,ARL,333581625
2129,2025-07-17T16:08:27.501093618Z,2025-07-17T16:08:27.500928061Z,10,2,1108,C,A,0,13.850000000,2,0,165557,277841469,13.11,100,1,14.19,100,1,13.01,2,1,14.28,100,1,12.98,200,2,14.46,100,1,12.86,100,1,14.48,700,1,12.73,100,1,14.56,800,2,12.71,100,1,14.60,700,1,12.50,700,1,14.68,700,1,12.49,200,2,14.74,200,2,12.46,100,1,14.75,100,1,12.43,700,1,14.94,200,2,ARL,331155889
2130,2025-07-17T16:08:27.501093618Z,2025-07-17T16:08:27.500928061Z,10,2,1108,A,A,0,13.980000000,2,130,165557,277841469,13.11,100,1,13.98,2,1,13.01,2,1,14.19,100,1,12.98,200,2,14.28,100,1,12.86,100,1,14.46,100,1,12.73,100,1,14.48,700,1,12.71,100,1,14.56,800,2,12.50,700,1,14.60,700,1,12.49,200,2,14.68,700,1,12.46,100,1,14.74,200,2,12.43,700,1,14.75,100,1,ARL,333581677
2131,2025-07-17T16:08:27.516614373Z,2025-07-17T16:08:27.516449334Z,10,2,1108,C,A,0,14.190000000,100,130,165039,277841551,13.11,100,1,13.98,2,1,13.01,2,1,14.28,100,1,12.98,200,2,14.46,100,1,12.86,100,1,14.48,700,1,12.73,100,1,14.56,800,2,12.71,100,1,14.60,700,1,12.50,700,1,14.68,700,1,12.49,200,2,14.74,200,2,12.46,100,1,14.75,100,1,12.43,700,1,14.94,200,2,ARL,333581625
2132,2025-07-17T16:08:27.516662099Z,2025-07-17T16:08:27.516496962Z,10,2,1108,A,A,0,14.260000000,100,130,165137,277841552,13.11,100,1,13.98,2,1,13.01,2,1,14.26,100,1,12.98,200,2,14.28,100,1,12.86,100,1,14.46,100,1,12.73,100,1,14.48,700,1,12.71,100,1,14.56,800,2,12.50,700,1,14.60,700,1,12.49,200,2,14.68,700,1,12.46,100,1,14.74,200,2,12.43,700,1,14.75,100,1,ARL,333581765
2133,2025-07-17T16:08:27.533938450Z,2025-07-17T16:08:27.533773259Z,10,2,1108,C,A,0,14.990000000,100,0,165191,277841588,13.11,100,1,13.98,2,1,13.01,2,1,14.26,100,1,12.98,200,2,14.28,100,1,12.86,100,1,14.46,100,1,12.73,100,1,14.48,700,1,12.71,100,1,14.56,800,2,12.50,700,1,14.60,700,1,12.49,200,2,14.68,700,1,12.46,100,1,14.74,200,2,12.43,700,1,14.75,100,1,ARL,333581389
2134,2025-07-17T16:08:27.533938450Z,2025-07-17T16:08:27.533773259Z,10,2,1108,A,A,0,15.040000000,100,130,165191,277841588,13.11,100,1,13.98,2,1,13.01,2,1,14.26,100,1,12.98,200,2,14.28,100,1,12.86,100,1,14.46,100,1,12.73,100,1,14.48,700,1,12.71,100,1,14.56,800,2,12.50,700,1,14.60,700,1,12.49,200,2,14.68,700,1,12.46,100,1,14.74,200,2,12.43,700,1,14.75,100,1,ARL,333581845
2135,2025-07-17T16:08:27.987678739Z,2025-07-17T16:08:27.987513451Z,10,2,1108,A,A,0,13.990000000,100,130,165288,277846288,13.11,100,1,13.98,2,1,13.01,2,1,13.99,100,1,12.98,200,2,14.26,100,1,12.86,100,1,14.28,100,1,12.73,100,1,14.46,100,1,12.71,100,1,14.48,700,1,12.50,700,1,14.56,800,2,12.49,200,2,14.60,700,1,12.46,100,1,14.68,700,1,12.43,700,1,14.74,200,2,ARL,333590057
2136,2025-07-17T16:08:58.024979382Z,2025-07-17T16:08:58.024814068Z,10,2,1108,A,A,0,13.810000000,15,130,165314,278261182,13.11,100,1,13.81,15,1,13.01,2,1,13.98,2,1,12.98,200,2,13.99,100,1,12.86,100,1,14.26,100,1,12.73,100,1,14.28,100,1,12.71,100,1,14.46,100,1,12.50,700,1,14.48,700,1,12.49,200,2,14.56,800,2,12.46,100,1,14.60,700,1,12.43,700,1,14.68,700,1,ARL,334141429
2137,2025-07-17T16:09:00.222675234Z,2025-07-17T16:09:00.222509491Z,10,2,1108,C,A,0,13.990000000,100,0,165743,278295684,13.11,100,1,13.81,15,1,13.01,2,1,13.98,2,1,12.98,200,2,14.26,100,1,12.86,100,1,14.28,100,1,12.73,100,1,14.46,100,1,12.71,100,1,14.48,700,1,12.50,700,1,14.56,800,2,12.49,200,2,14.60,700,1,12.46,100,1,14.68,700,1,12.43,700,1,14.74,200,2,ARL,333590057
2138,2025-07-17T16:09:00.222675234Z,2025-07-17T16:09:00.222509491Z,10,2,1108,A,A,0,13.820000000,100,130,165743,278295684,13.11,100,1,13.81,15,1,13.01,2,1,13.82,100,1,12.98,200,2,13.98,2,1,12.86,100,1,14.26,100,1,12.73,100,1,14.28,100,1,12.71,100,1,14.46,100,1,12.50,700,1,14.48,700,1,12.49,200,2,14.56,800,2,12.46,100,1,14.60,700,1,12.43,700,1,14.68,700,1,ARL,334189729
2139,2025-07-17T16:09:00.223436757Z,2025-07-17T16:09:00.223269382Z,10,2,1108,C,A,0,15.040000000,100,0,167375,278295848,13.11,100,1,13.81,15,1,13.01,2,1,13.82,100,1,12.98,200,2,13.98,2,1,12.86,100,1,14.26,100,1,12.73,100,1,14.28,100,1,12.71,100,1,14.46,100,1,12.50,700,1,14.48,700,1,12.49,200,2,14.56,800,2,12.46,100,1,14.60,700,1,12.43,700,1,14.68,700,1,ARL,333581845
2140,2025-07-17T16:09:00.223436757Z,2025-07-17T16:09:00.223269382Z,10,2,1108,A,A,0,14.890000000,100,128,167375,278295848,13.11,100,1,13.81,15,1,13.01,2,1,13.82,100,1,12.98,200,2,13.98,2,1,12.86,100,1,14.26,100,1,12.73,100,1,14.28,100,1,12.71,100,1,14.46,100,1,12.50,700,1,14.48,700,1,12.49,200,2,14.56,800,2,12.46,100,1,14.60,700,1,12.43,700,1,14.68,700,1,ARL,334189777
2141,2025-07-17T16:09:00.226504346Z,2025-07-17T16:09:00.226338384Z,10,2,1108,C,A,0,14.750000000,100,0,165962,278296281,13.11,100,1,13.81,15,1,13.01,2,1,13.82,100,1,12.98,200,2,13.98,2,1,12.86,100,1,14.26,100,1,12.73,100,1,14.28,100,1,12.71,100,1,14.46,100,1,12.50,700,1,14.48,700,1,12.49,200,2,14.56,800,2,12.46,100,1,14.60,700,1,12.43,700,1,14.68,700,1,ARL,333581569
2142,2025-07-17T16:09:00.226504346Z,2025-07-17T16:09:00.226338384Z,10,2,1108,A,A,0,14.610000000,100,130,165962,278296281,13.11,100,1,13.81,15,1,13.01,2,1,13.82,100,1,12.98,200,2,13.98,2,1,12.86,100,1,14.26,100,1,12.73,100,1,14.28,100,1,12.71,100,1,14.46,100,1,12.50,700,1,14.48,700,1,12.49,200,2,14.56,800,2,12.46,100,1,14.60,700,1,12.43,700,1,14.61,100,1,ARL,334190189
2143,2025-07-17T16:09:00.227929061Z,2025-07-17T16:09:00.227763275Z,10,2,1108,C,A,0,14.260000000,100,130,165786,278296402,13.11,100,1,13.81,15,1,13.01,2,1,13.82,100,1,12.98,200,2,13.98,2,1,12.86,100,1,14.28,100,1,12.73,100,1,14.46,100,1,12.71,100,1,14.48,700,1,12.50,700,1,14.56,800,2,12.49,200,2,14.60,700,1,12.46,100,1,14.61,100,1,12.43,700,1,14.68,700,1,ARL,333581765
2144,2025-07-17T16:09:00.227983483Z,2025-07-17T16:09:00.227818153Z,10,2,1108,A,A,0,14.100000000,100,130,165330,278296411,13.11,100,1,13.81,15,1,13.01,2,1,13.82,100,1,12.98,200,2,13.98,2,1,12.86,100,1,14.10,100,1,12.73,100,1,14.28,100,1,12.71,100,1,14.46,100,1,12.50,700,1,14.48,700,1,12.49,200,2,14.56,800,2,12.46,100,1,14.60,700,1,12.43,700,1,14.61,100,1,ARL,334190225
2145,2025-07-17T16:09:00.232908882Z,2025-07-17T16:09:00.232743323Z,10,2,1108,C,A,0,14.940000000,100,0,165559,278296544,13.11,100,1,13.81,15,1,13.01,2,1,13.82,100,1,12.98,200,2,13.98,2,1,12.86,100,1,14.10,100,1,12.73,100,1,14.28,100,1,12.71,100,1,14.46,100,1,12.50,700,1,14.48,700,1,12.49,200,2,14.56,800,2,12.46,100,1,14.60,700,1,12.43,700,1,14.61,100,1,ARL,333581429
2146,2025-07-17T16:09:00.232908882Z,2025-07-17T16:09:00.232743323Z,10,2,1108,A,A,0,14.790000000,100,130,165559,278296544,13.11,100,1,13.81,15,1,13.01,2,1,13.82,100,1,12.98,200,2,13.98,2,1,12.86,100,1,14.10,100,1,12.73,100,1,14.28,100,1,12.71,100,1,14.46,100,1,12.50,700,1,14.48,700,1,12.49,200,2,14.56,800,2,12.46,100,1,14.60,700,1,12.43,700,1,14.61,100,1,ARL,334190353
2147,2025-07-17T16:09:00.326293286Z,2025-07-17T16:09:00.326127587Z,10,2,1108,C,A,0,17.730000000,100,0,165699,278298302,13.11,100,1,13.81,15,1,13.01,2,1,13.82,100,1,12.98,200,2,13.98,2,1,12.86,100,1,14.10,100,1,12.73,100,1,14.28,100,1,12.71,100,1,14.46,100,1,12.50,700,1,14.48,700,1,12.49,200,2,14.56,800,2,12.46,100,1,14.60,700,1,12.43,700,1,14.61,100,1,ARL,333581425
2148,2025-07-17T16:09:00.326293286Z,2025-07-17T16:09:00.326127587Z,10,2,1108,A,A,0,17.560000000,100,130,165699,278298302,13.11,100,1,13.81,15,1,13.01,2,1,13.82,100,1,12.98,200,2,13.98,2,1,12.86,100,1,14.10,100,1,12.73,100,1,14.28,100,1,12.71,100,1,14.46,100,1,12.50,700,1,14.48,700,1,12.49,200,2,14.56,800,2,12.46,100,1,14.60,700,1,12.43,700,1,14.61,100,1,ARL,334192253
2149,2025-07-17T16:09:00.335607827Z,2025-07-17T16:09:00.335442266Z,10,2,1108,C,A,0,16.060000000,100,0,165561,278298372,13.11,100,1,13.81,15,1,13.01,2,1,13.82,100,1,12.98,200,2,13.98,2,1,12.86,100,1,14.10,100,1,12.73,100,1,14.28,100,1,12.71,100,1,14.46,100,1,12.50,700,1,14.48,700,1,12.49,200,2,14.56,800,2,12.46,100,1,14.60,700,1,12.43,700,1,14.61,100,1,ARL,333581433
2150,2025-07-17T16:09:00.335607827Z,2025-07-17T16:09:00.335442266Z,10,2,1108,A,A,0,15.900000000,100,130,165561,278298372,13.11,100,1,13.81,15,1,13.01,2,1,13.82,100,1,12.98,200,2,13.98,2,1,12.86,100,1,14.10,100,1,12.73,100,1,14.28,100,1,12.71,100,1,14.46,100,1,12.50,700,1,14.48,700,1,12.49,200,2,14.56,800,2,12.46,100,1,14.60,700,1,12.43,700,1,14.61,100,1,ARL,334192405
2151,2025-07-17T16:09:00.695776010Z,2025-07-17T16:09:00.695610142Z,10,2,1108,C,A,0,14.940000000,100,0,165868,278304343,13.11,100,1,13.81,15,1,13.01,2,1,13.82,100,1,12.98,200,2,13.98,2,1,12.86,100,1,14.10,100,1,12.73,100,1,14.28,100,1,12.71,100,1,14.46,100,1,12.50,700,1,14.48,700,1,12.49,200,2,14.56,800,2,12.46,100,1,14.60,700,1,12.43,700,1,14.61,100,1,ARL,333581409
2152,2025-07-17T16:09:00.695776010Z,2025-07-17T16:09:00.695610142Z,10,2,1108,A,A,0,14.790000000,100,130,165868,278304343,13.11,100,1,13.81,15,1,13.01,2,1,13.82,100,1,12.98,200,2,13.98,2,1,12.86,100,1,14.10,100,1,12.73,100,1,14.28,100,1,12.71,100,1,14.46,100,1,12.50,700,1,14.48,700,1,12.49,200,2,14.56,800,2,12.46,100,1,14.60,700,1,12.43,700,1,14.61,100,1,ARL,334199009
2153,2025-07-17T16:09:08.719690693Z,2025-07-17T16:09:08.719524374Z,10,2,1108,A,A,0,13.750000000,15,130,166319,278436950,13.11,100,1,13.75,15,1,13.01,2,1,13.81,15,1,12.98,200,2,13.82,100,1,12.86,100,1,13.98,2,1,12.73,100,1,14.10,100,1,12.71,100,1,14.28,100,1,12.50,700,1,14.46,100,1,12.49,200,2,14.48,700,1,12.46,100,1,14.56,800,2,12.43,700,1,14.60,700,1,ARL,334366613
2154,2025-07-17T16:09:08.719871410Z,2025-07-17T16:09:08.719706070Z,10,2,1108,C,A,0,13.820000000,100,0,165340,278436967,13.11,100,1,13.75,15,1,13.01,2,1,13.81,15,1,12.98,200,2,13.98,2,1,12.86,100,1,14.10,100,1,12.73,100,1,14.28,100,1,12.71,100,1,14.46,100,1,12.50,700,1,14.48,700,1,12.49,200,2,14.56,800,2,12.46,100,1,14.60,700,1,12.43,700,1,14.61,100,1,ARL,334189729
2155,2025-07-17T16:09:08.719871410Z,2025-07-17T16:09:08.719706070Z,10,2,1108,A,A,0,13.760000000,100,130,165340,278436967,13.11,100,1,13.75,15,1,13.01,2,1,13.76,100,1,12.98,200,2,13.81,15,1,12.86,100,1,13.98,2,1,12.73,100,1,14.10,100,1,12.71,100,1,14.28,100,1,12.50,700,1,14.46,100,1,12.49,200,2,14.48,700,1,12.46,100,1,14.56,800,2,12.43,700,1,14.60,700,1,ARL,334366617
2156,2025-07-17T16:09:08.720607932Z,2025-07-17T16:09:08.720442245Z,10,2,1108,C,A,0,14.890000000,100,0,165687,278436994,13.11,100,1,13.75,15,1,13.01,2,1,13.76,100,1,12.98,200,2,13.81,15,1,12.86,100,1,13.98,2,1,12.73,100,1,14.10,100,1,12.71,100,1,14.28,100,1,12.50,700,1,14.46,100,1,12.49,200,2,14.48,700,1,12.46,100,1,14.56,800,2,12.43,700,1,14.60,700,1,ARL,334189777
2157,2025-07-17T16:09:08.720607932Z,2025-07-17T16:09:08.720442245Z,10,2,1108,A,A,0,14.830000000,100,130,165687,278436994,13.11,100,1,13.75,15,1,13.01,2,1,13.76,100,1,12.98,200,2,13.81,15,1,12.86,100,1,13.98,2,1,12.73,100,1,14.10,100,1,12.71,100,1,14.28,100,1,12.50,700,1,14.46,100,1,12.49,200,2,14.48,700,1,12.46,100,1,14.56,800,2,12.43,700,1,14.60,700,1,ARL,334366645
2158,2025-07-17T16:09:18.819300735Z,2025-07-17T16:09:18.819135505Z,10,2,1108,C,A,0,13.810000000,15,130,165230,278596985,13.11,100,1,13.75,15,1,13.01,2,1,13.76,100,1,12.98,200,2,13.98,2,1,12.86,100,1,14.10,100,1,12.73,100,1,14.28,100,1,12.71,100,1,14.46,100,1,12.50,700,1,14.48,700,1,12.49,200,2,14.56,800,2,12.46,100,1,14.60,700,1,12.43,700,1,14.61,100,1,ARL,334141429
2159,2025-07-17T16:09:19.927205023Z,2025-07-17T16:09:19.927039122Z,10,2,1108,A,A,0,13.730000000,15,130,165901,278621672,13.11,100,1,13.73,15,1,13.01,2,1,13.75,15,1,12.98,200,2,13.76,100,1,12.86,100,1,13.98,2,1,12.73,100,1,14.10,100,1,12.71,100,1,14.28,100,1,12.50,700,1,14.46,100,1,12.49,200,2,14.48,700,1,12.46,100,1,14.56,800,2,12.43,700,1,14.60,700,1,ARL,334583329
2160,2025-07-17T16:09:19.927910703Z,2025-07-17T16:09:19.927745104Z,10,2,1108,C,A,0,14.740000000,100,0,165599,278621693,13.11,100,1,13.73,15,1,13.01,2,1,13.75,15,1,12.98,200,2,13.76,100,1,12.86,100,1,13.98,2,1,12.73,100,1,14.10,100,1,12.71,100,1,14.28,100,1,12.50,700,1,14.46,100,1,12.49,200,2,14.48,700,1,12.46,100,1,14.56,800,2,12.43,700,1,14.60,700,1,ARL,333581393
2161,2025-07-17T16:09:19.927910703Z,2025-07-17T16:09:19.927745104Z,10,2,1108,A,A,0,14.620000000,100,130,165599,278621693,13.11,100,1,13.73,15,1,13.01,2,1,13.75,15,1,12.98,200,2,13.76,100,1,12.86,100,1,13.98,2,1,12.73,100,1,14.10,100,1,12.71,100,1,14.28,100,1,12.50,700,1,14.46,100,1,12.49,200,2,14.48,700,1,12.46,100,1,14.56,800,2,12.43,700,1,14.60,700,1,ARL,334583349
2162,2025-07-17T16:09:19.928319369Z,2025-07-17T16:09:19.928153837Z,10,2,1108,C,A,0,14.740000000,100,0,165532,278621695,13.11,100,1,13.73,15,1,13.01,2,1,13.75,15,1,12.98,200,2,13.76,100,1,12.86,100,1,13.98,2,1,12.73,100,1,14.10,100,1,12.71,100,1,14.28,100,1,12.50,700,1,14.46,100,1,12.49,200,2,14.48,700,1,12.46,100,1,14.56,800,2,12.43,700,1,14.60,700,1,ARL,333581481
2163,2025-07-17T16:09:19.928319369Z,2025-07-17T16:09:19.928153837Z,10,2,1108,A,A,0,14.620000000,100,130,165532,278621695,13.11,100,1,13.73,15,1,13.01,2,1,13.75,15,1,12.98,200,2,13.76,100,1,12.86,100,1,13.98,2,1,12.73,100,1,14.10,100,1,12.71,100,1,14.28,100,1,12.50,700,1,14.46,100,1,12.49,200,2,14.48,700,1,12.46,100,1,14.56,800,2,12.43,700,1,14.60,700,1,ARL,334583361
2164,2025-07-17T16:09:20.284861075Z,2025-07-17T16:09:20.284695585Z,10,2,1108,C,A,0,13.760000000,100,0,165490,278629057,13.11,100,1,13.73,15,1,13.01,2,1,13.75,15,1,12.98,200,2,13.98,2,1,12.86,100,1,14.10,100,1,12.73,100,1,14.28,100,1,12.71,100,1,14.46,100,1,12.50,700,1,14.48,700,1,12.49,200,2,14.56,800,2,12.46,100,1,14.60,700,1,12.43,700,1,14.61,100,1,ARL,334366617
2165,2025-07-17T16:09:20.284861075Z,2025-07-17T16:09:20.284695585Z,10,2,1108,A,A,0,13.740000000,100,130,165490,278629057,13.11,100,1,13.73,15,1,13.01,2,1,13.74,100,1,12.98,200,2,13.75,15,1,12.86,100,1,13.98,2,1,12.73,100,1,14.10,100,1,12.71,100,1,14.28,100,1,12.50,700,1,14.46,100,1,12.49,200,2,14.48,700,1,12.46,100,1,14.56,800,2,12.43,700,1,14.60,700,1,ARL,334593569
2166,2025-07-17T16:09:20.293271620Z,2025-07-17T16:09:20.293106270Z,10,2,1108,C,A,0,14.100000000,100,130,165350,278629219,13.11,100,1,13.73,15,1,13.01,2,1,13.74,100,1,12.98,200,2,13.75,15,1,12.86,100,1,13.98,2,1,12.73,100,1,14.28,100,1,12.71,100,1,14.46,100,1,12.50,700,1,14.48,700,1,12.49,200,2,14.56,800,2,12.46,100,1,14.60,700,1,12.43,700,1,14.61,100,1,ARL,334190225
2167,2025-07-17T16:09:20.293326641Z,2025-07-17T16:09:20.293161454Z,10,2,1108,A,A,0,14.010000000,100,130,165187,278629220,13.11,100,1,13.73,15,1,13.01,2,1,13.74,100,1,12.98,200,2,13.75,15,1,12.86,100,1,13.98,2,1,12.73,100,1,14.01,100,1,12.71,100,1,14.28,100,1,12.50,700,1,14.46,100,1,12.49,200,2,14.48,700,1,12.46,100,1,14.56,800,2,12.43,700,1,14.60,700,1,ARL,334593753
2168,2025-07-17T16:09:20.818813935Z,2025-07-17T16:09:20.818648795Z,10,2,1108,C,A,0,13.730000000,15,130,165140,278640667,13.11,100,1,13.74,100,1,13.01,2,1,13.75,15,1,12.98,200,2,13.98,2,1,12.86,100,1,14.01,100,1,12.73,100,1,14.28,100,1,12.71,100,1,14.46,100,1,12.50,700,1,14.48,700,1,12.49,200,2,14.56,800,2,12.46,100,1,14.60,700,1,12.43,700,1,14.61,100,1,ARL,334583329
2169,2025-07-17T16:09:20.818926356Z,2025-07-17T16:09:20.818761228Z,10,2,1108,C,A,0,13.750000000,15,130,165128,278640670,13.11,100,1,13.74,100,1,13.01,2,1,13.98,2,1,12.98,200,2,14.01,100,1,12.86,100,1,14.28,100,1,12.73,100,1,14.46,100,1,12.71,100,1,14.48,700,1,12.50,700,1,14.56,800,2,12.49,200,2,14.60,700,1,12.46,100,1,14.61,100,1,12.43,700,1,14.62,200,2,ARL,334366613
2170,2025-07-17T16:09:28.986122432Z,2025-07-17T16:09:28.985956629Z,10,2,1108,C,A,0,13.980000000,2,0,165803,278784943,13.11,100,1,13.74,100,1,13.01,2,1,14.01,100,1,12.98,200,2,14.28,100,1,12.86,100,1,14.46,100,1,12.73,100,1,14.48,700,1,12.71,100,1,14.56,800,2,12.50,700,1,14.60,700,1,12.49,200,2,14.61,100,1,12.46,100,1,14.62,200,2,12.43,700,1,14.68,700,1,ARL,333581677
2171,2025-07-17T16:09:28.986122432Z,2025-07-17T16:09:28.985956629Z,10,2,1108,A,A,0,13.900000000,2,130,165803,278784943,13.11,100,1,13.74,100,1,13.01,2,1,13.90,2,1,12.98,200,2,14.01,100,1,12.86,100,1,14.28,100,1,12.73,100,1,14.46,100,1,12.71,100,1,14.48,700,1,12.50,700,1,14.56,800,2,12.49,200,2,14.60,700,1,12.46,100,1,14.61,100,1,12.43,700,1,14.62,200,2,ARL,334804177
2172,2025-07-17T16:09:40.821687905Z,2025-07-17T16:09:40.821522565Z,10,2,1108,A,A,0,13.700000000,15,130,165340,278938091,13.11,100,1,13.70,15,1,13.01,2,1,13.74,100,1,12.98,200,2,13.90,2,1,12.86,100,1,14.01,100,1,12.73,100,1,14.28,100,1,12.71,100,1,14.46,100,1,12.50,700,1,14.48,700,1,12.49,200,2,14.56,800,2,12.46,100,1,14.60,700,1,12.43,700,1,14.61,100,1,ARL,335003269
2173,2025-07-17T16:09:40.853604577Z,2025-07-17T16:09:40.853439053Z,10,2,1108,C,A,0,13.740000000,100,0,165524,278938747,13.11,100,1,13.70,15,1,13.01,2,1,13.90,2,1,12.98,200,2,14.01,100,1,12.86,100,1,14.28,100,1,12.73,100,1,14.46,100,1,12.71,100,1,14.48,700,1,12.50,700,1,14.56,800,2,12.49,200,2,14.60,700,1,12.46,100,1,14.61,100,1,12.43,700,1,14.62,200,2,ARL,334593569
2174,2025-07-17T16:09:40.853604577Z,2025-07-17T16:09:40.853439053Z,10,2,1108,A,A,0,13.710000000,100,130,165524,278938747,13.11,100,1,13.70,15,1,13.01,2,1,13.71,100,1,12.98,200,2,13.90,2,1,12.86,100,1,14.01,100,1,12.73,100,1,14.28,100,1,12.71,100,1,14.46,100,1,12.50,700,1,14.48,700,1,12.49,200,2,14.56,800,2,12.46,100,1,14.60,700,1,12.43,700,1,14.61,100,1,ARL,335003813
2175,2025-07-17T16:09:40.854356022Z,2025-07-17T16:09:40.854190408Z,10,2,1108,C,A,0,14.830000000,100,0,165614,278938765,13.11,100,1,13.70,15,1,13.01,2,1,13.71,100,1,12.98,200,2,13.90,2,1,12.86,100,1,14.01,100,1,12.73,100,1,14.28,100,1,12.71,100,1,14.46,100,1,12.50,700,1,14.48,700,1,12.49,200,2,14.56,800,2,12.46,100,1,14.60,700,1,12.43,700,1,14.61,100,1,ARL,334366645
2176,2025-07-17T16:09:40.854356022Z,2025-07-17T16:09:40.854190408Z,10,2,1108,A,A,0,14.770000000,100,130,165614,278938765,13.11,100,1,13.70,15,1,13.01,2,1,13.71,100,1,12.98,200,2,13.90,2,1,12.86,100,1,14.01,100,1,12.73,100,1,14.28,100,1,12.71,100,1,14.46,100,1,12.50,700,1,14.48,700,1,12.49,200,2,14.56,800,2,12.46,100,1,14.60,700,1,12.43,700,1,14.61,100,1,ARL,335003845
2177,2025-07-17T16:09:40.855724422Z,2025-07-17T16:09:40.855558831Z,10,2,1108,C,A,0,17.560000000,100,0,165591,278938788,13.11,100,1,13.70,15,1,13.01,2,1,13.71,100,1,12.98,200,2,13.90,2,1,12.86,100,1,14.01,100,1,12.73,100,1,14.28,100,1,12.71,100,1,14.46,100,1,12.50,700,1,14.48,700,1,12.49,200,2,14.56,800,2,12.46,100,1,14.60,700,1,12.43,700,1,14.61,100,1,ARL,334192253
2178,2025-07-17T16:09:40.855724422Z,2025-07-17T16:09:40.855558831Z,10,2,1108,A,A,0,17.420000000,100,130,165591,278938788,13.11,100,1,13.70,15,1,13.01,2,1,13.71,100,1,12.98,200,2,13.90,2,1,12.86,100,1,14.01,100,1,12.73,100,1,14.28,100,1,12.71,100,1,14.46,100,1,12.50,700,1,14.48,700,1,12.49,200,2,14.56,800,2,12.46,100,1,14.60,700,1,12.43,700,1,14.61,100,1,ARL,335003849
2179,2025-07-17T16:09:50.820949131Z,2025-07-17T16:09:50.820783486Z,10,2,1108,A,A,0,13.670000000,15,130,165645,279081140,13.11,100,1,13.67,15,1,13.01,2,1,13.70,15,1,12.98,200,2,13.71,100,1,12.86,100,1,13.90,2,1,12.73,100,1,14.01,100,1,12.71,100,1,14.28,100,1,12.50,700,1,14.46,100,1,12.49,200,2,14.48,700,1,12.46,100,1,14.56,800,2,12.43,700,1,14.60,700,1,ARL,335178437
2180,2025-07-17T16:09:52.678777358Z,2025-07-17T16:09:52.678611805Z,10,2,1108,C,A,0,13.710000000,100,0,165553,279109959,13.11,100,1,13.67,15,1,13.01,2,1,13.70,15,1,12.98,200,2,13.90,2,1,12.86,100,1,14.01,100,1,12.73,100,1,14.28,100,1,12.71,100,1,14.46,100,1,12.50,700,1,14.48,700,1,12.49,200,2,14.56,800,2,12.46,100,1,14.60,700,1,12.43,700,1,14.61,100,1,ARL,335003813
2181,2025-07-17T16:09:52.678777358Z,2025-07-17T16:09:52.678611805Z,10,2,1108,A,A,0,13.680000000,100,130,165553,279109959,13.11,100,1,13.67,15,1,13.01,2,1,13.68,100,1,12.98,200,2,13.70,15,1,12.86,100,1,13.90,2,1,12.73,100,1,14.01,100,1,12.71,100,1,14.28,100,1,12.50,700,1,14.46,100,1,12.49,200,2,14.48,700,1,12.46,100,1,14.56,800,2,12.43,700,1,14.60,700,1,ARL,335220349
2182,2025-07-17T16:09:52.679844338Z,2025-07-17T16:09:52.679678566Z,10,2,1108,C,A,0,15.900000000,100,0,165772,279109991,13.11,100,1,13.67,15,1,13.01,2,1,13.68,100,1,12.98,200,2,13.70,15,1,12.86,100,1,13.90,2,1,12.73,100,1,14.01,100,1,12.71,100,1,14.28,100,1,12.50,700,1,14.46,100,1,12.49,200,2,14.48,700,1,12.46,100,1,14.56,800,2,12.43,700,1,14.60,700,1,ARL,334192405
2183,2025-07-17T16:09:52.679844338Z,2025-07-17T16:09:52.679678566Z,10,2,1108,A,A,0,15.740000000,100,130,165772,279109991,13.11,100,1,13.67,15,1,13.01,2,1,13.68,100,1,12.98,200,2,13.70,15,1,12.86,100,1,13.90,2,1,12.73,100,1,14.01,100,1,12.71,100,1,14.28,100,1,12.50,700,1,14.46,100,1,12.49,200,2,14.48,700,1,12.46,100,1,14.56,800,2,12.43,700,1,14.60,700,1,ARL,335220497
2184,2025-07-17T16:09:52.679936826Z,2025-07-17T16:09:52.679769832Z,10,2,1108,C,A,0,14.790000000,100,0,166994,279109996,13.11,100,1,13.67,15,1,13.01,2,1,13.68,100,1,12.98,200,2,13.70,15,1,12.86,100,1,13.90,2,1,12.73,100,1,14.01,100,1,12.71,100,1,14.28,100,1,12.50,700,1,14.46,100,1,12.49,200,2,14.48,700,1,12.46,100,1,14.56,800,2,12.43,700,1,14.60,700,1,ARL,334190353
2185,2025-07-17T16:09:52.679936826Z,2025-07-17T16:09:52.679769832Z,10,2,1108,A,A,0,14.640000000,100,130,166994,279109996,13.11,100,1,13.67,15,1,13.01,2,1,13.68,100,1,12.98,200,2,13.70,15,1,12.86,100,1,13.90,2,1,12.73,100,1,14.01,100,1,12.71,100,1,14.28,100,1,12.50,700,1,14.46,100,1,12.49,200,2,14.48,700,1,12.46,100,1,14.56,800,2,12.43,700,1,14.60,700,1,ARL,335220525
2186,2025-07-17T16:09:52.680837736Z,2025-07-17T16:09:52.680672148Z,10,2,1108,C,A,0,15.360000000,100,0,165588,279110032,13.11,100,1,13.67,15,1,13.01,2,1,13.68,100,1,12.98,200,2,13.70,15,1,12.86,100,1,13.90,2,1,12.73,100,1,14.01,100,1,12.71,100,1,14.28,100,1,12.50,700,1,14.46,100,1,12.49,200,2,14.48,700,1,12.46,100,1,14.56,800,2,12.43,700,1,14.60,700,1,ARL,333581441
2187,2025-07-17T16:09:52.680837736Z,2025-07-17T16:09:52.680672148Z,10,2,1108,A,A,0,15.050000000,100,130,165588,279110032,13.11,100,1,13.67,15,1,13.01,2,1,13.68,100,1,12.98,200,2,13.70,15,1,12.86,100,1,13.90,2,1,12.73,100,1,14.01,100,1,12.71,100,1,14.28,100,1,12.50,700,1,14.46,100,1,12.49,200,2,14.48,700,1,12.46,100,1,14.56,800,2,12.43,700,1,14.60,700,1,ARL,335220549
2188,2025-07-17T16:09:52.682009938Z,2025-07-17T16:09:52.681844377Z,10,2,1108,C,A,0,14.610000000,100,130,165561,279110066,13.11,100,1,13.67,15,1,13.01,2,1,13.68,100,1,12.98,200,2,13.70,15,1,12.86,100,1,13.90,2,1,12.73,100,1,14.01,100,1,12.71,100,1,14.28,100,1,12.50,700,1,14.46,100,1,12.49,200,2,14.48,700,1,12.46,100,1,14.56,800,2,12.43,700,1,14.60,700,1,ARL,334190189
2189,2025-07-17T16:09:52.682127530Z,2025-07-17T16:09:52.681961200Z,10,2,1108,A,A,0,14.470000000,100,130,166330,279110068,13.11,100,1,13.67,15,1,13.01,2,1,13.68,100,1,12.98,200,2,13.70,15,1,12.86,100,1,13.90,2,1,12.73,100,1,14.01,100,1,12.71,100,1,14.28,100,1,12.50,700,1,14.46,100,1,12.49,200,2,14.47,100,1,12.46,100,1,14.48,700,1,12.43,700,1,14.56,800,2,ARL,335220561
2190,2025-07-17T16:09:52.683922707Z,2025-07-17T16:09:52.683757265Z,10,2,1108,C,A,0,14.790000000,100,0,165442,279110090,13.11,100,1,13.67,15,1,13.01,2,1,13.68,100,1,12.98,200,2,13.70,15,1,12.86,100,1,13.90,2,1,12.73,100,1,14.01,100,1,12.71,100,1,14.28,100,1,12.50,700,1,14.46,100,1,12.49,200,2,14.47,100,1,12.46,100,1,14.48,700,1,12.43,700,1,14.56,800,2,ARL,334199009
2191,2025-07-17T16:09:52.683922707Z,2025-07-17T16:09:52.683757265Z,10,2,1108,A,A,0,14.640000000,100,130,165442,279110090,13.11,100,1,13.67,15,1,13.01,2,1,13.68,100,1,12.98,200,2,13.70,15,1,12.86,100,1,13.90,2,1,12.73,100,1,14.01,100,1,12.71,100,1,14.28,100,1,12.50,700,1,14.46,100,1,12.49,200,2,14.47,100,1,12.46,100,1,14.48,700,1,12.43,700,1,14.56,800,2,ARL,335220629
2192,2025-07-17T16:10:04.521471804Z,2025-07-17T16:10:04.521306513Z,10,2,1108,C,A,0,13.670000000,15,130,165291,279306715,13.11,100,1,13.68,100,1,13.01,2,1,13.70,15,1,12.98,200,2,13.90,2,1,12.86,100,1,14.01,100,1,12.73,100,1,14.28,100,1,12.71,100,1,14.46,100,1,12.50,700,1,14.47,100,1,12.49,200,2,14.48,700,1,12.46,100,1,14.56,800,2,12.43,700,1,14.60,700,1,ARL,335178437
2193,2025-07-17T16:10:04.561854856Z,2025-07-17T16:10:04.561688313Z,10,2,1108,C,A,0,13.700000000,15,128,166543,279312083,13.11,100,1,13.68,100,1,13.01,2,1,13.90,2,1,12.98,200,2,14.01,100,1,12.86,100,1,14.28,100,1,12.73,100,1,14.46,100,1,12.71,100,1,14.47,100,1,12.50,700,1,14.48,700,1,12.49,200,2,14.56,800,2,12.46,100,1,14.60,700,1,12.43,700,1,14.62,200,2,ARL,335003269
2194,2025-07-17T16:10:32.822660498Z,2025-07-17T16:10:32.822495087Z,10,2,1108,A,A,0,13.650000000,15,130,165411,279705339,13.11,100,1,13.65,15,1,13.01,2,1,13.68,100,1,12.98,200,2,13.90,2,1,12.86,100,1,14.01,100,1,12.73,100,1,14.28,100,1,12.71,100,1,14.46,100,1,12.50,700,1,14.47,100,1,12.49,200,2,14.48,700,1,12.46,100,1,14.56,800,2,12.43,700,1,14.60,700,1,ARL,335996705
2195,2025-07-17T16:10:32.822923138Z,2025-07-17T16:10:32.822757517Z,10,2,1108,C,A,0,13.680000000,100,0,165621,279705347,13.11,100,1,13.65,15,1,13.01,2,1,13.90,2,1,12.98,200,2,14.01,100,1,12.86,100,1,14.28,100,1,12.73,100,1,14.46,100,1,12.71,100,1,14.47,100,1,12.50,700,1,14.48,700,1,12.49,200,2,14.56,800,2,12.46,100,1,14.60,700,1,12.43,700,1,14.62,200,2,ARL,335220349
2196,2025-07-17T16:10:32.822923138Z,2025-07-17T16:10:32.822757517Z,10,2,1108,A,A,0,13.660000000,100,130,165621,279705347,13.11,100,1,13.65,15,1,13.01,2,1,13.66,100,1,12.98,200,2,13.90,2,1,12.86,100,1,14.01,100,1,12.73,100,1,14.28,100,1,12.71,100,1,14.46,100,1,12.50,700,1,14.47,100,1,12.49,200,2,14.48,700,1,12.46,100,1,14.56,800,2,12.43,700,1,14.60,700,1,ARL,335996709
2197,2025-07-17T16:10:32.823656903Z,2025-07-17T16:10:32.823491276Z,10,2,1108,C,A,0,14.770000000,100,0,165627,279705362,13.11,100,1,13.65,15,1,13.01,2,1,13.66,100,1,12.98,200,2,13.90,2,1,12.86,100,1,14.01,100,1,12.73,100,1,14.28,100,1,12.71,100,1,14.46,100,1,12.50,700,1,14.47,100,1,12.49,200,2,14.48,700,1,12.46,100,1,14.56,800,2,12.43,700,1,14.60,700,1,ARL,335003845
2198,2025-07-17T16:10:32.823656903Z,2025-07-17T16:10:32.823491276Z,10,2,1108,A,A,0,14.720000000,100,130,165627,279705362,13.11,100,1,13.65,15,1,13.01,2,1,13.66,100,1,12.98,200,2,13.90,2,1,12.86,100,1,14.01,100,1,12.73,100,1,14.28,100,1,12.71,100,1,14.46,100,1,12.50,700,1,14.47,100,1,12.49,200,2,14.48,700,1,12.46,100,1,14.56,800,2,12.43,700,1,14.60,700,1,ARL,335996725
2199,2025-07-17T16:10:32.830200844Z,2025-07-17T16:10:32.830032662Z,10,2,1108,C,A,0,14.010000000,100,130,168182,279705485,13.11,100,1,13.65,15,1,13.01,2,1,13.66,100,1,12.98,200,2,13.90,2,1,12.86,100,1,14.28,100,1,12.73,100,1,14.46,100,1,12.71,100,1,14.47,100,1,12.50,700,1,14.48,700,1,12.49,200,2,14.56,800,2,12.46,100,1,14.60,700,1,12.43,700,1,14.62,200,2,ARL,334593753
2200,2025-07-17T16:10:32.830250720Z,2025-07-17T16:10:32.830085472Z,10,2,1108,A,A,0,13.930000000,100,130,165248,279705486,13.11,100,1,13.65,15,1,13.01,2,1,13.66,100,1,12.98,200,2,13.90,2,1,12.86,100,1,13.93,100,1,12.73,100,1,14.28,100,1,12.71,100,1,14.46,100,1,12.50,700,1,14.47,100,1,12.49,200,2,14.48,700,1,12.46,100,1,14.56,800,2,12.43,700,1,14.60,700,1,ARL,335996777
2201,2025-07-17T16:10:42.822354869Z,2025-07-17T16:10:42.822189504Z,10,2,1108,A,A,0,13.630000000,15,130,165365,279834760,13.11,100,1,13.63,15,1,13.01,2,1,13.65,15,1,12.98,200,2,13.66,100,1,12.86,100,1,13.90,2,1,12.73,100,1,13.93,100,1,12.71,100,1,14.28,100,1,12.50,700,1,14.46,100,1,12.49,200,2,14.47,100,1,12.46,100,1,14.48,700,1,12.43,700,1,14.56,800,2,ARL,336161333
